Workbook

Sheet Payroll Summary
A1: Sno | B1: Employee Category | C1: Total Payroll Amount
A2: 1 | B2: Tech Employees | C2: ='Tech Team'!AB26 -> 691441.21
A3: 2 | B3: Consultants | C3: =Consultant!H5 -> 229400
A4: 3 | B4: Internal Employees | C4: =Employees!AB8 -> 221871.61
A5: 4 | B5: Hiring Team | C5: ='Hiring Team'!K16 -> 244651.23
A6: 5 | B6: Rental Payments | C6: ='Rental Payment'!D5 -> 180000
B7: Grand Total | C7: =SUM(C2:C6) -> 1567364.1

Sheet Employees
A1: Employee ID | B1: Employee Name | C1: DOJ | D1: CTC | E1: Calendar Days | F1: Paid Days | G1: LOP day's | H1: Basic | I1: HRA | J1: Special Allowance | K1: Other Allowance | L1: Gross Income | M1: Employee PF (12%) | N1: Employee ESI (0.75%) | O1: Professional Tax | P1: Arrears | Q1: Reimbursements | R1: Bonus/Incentive | S1: Gross Earnings | T1: TDS | U1: LOP Deduction | V1: Other Deductions | W1: Employer PF (12%) | X1: Employer ESI (3.25%) | Y1: Gratuity (4.81%) | Z1: Total Deductions | AA1: Correction | AB1: Net Salary Payable
A2: AGS26038 | B2: Ainala Saiesha | C2: 46086 | D2: 100000 | E2: 30 | F2: =E2-G2 -> 30 | G2: 0 | H2: =(+D2*49.99999%)/E2*F2 -> 49999.99 | I2: =(H2*50%) -> 24999.995 | J2: =(1600/E2)*F2 -> 1600 | K2: =(L2-H2-I2-J2) -> 19195.015 | L2: =(D2-W2)/E2*F2-Y2 -> 95795 | M2: =IF($H2*0.12>1800,1800,$H2*0.12) -> 1800 | N2: =IF(L2<=21000,L2*0.75%,0) -> 0 | O2: 200 | P2: 0 | R2: 0 | S2: =L2+P2+Q2+R2 -> 95795 | T2: 0 | U2: =ROUND((L2/E2)*G2,0) -> 0 | W2: =IF($H2*0.12>1800,1800,$H2*0.12) -> 1800 | X2: =IF(L2<=21000,L2*3.25%,0) -> 0 | Y2: 2405 | Z2: =M2+N2+O2+V2+T2+W2+X2+Y2 -> 6205 | AB2: =L2-Z2+AA2+M2+Y2 -> 93795
A3: AGS26051 | B3: Mundlamuri Mrudula | C3: 46113 | D3: 29166 | E3: 30 | F3: 24 | G3: 0 | H3: =(+D3*49.99999%)/E3*F3 -> 11666.398 | I3: =(H3*50%) -> 5833.1988 | J3: =(1600/E3)*F3 -> 1280 | K3: =(L3-H3-I3-J3) -> 2732.2293 | L3: =(D3-W3)/E3*F3-Y3 -> 21511.826 | M3: =IF($H3*0.12>1800,1800,$H3*0.12) -> 1399.9677 | N3: =IF(L3<=21000,L3*0.75%,0) -> 0 | O3: 200 | P3: 0 | R3: 0 | S3: =L3+P3+Q3+R3 -> 21511.826 | T3: 0 | U3: =ROUND((L3/E3)*G3,0) -> 0 | W3: =IF($H3*0.12>1800,1800,$H3*0.12) -> 1399.9677 | X3: =IF(L3<=21000,L3*3.25%,0) -> 0 | Y3: 701 | Z3: =M3+N3+O3+V3+T3+W3+X3+Y3 -> 3700.9354 | AB3: =L3-Z3+AA3+M3+Y3 -> 19911.858
A4: AGS26048 | B4: Rapolu Rekha | C4: 46113 | D4: 25000 | E4: 30 | F4: =E4-G4 -> 30 | G4: 0 | H4: =(+D4*49.99999%)/E4*F4 -> 12499.997 | I4: =(H4*50%) -> 6249.9987 | J4: =(1600/E4)*F4 -> 1600 | K4: =(L4-H4-I4-J4) -> 2548.7542 | L4: =(D4-W4)/E4*F4-Y4 -> 22898.75 | M4: =IF($H4*0.12>1800,1800,$H4*0.12) -> 1499.9997 | N4: =IF(L4<=21000,L4*0.75%,0) -> 0 | O4: 200 | P4: 0 | R4: 0 | S4: =L4+P4+Q4+R4 -> 22898.75 | T4: 0 | U4: =ROUND((L4/E4)*G4,0) -> 0 | W4: =IF($H4*0.12>1800,1800,$H4*0.12) -> 1499.9997 | X4: =IF(L4<=21000,L4*3.25%,0) -> 0 | Y4: =H4*4.81% -> 601.24988 | Z4: =M4+N4+O4+V4+T4+W4+X4+Y4 -> 3801.2493 | AB4: =L4-Z4+AA4+M4+Y4 -> 21198.751
A5: AGS26057 | B5: Odeti Srinivas | C5: 46113 | D5: 41667 | E5: 30 | F5: =E5-G5 -> 30 | G5: 0 | H5: =(+D5*49.99999%)/E5*F5 -> 20833.496 | I5: =(H5*50%) -> 10416.748 | J5: =(1600/E5)*F5 -> 1600 | K5: =(L5-H5-I5-J5) -> 6014.7563 | L5: =(D5-W5)/E5*F5-Y5 -> 38865 | M5: =IF($H5*0.12>1800,1800,$H5*0.12) -> 1800 | N5: =IF(L5<=21000,L5*0.75%,0) -> 0 | O5: 200 | P5: 0 | R5: 0 | S5: =L5+P5+Q5+R5 -> 38865 | T5: 0 | U5: =ROUND((L5/E5)*G5,0) -> 0 | W5: =IF($H5*0.12>1800,1800,$H5*0.12) -> 1800 | X5: =IF(L5<=21000,L5*3.25%,0) -> 0 | Y5: 1002 | Z5: =M5+N5+O5+V5+T5+W5+X5+Y5 -> 4802 | AB5: =L5-Z5+AA5+M5+Y5 -> 36865
A6: AGS26060 | B6: Thallada Venkatasagar | C6: 46114 | D6: 34982 | E6: 30 | F6: =E6-G6 -> 30 | G6: 0 | H6: =(+D6*49.99999%)/E6*F6 -> 17490.997 | I6: =(H6*50%) -> 8745.4983 | J6: =(1600/E6)*F6 -> 1600 | K6: =(L6-H6-I6-J6) -> 4521.5052 | L6: =(D6-W6)/E6*F6-Y6 -> 32358 | M6: =IF($H6*0.12>1800,1800,$H6*0.12) -> 1800 | N6: =IF(L6<=21000,L6*0.75%,0) -> 0 | O6: 200 | P6: 0 | R6: 0 | S6: =L6+P6+Q6+R6 -> 32358 | T6: 0 | U6: =ROUND((L6/E6)*G6,0) -> 0 | W6: =IF($H6*0.12>1800,1800,$H6*0.12) -> 1800 | X6: =IF(L6<=21000,L6*3.25%,0) -> 0 | Y6: 824 | Z6: =M6+N6+O6+V6+T6+W6+X6+Y6 -> 4624 | AB6: =L6-Z6+AA6+M6+Y6 -> 30358
A7: AGS26097 | B7: Mugidi Pavan Sriram Kalyan | C7: 46264 | D7: 23600 | E7: 30 | F7: =E7-G7 -> 30 | G7: 0 | H7: =(+D7*49.99999%)/E7*F7 -> 11799.998 | I7: =(H7*50%) -> 5899.9988 | J7: =(1600/E7)*F7 -> 1600 | K7: =(L7-H7-I7-J7) -> 2059.0038 | L7: =(D7-W7)/E7*F7-Y7 -> 21359 | M7: =IF($H7*0.12>1800,1800,$H7*0.12) -> 1415.9997 | N7: =IF(L7<=21000,L7*0.75%,0) -> 0 | O7: 200 | P7: 0 | R7: 0 | S7: =L7+P7+Q7+R7 -> 21359 | T7: 0 | U7: =ROUND((L7/E7)*G7,0) -> 0 | W7: =IF($H7*0.12>1800,1800,$H7*0.12) -> 1415.9997 | X7: =IF(L7<=21000,L7*3.25%,0) -> 0 | Y7: 825 | Z7: =M7+N7+O7+V7+T7+W7+X7+Y7 -> 3856.9994 | AB7: =L7-Z7+AA7+M7+Y7 -> 19743.001
L8: Total | AB8: =SUM(AB2:AB7) -> 221871.61

Sheet Consultant
A1: Employee ID | B1: Employee Name | C1: DOJ | D1: CTC | E1: Actuals | F1: TDS | G1: PT | H1: Payable | I1: LOP
A2: AGS26004 | B2: Ande Sharath Chandra | C2: 46055 | D2: 80000 | E2: 80000 | F2: 0 | G2: 200 | H2: =E2-G2 -> 79800
A3: AGS26005 | B3: Tanakala Janardhan | C3: 46055 | D3: 70000 | E3: 70000 | F3: 0 | G3: 200 | H3: =E3-G3 -> 69800
A4: AGS26024 | B4: Priya Darshini Pola | C4: 46072 | D4: 80000 | E4: 80000 | F4: 0 | G4: 200 | H4: =E4-G4 -> 79800
G5: Total | H5: =SUM(H2:H4) -> 229400

Sheet Tech Team
B1: Employee ID | C1: Employee Name | D1: DOJ | E1: CTC | F1: Calendar Days | G1: Paid Days | H1: LOP day's | I1: Basic | J1: HRA | K1: Special Allowance | L1: Other Allowance | M1: Gross Income | N1: Employee PF (12%) | O1: Employee ESI (0.75%) | P1: Professional Tax | Q1: Arrears | R1: Reimbursements | S1: Bonus/ Incentive | T1: Gross Earnings | U1: TDS | V1: LOP Deduction | W1: Other Deductions | X1: Employer PF (12%) | Y1: Employer ESI (3.25%) | Z1: Gratuity (4.81%) | AA1: Total Deductions | AB1: Net Salary Payable
A2: 1 | B2: AGS26010 | C2: Vemula Varshith | D2: 46083 | E2: 35000 | F2: 30 | G2: =F2-H2 -> 29 | H2: 1 | I2: =(+E2*49.99999%)/F2*G2 -> 16916.663 | J2: =(I2*50%) -> 8458.3316 | K2: =(1600/F2)*G2 -> 1546.6667 | L2: =(M2-I2-J2-K2) -> 4357.9802 | M2: =(E2-X2)/F2*G2-Z2 -> 31279.642 | N2: =IF($I2*0.12>1800,1800,$I2*0.12) -> 1800 | O2: =IF(M2<=21000,M2*0.75%,0) -> 0 | P2: 200 | Q2: 0 | R2: 0 | S2: 0 | T2: =M2+Q2+R2+S2 -> 31279.642 | U2: 0 | V2: 0 | W2: 0 | X2: =IF($I2*0.12>1800,1800,$I2*0.12) -> 1800 | Y2: =IF(M2<=21000,M2*3.25%,0) -> 0 | Z2: =I2*4.81% -> 813.6915 | AA2: =N2+O2+P2+V2+W2+U2+X2+Y2+Z2 -> 4613.6915 | AB2: =M2-AA2+Z2+X2 -> 29279.642
A3: 2 | B3: AGS26011 | C3: Siddula Hemasai | D3: 46083 | E3: 45000 | F3: 30 | G3: =F3-H3 -> 29 | H3: 1 | I3: =(+E3*49.99999%)/F3*G3 -> 21749.996 | J3: =(I3*50%) -> 10874.998 | K3: =(1600/F3)*G3 -> 1546.6667 | L3: =(M3-I3-J3-K3) -> 6542.1651 | M3: =(E3-X3)/F3*G3-Z3 -> 40713.825 | N3: =IF($I3*0.12>1800,1800,$I3*0.12) -> 1800 | O3: =IF(M3<=21000,M3*0.75%,0) -> 0 | P3: 200 | Q3: 0 | R3: 0 | S3: 0 | T3: =M3+Q3+R3+S3 -> 40713.825 | U3: 0 | V3: 0 | W3: 0 | X3: =IF($I3*0.12>1800,1800,$I3*0.12) -> 1800 | Y3: =IF(M3<=21000,M3*3.25%,0) -> 0 | Z3: =I3*4.81% -> 1046.1748 | AA3: =N3+O3+P3+W3+U3+X3+Y3+Z3 -> 4846.1748 | AB3: =M3-AA3+Z3+X3+Y3 -> 38713.825
A4: 3 | B4: AGS26019 | C4: Nelapatla Srinivas | D4: 46083 | E4: 23000 | F4: 30 | G4: =F4-H4 -> 29 | H4: 1 | I4: =(+E4*49.99999%)/F4*G4 -> 11116.664 | J4: =(I4*50%) -> 5558.3322 | K4: =(1600/F4)*G4 -> 1546.6667 | L4: =(M4-I4-J4-K4) -> 2187.4254 | M4: =(E4-X4)/F4*G4-Z4 -> 20409.089 | N4: =IF($I4*0.12>1800,1800,$I4*0.12) -> 1333.9997 | O4: 0 | P4: 200 | Q4: 0 | R4: 0 | S4: 0 | T4: =M4+Q4+R4+S4 -> 20409.089 | U4: 0 | V4: 0 | W4: 0 | X4: =IF($I4*0.12>1800,1800,$I4*0.12) -> 1333.9997 | Y4: 0 | Z4: =I4*4.81% -> 534.71156 | AA4: =N4+O4+P4+V4+W4+U4+X4+Y4+Z4 -> 3402.711 | AB4: =M4-AA4+Z4+X4 -> 18875.089
A5: 4 | B5: AGS26023 | C5: Bobbarala Varshini | D5: 46083 | E5: 35000 | F5: 30 | G5: =F5-H5 -> 30 | H5: 0 | I5: =(+E5*49.99999%)/F5*G5 -> 17499.996 | J5: =(I5*50%) -> 8749.9982 | K5: =(1600/F5)*G5 -> 1600 | L5: =(M5-I5-J5-K5) -> 4508.2554 | M5: =(E5-X5)/F5*G5-Z5 -> 32358.25 | N5: =IF($I5*0.12>1800,1800,$I5*0.12) -> 1800 | O5: =IF(M5<=21000,M5*0.75%,0) -> 0 | P5: 200 | Q5: 0 | R5: 0 | S5: 0 | T5: =M5+Q5+R5+S5 -> 32358.25 | U5: 0 | V5: 0 | W5: 0 | X5: =IF($I5*0.12>1800,1800,$I5*0.12) -> 1800 | Y5: =IF(M5<=21000,M5*3.25%,0) -> 0 | Z5: =I5*4.81% -> 841.74983 | AA5: =N5+O5+P5+V5+W5+U5+X5+Y5+Z5 -> 4641.7498 | AB5: =M5-AA5+Z5+X5 -> 30358.25
A6: 5 | B6: AGS26032 | C6: Vempadapu Uday Sai Tarun | D6: 46083 | E6: 17000 | F6: 30 | G6: =F6-H6 -> 30 | H6: 0 | I6: =(+E6*49.99999%)/F6*G6 -> 8499.9983 | J6: =(I6*50%) -> 4249.9991 | K6: =(1600/F6)*G6 -> 1600 | L6: =(M6-I6-J6-K6) -> 1221.1528 | M6: =(E6-X6)/F6*G6-Z6 -> 15571.15 | N6: =IF($I6*0.12>1800,1800,$I6*0.12) -> 1019.9998 | O6: 0 | P6: 200 | Q6: 0 | R6: 0 | S6: 0 | T6: =M6+Q6+R6+S6 -> 15571.15 | U6: 0 | V6: 0 | W6: 0 | X6: =IF($I6*0.12>1800,1800,$I6*0.12) -> 1019.9998 | Y6: 0 | Z6: =I6*4.81% -> 408.84992 | AA6: =N6+O6+P6+V6+W6+U6+X6+Y6+Z6 -> 2648.8495 | AB6: =M6-AA6+Z6+X6 -> 14351.15
A7: 6 | B7: AGS26034 | C7: Sripada Shivakumar | D7: 46083 | E7: 50000 | F7: 30 | G7: =F7-H7 -> 30 | H7: 0 | I7: =(+E7*49.99999%)/F7*G7 -> 24999.995 | J7: =(I7*50%) -> 12499.997 | K7: =(1600/F7)*G7 -> 1600 | L7: =(M7-I7-J7-K7) -> 7897.5077 | M7: =(E7-X7)/F7*G7-Z7 -> 46997.5 | N7: =IF($I7*0.12>1800,1800,$I7*0.12) -> 1800 | O7: =IF(M7<=21000,M7*0.75%,0) -> 0 | P7: 200 | Q7: 0 | R7: 0 | S7: 0 | T7: =M7+Q7+R7+S7 -> 46997.5 | U7: 0 | V7: 0 | W7: 0 | X7: =IF($I7*0.12>1800,1800,$I7*0.12) -> 1800 | Y7: =IF(M7<=21000,M7*3.25%,0) -> 0 | Z7: =I7*4.81% -> 1202.4998 | AA7: =N7+O7+P7+V7+W7+U7+X7+Y7+Z7 -> 5002.4998 | AB7: =M7-AA7+Z7+X7 -> 44997.5
A8: 7 | B8: AGS26041 | C8: Sudhagani Sai Charan | D8: 46113 | E8: 23000 | F8: 30 | G8: =F8-H8 -> 30 | H8: 0 | I8: =(+E8*49.99999%)/F8*G8 -> 11499.998 | J8: =(I8*50%) -> 5749.9988 | K8: =(1600/F8)*G8 -> 1600 | L8: =(M8-I8-J8-K8) -> 2216.8538 | M8: =(E8-X8)/F8*G8-Z8 -> 21066.85 | N8: =IF($I8*0.12>1800,1800,$I8*0.12) -> 1379.9997 | O8: =IF(M8<=21000,M8*0.75%,0) -> 0 | P8: 200 | Q8: 0 | R8: 0 | S8: 0 | T8: =M8+Q8+R8+S8 -> 21066.85 | U8: 0 | V8: 0 | W8: 0 | X8: =IF($I8*0.12>1800,1800,$I8*0.12) -> 1379.9997 | Y8: =IF(M8<=21000,M8*3.25%,0) -> 0 | Z8: =I8*4.81% -> 553.14989 | AA8: =N8+O8+P8+V8+W8+U8+X8+Y8+Z8 -> 3513.1493 | AB8: =M8-AA8+Z8+X8 -> 19486.851
A9: 8 | B9: AGS26047 | C9: Upadhyayula Naga Lakshmi Deepthi | D9: 46114 | E9: 23000 | F9: 30 | G9: =F9-H9 -> 30 | H9: 0 | I9: =(+E9*49.99999%)/F9*G9 -> 11499.998 | J9: =(I9*50%) -> 5749.9988 | K9: =(1600/F9)*G9 -> 1600 | L9: =(M9-I9-J9-K9) -> 2216.8538 | M9: =(E9-X9)/F9*G9-Z9 -> 21066.85 | N9: =IF($I9*0.12>1800,1800,$I9*0.12) -> 1379.9997 | O9: 0 | P9: 200 | Q9: 0 | R9: 0 | S9: 0 | T9: =M9+Q9+R9+S9 -> 21066.85 | U9: 0 | V9: 0 | W9: 0 | X9: =IF($I9*0.12>1800,1800,$I9*0.12) -> 1379.9997 | Y9: 0 | Z9: =I9*4.81% -> 553.14989 | AA9: =N9+O9+P9+V9+W9+U9+X9+Y9+Z9 -> 3513.1493 | AB9: =M9-AA9+Z9+X9 -> 19486.851
A10: 9 | B10: AGS26049 | C10: Ragiru Nikhitha | D10: 46113 | E10: 15000 | F10: 30 | G10: =F10-H10 -> 30 | H10: 0 | I10: =(+E10*49.99999%)/F10*G10 -> 7499.9985 | J10: =(I10*50%) -> 3749.9992 | K10: =(1600/F10)*G10 -> 1600 | L10: =(M10-I10-J10-K10) -> 889.2525 | M10: =(E10-X10)/F10*G10-Z10 -> 13739.25 | N10: =IF($I10*0.12>1800,1800,$I10*0.12) -> 899.99982 | O10: 0 | P10: 150 | Q10: 0 | R10: 0 | S10: 0 | T10: =M10+Q10+R10+S10 -> 13739.25 | U10: 0 | V10: 0 | W10: 0 | X10: =IF($I10*0.12>1800,1800,$I10*0.12) -> 899.99982 | Y10: 0 | Z10: =I10*4.81% -> 360.74993 | AA10: =N10+O10+P10+V10+W10+U10+X10+Y10+Z10 -> 2310.7496 | AB10: =M10-AA10+Z10+X10 -> 12689.25
A11: 10 | B11: AGS26031 | C11: Y Raghavendar | D11: 46113 | E11: 45000 | F11: 30 | G11: =F11-H11 -> 30 | H11: 0 | I11: =(+E11*49.99999%)/F11*G11 -> 22499.995 | J11: =(I11*50%) -> 11249.998 | K11: =(1600/F11)*G11 -> 1600 | L11: =(M11-I11-J11-K11) -> 6767.757 | M11: =(E11-X11)/F11*G11-Z11 -> 42117.75 | N11: =IF($I11*0.12>1800,1800,$I11*0.12) -> 1800 | O11: 0 | P11: 200 | Q11: 0 | R11: 0 | S11: 0 | T11: =M11+Q11+R11+S11 -> 42117.75 | U11: 0 | V11: 0 | W11: 0 | X11: =IF($I11*0.12>1800,1800,$I11*0.12) -> 1800 | Y11: 0 | Z11: =I11*4.81% -> 1082.2498 | AA11: =N11+O11+P11+V11+W11+U11+X11+Y11+Z11 -> 4882.2498 | AB11: =M11-AA11+Z11+X11 -> 40117.75
A12: 11 | B12: AGS26056 | C12: Bommala Naveen Kumar | D12: 46113 | E12: 45000 | F12: 30 | G12: =F12-H12 -> 30 | H12: 0 | I12: =(+E12*49.99999%)/F12*G12 -> 22499.995 | J12: =(I12*50%) -> 11249.998 | K12: =(1600/F12)*G12 -> 1600 | L12: =(M12-I12-J12-K12) -> 6767.757 | M12: =(E12-X12)/F12*G12-Z12 -> 42117.75 | N12: =IF($I12*0.12>1800,1800,$I12*0.12) -> 1800 | O12: 0 | P12: 200 | Q12: 0 | R12: 0 | S12: 0 | T12: =M12+Q12+R12+S12 -> 42117.75 | U12: 0 | V12: 0 | W12: 0 | X12: =IF($I12*0.12>1800,1800,$I12*0.12) -> 1800 | Y12: 0 | Z12: =I12*4.81% -> 1082.2498 | AA12: =N12+O12+P12+V12+W12+U12+X12+Y12+Z12 -> 4882.2498 | AB12: =M12-AA12+Z12+X12 -> 40117.75
A13: 12 | B13: AGS26025 | C13: Tumula Dinesh Kumar | D13: 46113 | E13: 23000 | F13: 30 | G13: =F13-H13 -> 30 | H13: 0 | I13: =(+E13*49.99999%)/F13*G13 -> 11499.998 | J13: =(I13*50%) -> 5749.9988 | K13: =(1600/F13)*G13 -> 1600 | L13: =(M13-I13-J13-K13) -> 2216.8538 | M13: =(E13-X13)/F13*G13-Z13 -> 21066.85 | N13: =IF($I13*0.12>1800,1800,$I13*0.12) -> 1379.9997 | O13: =IF(M13<=21000,M13*0.75%,0) -> 0 | P13: 200 | Q13: 0 | R13: 0 | S13: 0 | T13: =M13+Q13+R13+S13 -> 21066.85 | U13: 0 | V13: 0 | W13: 0 | X13: =IF($I13*0.12>1800,1800,$I13*0.12) -> 1379.9997 | Y13: =IF(M13<=21000,M13*3.25%,0) -> 0 | Z13: =I13*4.81% -> 553.14989 | AA13: =N13+O13+P13+V13+W13+U13+X13+Y13+Z13 -> 3513.1493 | AB13: =M13-AA13+Z13+X13 -> 19486.851
A14: 13 | B14: AGS26073 | C14: KONDAPALLY AKHIL | D14: 46113 | E14: 100000 | F14: 30 | G14: =F14-H14 -> 30 | H14: 0 | I14: =(+E14*49.99999%)/F14*G14 -> 49999.99 | J14: =(I14*50%) -> 24999.995 | K14: =(1600/F14)*G14 -> 1600 | L14: =(M14-I14-J14-K14) -> 19195.015 | M14: =(E14-X14)/F14*G14-Z14 -> 95795 | N14: =IF($I14*0.12>1800,1800,$I14*0.12) -> 1800 | O14: =IF(M14<=21000,M14*0.75%,0) -> 0 | P14: 200 | Q14: 0 | R14: 0 | S14: 0 | T14: =M14+Q14+R14+S14 -> 95795 | U14: 0 | V14: 0 | W14: 0 | X14: =IF($I14*0.12>1800,1800,$I14*0.12) -> 1800 | Y14: =IF(M14<=21000,M14*3.25%,0) -> 0 | Z14: =I14*4.81% -> 2404.9995 | AA14: =N14+O14+P14+V14+W14+U14+X14+Y14+Z14 -> 6204.9995 | AB14: =M14-AA14+Z14+X14 -> 93795
A15: 14 | B15: AGS26074 | C15: Manikonda Nagasurya Koundinya | D15: 46113 | E15: 33333 | F15: 30 | G15: =F15-H15 -> 30 | H15: 0 | I15: =(+E15*49.99999%)/F15*G15 -> 16666.497 | J15: =(I15*50%) -> 8333.2483 | K15: =(1600/F15)*G15 -> 1600 | L15: =(M15-I15-J15-K15) -> 4131.5965 | M15: =(E15-X15)/F15*G15-Z15 -> 30731.342 | N15: =IF($I15*0.12>1800,1800,$I15*0.12) -> 1800 | O15: =IF(M15<=21000,M15*0.75%,0) -> 0 | P15: 200 | Q15: 0 | R15: 0 | S15: 0 | T15: =M15+Q15+R15+S15 -> 30731.342 | U15: 0 | V15: 0 | W15: 0 | X15: =IF($I15*0.12>1800,1800,$I15*0.12) -> 1800 | Y15: =IF(M15<=21000,M15*3.25%,0) -> 0 | Z15: =I15*4.81% -> 801.65849 | AA15: =N15+O15+P15+V15+W15+U15+X15+Y15+Z15 -> 4601.6585 | AB15: =M15-AA15+Z15+X15 -> 28731.342
A16: 15 | B16: AGS26063 | C16: Bondada Jayanth | D16: 46146 | E16: 23000 | F16: 30 | G16: =F16-H16 -> 30 | H16: 0 | I16: =(+E16*49.99999%)/F16*G16 -> 11499.998 | J16: =(I16*50%) -> 5749.9988 | K16: =(1600/F16)*G16 -> 1600 | L16: =(M16-I16-J16-K16) -> 2216.8538 | M16: =(E16-X16)/F16*G16-Z16 -> 21066.85 | N16: =IF($I16*0.12>1800,1800,$I16*0.12) -> 1379.9997 | O16: 0 | P16: 200 | Q16: 0 | R16: 0 | S16: 0 | T16: =M16+Q16+R16+S16 -> 21066.85 | U16: 0 | V16: 0 | W16: 0 | X16: =IF($I16*0.12>1800,1800,$I16*0.12) -> 1379.9997 | Y16: 0 | Z16: =I16*4.81% -> 553.14989 | AA16: =N16+O16+P16+V16+W16+U16+X16+Y16+Z16 -> 3513.1493 | AB16: =M16-AA16+Z16+X16 -> 19486.851
A17: 16 | B17: AGS26066 | C17: Mohammad Sulthan | D17: 46146 | E17: 45000 | F17: 30 | G17: =F17-H17 -> 30 | H17: 0 | I17: =(+E17*49.99999%)/F17*G17 -> 22499.995 | J17: =(I17*50%) -> 11249.998 | K17: =(1600/F17)*G17 -> 1600 | L17: =(M17-I17-J17-K17) -> 6767.757 | M17: =(E17-X17)/F17*G17-Z17 -> 42117.75 | N17: =IF($I17*0.12>1800,1800,$I17*0.12) -> 1800 | O17: =IF(M17<=21000,M17*0.75%,0) -> 0 | P17: 200 | Q17: 0 | R17: 0 | S17: 0 | T17: =M17+Q17+R17+S17 -> 42117.75 | U17: 0 | V17: 0 | W17: 0 | X17: =IF($I17*0.12>1800,1800,$I17*0.12) -> 1800 | Y17: =IF(M17<=21000,M17*3.25%,0) -> 0 | Z17: =I17*4.81% -> 1082.2498 | AA17: =N17+O17+P17+V17+W17+U17+X17+Y17+Z17 -> 4882.2498 | AB17: =M17-AA17+Z17+X17 -> 40117.75
A18: 17 | B18: AGS26067 | C18: Md Imran Khan | D18: 46146 | E18: 15000 | F18: 30 | G18: =F18-H18 -> 30 | H18: 0 | I18: =(+E18*49.99999%)/F18*G18 -> 7499.9985 | J18: =(I18*50%) -> 3749.9992 | K18: =(1600/F18)*G18 -> 1600 | L18: =(M18-I18-J18-K18) -> 889.2525 | M18: =(E18-X18)/F18*G18-Z18 -> 13739.25 | N18: =IF($I18*0.12>1800,1800,$I18*0.12) -> 899.99982 | O18: 0 | P18: 150 | Q18: 0 | R18: 0 | S18: 0 | T18: =M18+Q18+R18+S18 -> 13739.25 | U18: 0 | V18: 0 | W18: 0 | X18: =IF($I18*0.12>1800,1800,$I18*0.12) -> 899.99982 | Y18: 0 | Z18: =I18*4.81% -> 360.74993 | AA18: =N18+O18+P18+V18+W18+U18+X18+Y18+Z18 -> 2310.7496 | AB18: =M18-AA18+Z18+X18 -> 12689.25
A19: 18 | B19: AGS26068 | C19: Narmeta Srujanreddy | D19: 46146 | E19: 15000 | F19: 30 | G19: =F19-H19 -> 30 | H19: 0 | I19: =(+E19*49.99999%)/F19*G19 -> 7499.9985 | J19: =(I19*50%) -> 3749.9992 | K19: =(1600/F19)*G19 -> 1600 | L19: =(M19-I19-J19-K19) -> 889.2525 | M19: =(E19-X19)/F19*G19-Z19 -> 13739.25 | N19: =IF($I19*0.12>1800,1800,$I19*0.12) -> 899.99982 | O19: 0 | P19: 150 | Q19: 0 | R19: 0 | S19: 0 | T19: =M19+Q19+R19+S19 -> 13739.25 | U19: 0 | V19: 0 | W19: 0 | X19: =IF($I19*0.12>1800,1800,$I19*0.12) -> 899.99982 | Y19: 0 | Z19: =I19*4.81% -> 360.74993 | AA19: =N19+O19+P19+V19+W19+U19+X19+Y19+Z19 -> 2310.7496 | AB19: =M19-AA19+Z19+X19 -> 12689.25
A20: 19 | B20: AGS26069 | C20: Neetapalli Sreekanth Reddy | D20: 46146 | E20: 45000 | F20: 30 | G20: =F20-H20 -> 30 | H20: 0 | I20: =(+E20*49.99999%)/F20*G20 -> 22499.995 | J20: =(I20*50%) -> 11249.998 | K20: =(1600/F20)*G20 -> 1600 | L20: =(M20-I20-J20-K20) -> 6767.757 | M20: =(E20-X20)/F20*G20-Z20 -> 42117.75 | N20: =IF($I20*0.12>1800,1800,$I20*0.12) -> 1800 | O20: =IF(M20<=21000,M20*0.75%,0) -> 0 | P20: 200 | Q20: 0 | R20: 0 | S20: 0 | T20: =M20+Q20+R20+S20 -> 42117.75 | U20: 0 | V20: 0 | W20: 0 | X20: =IF($I20*0.12>1800,1800,$I20*0.12) -> 1800 | Y20: =IF(M20<=21000,M20*3.25%,0) -> 0 | Z20: =I20*4.81% -> 1082.2498 | AA20: =N20+O20+P20+V20+W20+U20+X20+Y20+Z20 -> 4882.2498 | AB20: =M20-AA20+Z20+X20 -> 40117.75
A21: 20 | B21: AGS26070 | C21: Melath Ashwin | D21: 46146 | E21: 35000 | F21: 30 | G21: =F21-H21 -> 30 | H21: 0 | I21: =(+E21*49.99999%)/F21*G21 -> 17499.996 | J21: =(I21*50%) -> 8749.9982 | K21: =(1600/F21)*G21 -> 1600 | L21: =(M21-I21-J21-K21) -> 4508.2554 | M21: =(E21-X21)/F21*G21-Z21 -> 32358.25 | N21: =IF($I21*0.12>1800,1800,$I21*0.12) -> 1800 | O21: =IF(M21<=21000,M21*0.75%,0) -> 0 | P21: 200 | Q21: 0 | R21: 0 | S21: 0 | T21: =M21+Q21+R21+S21 -> 32358.25 | U21: 0 | V21: 0 | W21: 0 | X21: =IF($I21*0.12>1800,1800,$I21*0.12) -> 1800 | Y21: =IF(M21<=21000,M21*3.25%,0) -> 0 | Z21: =I21*4.81% -> 841.74983 | AA21: =N21+O21+P21+V21+W21+U21+X21+Y21+Z21 -> 4641.7498 | AB21: =M21-AA21+Z21+X21 -> 30358.25
A22: 21 | B22: AGS26093 | C22: Jamboju Eshwar | D22: 46237 | E22: 17500 | F22: 30 | G22: =F22-H22 -> 30 | H22: 0 | I22: =(+E22*49.99999%)/F22*G22 -> 8749.9982 | J22: =(I22*50%) -> 4374.9991 | K22: =(1600/F22)*G22 -> 1600 | L22: =(M22-I22-J22-K22) -> 1304.1279 | M22: =(E22-X22)/F22*G22-Z22 -> 16029.125 | N22: =IF($I22*0.12>1800,1800,$I22*0.12) -> 1049.9998 | O22: 0 | P22: 150 | Q22: 0 | R22: 0 | S22: 0 | T22: =M22+Q22+R22+S22 -> 16029.125 | U22: 0 | V22: 0 | W22: 0 | X22: =IF($I22*0.12>1800,1800,$I22*0.12) -> 1049.9998 | Y22: 0 | Z22: =I22*4.81% -> 420.87492 | AA22: =N22+O22+P22+V22+W22+U22+X22+Y22+Z22 -> 2670.8745 | AB22: =M22-AA22+Z22+X22+Y22 -> 14829.126
A23: 22 | B23: AGS26094 | C23: Banka Sanhith | D23: 46237 | E23: 17500 | F23: 30 | G23: =F23-H23 -> 30 | H23: 0 | I23: =(+E23*49.99999%)/F23*G23 -> 8749.9982 | J23: =(I23*50%) -> 4374.9991 | K23: =(1600/F23)*G23 -> 1600 | L23: =(M23-I23-J23-K23) -> 1304.1279 | M23: =(E23-X23)/F23*G23-Z23 -> 16029.125 | N23: =IF($I23*0.12>1800,1800,$I23*0.12) -> 1049.9998 | O23: 0 | P23: 150 | Q23: 0 | R23: 0 | S23: 0 | T23: =M23+Q23+R23+S23 -> 16029.125 | U23: 0 | V23: 0 | W23: 0 | X23: =IF($I23*0.12>1800,1800,$I23*0.12) -> 1049.9998 | Y23: 0 | Z23: =I23*4.81% -> 420.87492 | AA23: =N23+O23+P23+V23+W23+U23+X23+Y23+Z23 -> 2670.8745 | AB23: =M23-AA23+Z23+X23+Y23 -> 14829.126
A24: 23 | B24: AGS26061 | C24: Indla Kiran Kumar | D24: 46146 | E24: 35000 | F24: 30 | G24: =F24-H24 -> 30 | H24: 0 | I24: =(+E24*49.99999%)/F24*G24 -> 17499.996 | J24: =(I24*50%) -> 8749.9982 | K24: =(1600/F24)*G24 -> 1600 | L24: =(M24-I24-J24-K24) -> 4508.2554 | M24: =(E24-X24)/F24*G24-Z24 -> 32358.25 | N24: =IF($I24*0.12>1800,1800,$I24*0.12) -> 1800 | O24: =IF(M24<=21000,M24*0.75%,0) -> 0 | P24: 200 | Q24: 0 | R24: 0 | S24: 0 | T24: =M24+Q24+R24+S24 -> 32358.25 | U24: 0 | V24: 0 | W24: 0 | X24: =IF($I24*0.12>1800,1800,$I24*0.12) -> 1800 | Y24: =IF(M24<=21000,M24*3.25%,0) -> 0 | Z24: =I24*4.81% -> 841.74983 | AA24: =N24+O24+P24+V24+W24+U24+X24+Y24+Z24 -> 4641.7498 | AB24: =M24-AA24+Z24+X24 -> 30358.25
A25: 24 | B25: AGS26017 | C25: Vavilla Saikumar | D25: 02 Mar 2026 | E25: 30000 | F25: 30 | G25: =F25-H25 -> 30 | H25: 0 | I25: =(+E25*49.99999%)/F25*G25 -> 14999.997 | J25: =(I25*50%) -> 7499.9985 | K25: =(1600/F25)*G25 -> 1600 | L25: =(M25-I25-J25-K25) -> 3378.505 | M25: =(E25-X25)/F25*G25-Z25 -> 27478.501 | N25: =IF($I25*0.12>1800,1800,$I25*0.12) -> 1799.9996 | O25: =IF(M25<=21000,M25*0.75%,0) -> 0 | P25: 200 | Q25: 0 | R25: 0 | S25: 0 | T25: =M25+Q25+R25+S25 -> 27478.501 | U25: 0 | V25: 0 | W25: 0 | X25: =IF($I25*0.12>1800,1800,$I25*0.12) -> 1799.9996 | Y25: =IF(M25<=21000,M25*3.25%,0) -> 0 | Z25: =I25*4.81% -> 721.49986 | AA25: =N25+O25+P25+V25+W25+U25+X25+Y25+Z25 -> 4521.4991 | AB25: =M25-AA25+Z25+X25 -> 25478.501
AB26: =SUM(AB2:AB25) -> 691441.21

Sheet Hiring Team
A1: Employee ID | B1: Employee Name | C1: DOJ | D1: CTC | E1: Calendar Days | F1: Paid Days | G1: LOP day's | H1: Basic | I1: HRA | J1: Special Allowance | K1: Other Allowance | L1: Gross Income | M1: Employee PF (12%) | N1: Employee ESI (0.75%) | O1: Professional Tax | P1: Arrears | Q1: Reimbursements | R1: Bonus/ Incentive | S1: Gross Earnings | T1: TDS | U1: LOP Deduction | V1: Other Deductions | W1: Employer PF (12%) | X1: Employer ESI (3.25%) | Y1: Gratuity (4.81%) | Z1: Total Deductions | AA1: Net Salary Payable
A2: AGS26077 | B2: Batta Jyotsna | C2: 46174 | D2: 18444 | E2: 30 | F2: =E2-G2 -> 30 | G2: 0 | H2: =(+D2*49.99999%)/E2*F2 -> 9221.9982 | I2: =(H2*50%) -> 4610.9991 | J2: =(1600/E2)*F2 -> 1600 | K2: =(L2-H2-I2-J2) -> 2567.4247 | L2: =(D2-W2)/E2*F2-Y2 -> 18000.422 | M2: 0 | N2: 0 | O2: 200 | P2: 0 | Q2: 0 | R2: 0 | S2: =L2+P2+Q2+R2 -> 18000.422 | T2: 0 | U2: =ROUND((L2/E2)*G2,0) -> 0 | V2: 0 | W2: 0 | X2: 0 | Y2: =H2*4.81% -> 443.57811 | Z2: =M2+N2+O2+U2+V2+T2+W2+X2+Y2 -> 643.57811 | AA2: =L2-Z2+Y2+W2+X2+P2+Q2+R2 -> 17800.422
A3: AGS26078 | B3: Kankanala Sravani | C3: 46174 | D3: 15370 | E3: 30 | F3: =E3-G3 -> 30 | G3: 0 | H3: =(+D3*49.99999%)/E3*F3 -> 7684.9985 | I3: =(H3*50%) -> 3842.4992 | J3: =(1600/E3)*F3 -> 1600 | K3: =(L3-H3-I3-J3) -> 1872.8539 | L3: =(D3-W3)/E3*F3-Y3 -> 15000.352 | M3: 0 | N3: 0 | O3: 200 | P3: 0 | Q3: 0 | R3: 0 | S3: =L3+P3+Q3+R3 -> 15000.352 | T3: 0 | U3: =ROUND((L3/E3)*G3,0) -> 0 | V3: 0 | W3: 0 | X3: 0 | Y3: =H3*4.81% -> 369.64843 | Z3: =M3+N3+O3+U3+V3+T3+W3+X3+Y3 -> 569.64843 | AA3: =L3-Z3+Y3+W3+X3+P3+Q3+R3 -> 14800.352
A4: AGS26079 | B4: Vadicharla Sandeep Kumar | C4: 46174 | D4: 18444 | E4: 30 | F4: =E4-G4 -> 30 | G4: 0 | H4: =(+D4*49.99999%)/E4*F4 -> 9221.9982 | I4: =(H4*50%) -> 4610.9991 | J4: =(1600/E4)*F4 -> 1600 | K4: =(L4-H4-I4-J4) -> 2567.4247 | L4: =(D4-W4)/E4*F4-Y4 -> 18000.422 | M4: 0 | N4: 0 | O4: 200 | P4: 0 | Q4: 0 | R4: 0 | S4: =L4+P4+Q4+R4 -> 18000.422 | T4: 0 | U4: =ROUND((L4/E4)*G4,0) -> 0 | V4: 0 | W4: 0 | X4: 0 | Y4: =H4*4.81% -> 443.57811 | Z4: =M4+N4+O4+U4+V4+T4+W4+X4+Y4 -> 643.57811 | AA4: =L4-Z4+Y4+W4+X4+P4+Q4+R4 -> 17800.422
A5: AGS26080 | B5: Thota Varsha | C5: 46174 | D5: 15370 | E5: 30 | F5: =E5-G5 -> 30 | G5: 0 | H5: =(+D5*49.99999%)/E5*F5 -> 7684.9985 | I5: =(H5*50%) -> 3842.4992 | J5: =(1600/E5)*F5 -> 1600 | K5: =(L5-H5-I5-J5) -> 1872.8539 | L5: =(D5-W5)/E5*F5-Y5 -> 15000.352 | M5: 0 | N5: 0 | O5: 200 | P5: 0 | Q5: 0 | R5: 0 | S5: =L5+P5+Q5+R5 -> 15000.352 | T5: 0 | U5: =ROUND((L5/E5)*G5,0) -> 0 | V5: 0 | W5: 0 | X5: 0 | Y5: =H5*4.81% -> 369.64843 | Z5: =M5+N5+O5+U5+V5+T5+W5+X5+Y5 -> 569.64843 | AA5: =L5-Z5+Y5+W5+X5+P5+Q5+R5 -> 14800.352
A6: AGS26081 | B6: Shaik Faiza | C6: 46174 | D6: 13320 | E6: 30 | F6: =E6-G6 -> 30 | G6: 0 | H6: =(+D6*49.99999%)/E6*F6 -> 6659.9987 | I6: =(H6*50%) -> 3329.9993 | J6: =(1600/E6)*F6 -> 1600 | K6: =(L6-H6-I6-J6) -> 1409.6561 | L6: =(D6-W6)/E6*F6-Y6 -> 12999.654 | M6: 0 | N6: 0 | O6: 150 | P6: 0 | Q6: 0 | R6: 0 | S6: =L6+P6+Q6+R6 -> 12999.654 | T6: 0 | U6: =ROUND((L6/E6)*G6,0) -> 0 | V6: 0 | W6: 0 | X6: 0 | Y6: =H6*4.81% -> 320.34594 | Z6: =M6+N6+O6+U6+V6+T6+W6+X6+Y6 -> 470.34594 | AA6: =L6-Z6+Y6+W6+X6+P6+Q6+R6 -> 12849.654
A7: AGS26082 | B7: Shaik Shaheen | C7: 46174 | D7: 12296 | E7: 30 | F7: =E7-G7 -> 30 | G7: 0 | H7: =(+D7*49.99999%)/E7*F7 -> 6147.9988 | I7: =(H7*50%) -> 3073.9994 | J7: =(1600/E7)*F7 -> 1600 | K7: =(L7-H7-I7-J7) -> 1178.2831 | L7: =(D7-W7)/E7*F7-Y7 -> 12000.281 | M7: 0 | N7: 0 | O7: 150 | P7: 0 | Q7: 0 | R7: 0 | S7: =L7+P7+Q7+R7 -> 12000.281 | T7: 0 | U7: =ROUND((L7/E7)*G7,0) -> 0 | V7: 0 | W7: 0 | X7: 0 | Y7: =H7*4.81% -> 295.71874 | Z7: =M7+N7+O7+U7+V7+T7+W7+X7+Y7 -> 445.71874 | AA7: =L7-Z7+Y7+W7+X7+P7+Q7+R7 -> 11850.281
A8: AGS26083 | B8: Guduru Subhanbee | C8: 46174 | D8: 13320 | E8: 30 | F8: =E8-G8 -> 30 | G8: 0 | H8: =(+D8*49.99999%)/E8*F8 -> 6659.9987 | I8: =(H8*50%) -> 3329.9993 | J8: =(1600/E8)*F8 -> 1600 | K8: =(L8-H8-I8-J8) -> 1409.6561 | L8: =(D8-W8)/E8*F8-Y8 -> 12999.654 | M8: 0 | N8: 0 | O8: 150 | P8: 0 | Q8: 0 | R8: 0 | S8: =L8+P8+Q8+R8 -> 12999.654 | T8: 0 | U8: =ROUND((L8/E8)*G8,0) -> 0 | V8: 0 | W8: 0 | X8: 0 | Y8: =H8*4.81% -> 320.34594 | Z8: =M8+N8+O8+U8+V8+T8+W8+X8+Y8 -> 470.34594 | AA8: =L8-Z8+Y8+W8+X8+P8+Q8+R8 -> 12849.654
A9: AGS26084 | B9: Yapakayala Sampath | C9: 46174 | D9: 28690 | E9: 30 | F9: =E9-G9 -> 30 | G9: 0 | H9: =(+D9*49.99999%)/E9*F9 -> 14344.997 | I9: =(H9*50%) -> 7172.4986 | J9: =(1600/E9)*F9 -> 1600 | K9: =(L9-H9-I9-J9) -> 4882.5099 | L9: =(D9-W9)/E9*F9-Y9 -> 28000.006 | M9: 0 | N9: 0 | O9: 200 | P9: 0 | Q9: 0 | R9: 0 | S9: =L9+P9+Q9+R9 -> 28000.006 | T9: 0 | U9: =ROUND((L9/E9)*G9,0) -> 0 | V9: 0 | W9: 0 | X9: 0 | Y9: =H9*4.81% -> 689.99436 | Z9: =M9+N9+O9+U9+V9+T9+W9+X9+Y9 -> 889.99436 | AA9: =L9-Z9+Y9+W9+X9+P9+Q9+R9 -> 27800.006
A10: AGS26085 | B10: Shaik Akram | C10: 46174 | D10: 25616 | E10: 30 | F10: =E10-G10 -> 30 | G10: 0 | H10: =(+D10*49.99999%)/E10*F10 -> 12807.997 | I10: =(H10*50%) -> 6403.9987 | J10: =(1600/E10)*F10 -> 1600 | K10: =(L10-H10-I10-J10) -> 4187.9392 | L10: =(D10-W10)/E10*F10-Y10 -> 24999.935 | M10: 0 | N10: 0 | O10: 200 | P10: 0 | Q10: 0 | R10: 0 | S10: =L10+P10+Q10+R10 -> 24999.935 | T10: 0 | U10: =ROUND((L10/E10)*G10,0) -> 0 | V10: 0 | W10: 0 | X10: 0 | Y10: =H10*4.81% -> 616.06468 | Z10: =M10+N10+O10+U10+V10+T10+W10+X10+Y10 -> 816.06468 | AA10: =L10-Z10+Y10+W10+X10+P10+Q10+R10 -> 24799.935
A11: AGS26086 | B11: Mesu Lion Kumar | C11: 46174 | D11: 23567 | E11: 30 | F11: =E11-G11 -> 30 | G11: 0 | H11: =(+D11*49.99999%)/E11*F11 -> 11783.498 | I11: =(H11*50%) -> 5891.7488 | J11: =(1600/E11)*F11 -> 1600 | K11: =(L11-H11-I11-J11) -> 3724.9673 | L11: =(D11-W11)/E11*F11-Y11 -> 23000.214 | M11: 0 | N11: 0 | O11: 200 | P11: 0 | Q11: 0 | R11: 0 | S11: =L11+P11+Q11+R11 -> 23000.214 | T11: 0 | U11: =ROUND((L11/E11)*G11,0) -> 0 | V11: 0 | W11: 0 | X11: 0 | Y11: =H11*4.81% -> 566.78624 | Z11: =M11+N11+O11+U11+V11+T11+W11+X11+Y11 -> 766.78624 | AA11: =L11-Z11+Y11+W11+X11+P11+Q11+R11 -> 22800.214
A12: AGS26087 | B12: Bashaboina Srilatha | C12: 46174 | D12: 46109 | E12: 30 | F12: =E12-G12 -> 30 | G12: 0 | H12: =(+D12*49.99999%)/E12*F12 -> 23054.495 | I12: =(H12*50%) -> 11527.248 | J12: =(1600/E12)*F12 -> 1600 | K12: =(L12-H12-I12-J12) -> 8818.3357 | L12: =(D12-W12)/E12*F12-Y12 -> 45000.079 | M12: 0 | N12: 0 | O12: 200 | P12: 0 | Q12: 0 | R12: 0 | S12: =L12+P12+Q12+R12 -> 45000.079 | T12: 0 | U12: =ROUND((L12/E12)*G12,0) -> 0 | V12: 0 | W12: 0 | X12: 0 | Y12: =H12*4.81% -> 1108.9212 | Z12: =M12+N12+O12+U12+V12+T12+W12+X12+Y12 -> 1308.9212 | AA12: =L12-Z12+Y12+W12+X12+P12+Q12+R12 -> 44800.079
A13: AGS26089 | B13: Pothuraju Haritha | C13: 46174 | D13: 10246 | E13: 30 | F13: =E13-G13 -> 30 | G13: 0 | H13: =(+D13*49.99999%)/E13*F13 -> 5122.999 | I13: =(H13*50%) -> 2561.4995 | J13: =(1600/E13)*F13 -> 1600 | K13: =(L13-H13-I13-J13) -> 715.08529 | L13: =(D13-W13)/E13*F13-Y13 -> 9999.5837 | M13: 0 | N13: 0 | O13: 150 | P13: 0 | Q13: 0 | R13: 0 | S13: =L13+P13+Q13+R13 -> 9999.5837 | T13: 0 | U13: =ROUND((L13/E13)*G13,0) -> 0 | V13: 0 | W13: 0 | X13: 0 | Y13: =H13*4.81% -> 246.41625 | Z13: =M13+N13+O13+U13+V13+T13+W13+X13+Y13 -> 396.41625 | AA13: =L13-Z13+Y13+W13+X13+P13+Q13+R13 -> 9849.5837
A14: AGS26090 | B14: Tirupathi Anusha | C14: 46174 | D14: 12296 | E14: 30 | F14: =E14-G14 -> 30 | G14: 0 | H14: =(+D14*49.99999%)/E14*F14 -> 6147.9988 | I14: =(H14*50%) -> 3073.9994 | J14: =(1600/E14)*F14 -> 1600 | K14: =(L14-H14-I14-J14) -> 1178.2831 | L14: =(D14-W14)/E14*F14-Y14 -> 12000.281 | M14: 0 | N14: 0 | O14: 150 | P14: 0 | Q14: 0 | R14: 0 | S14: =L14+P14+Q14+R14 -> 12000.281 | T14: 0 | U14: =ROUND((L14/E14)*G14,0) -> 0 | V14: 0 | W14: 0 | X14: 0 | Y14: =H14*4.81% -> 295.71874 | Z14: =M14+N14+O14+U14+V14+T14+W14+X14+Y14 -> 445.71874 | AA14: =L14-Z14+Y14+W14+X14+P14+Q14+R14 -> 11850.281
H16: Total | K16: =SUM(AA2:AA15) -> 244651.23

Sheet Bench September
A1: Employee ID | B1: Employee Name | C1: DOJ | D1: CTC | E1: Calendar Days | F1: Paid Days | G1: LOP day's | H1: Basic | I1: HRA | J1: Special Allowance | K1: Other Allowance | L1: Gross Income | M1: Employee PF (12%) | N1: Employee ESI (0.75%) | O1: Professional Tax | P1: Arrears | Q1: Reimbursements | R1: Bonus/ Incentive | S1: Gross Earnings | T1: TDS | U1: LOP Deduction | V1: Other Deductions | W1: Employer PF (12%) | X1: Employer ESI (3.25%) | Y1: Gratuity (4.81%) | Z1: Total Deductions | AA1: Net Salary Payable
A2: AGS26018 | B2: Settybathini Sathish | C2: 46083 | D2: 45000 | E2: 31 | F2: =E2-G2 -> 31 | G2: 0 | H2: =(+D2*49.99999%)/E2*F2 -> 22499.995 | I2: =(H2*50%) -> 11249.998 | J2: =(1600/E2)*F2 -> 1600 | K2: =(L2-H2-I2-J2) -> 6767.757 | L2: =(D2-W2)/E2*F2-Y2 -> 42117.75 | M2: =IF($H2*0.12>1800,1800,$H2*0.12) -> 1800 | N2: =IF(L2<=21000,L2*0.75%,0) -> 0 | O2: 200 | P2: 0 | Q2: 0 | R2: 0 | S2: =L2+P2+Q2+R2 -> 42117.75 | T2: 0 | U2: 0 | V2: 0 | W2: =IF($H2*0.12>1800,1800,$H2*0.12) -> 1800 | X2: =IF(L2<=21000,L2*3.25%,0) -> 0 | Y2: =H2*4.81% -> 1082.2498 | Z2: =M2+N2+O2+U2+V2+T2+W2+X2+Y2 -> 4882.2498 | AA2: =L2-Z2+Y2+W2 -> 40117.75
A3: AGS26014 | B3: Vulli Pavan | C3: 46083 | D3: 50000 | E3: 31 | F3: =E3-G3 -> 31 | G3: 0 | H3: =(+D3*49.99999%)/E3*F3 -> 24999.995 | I3: =(H3*50%) -> 12499.997 | J3: =(1600/E3)*F3 -> 1600 | K3: =(L3-H3-I3-J3) -> 7897.5077 | L3: =(D3-W3)/E3*F3-Y3 -> 46997.5 | M3: =IF($H3*0.12>1800,1800,$H3*0.12) -> 1800 | N3: =IF(L3<=21000,L3*0.75%,0) -> 0 | O3: 200 | P3: 0 | Q3: 0 | R3: 0 | S3: =L3+P3+Q3+R3 -> 46997.5 | T3: 0 | U3: =ROUND((L3/E3)*G3,0) -> 0 | V3: 0 | W3: =IF($H3*0.12>1800,1800,$H3*0.12) -> 1800 | X3: =IF(L3<=21000,L3*3.25%,0) -> 0 | Y3: =H3*4.81% -> 1202.4998 | Z3: =M3+N3+O3+U3+V3+T3+W3+X3+Y3 -> 5002.4998 | AA3: =L3-Z3+Y3+W3 -> 44997.5
A4: AGS26017 | B4: Vavilla Saikumar | C4: 46083 | D4: 45000 | E4: 31 | F4: =E4-G4 -> 31 | G4: 0 | H4: =(+D4*49.99999%)/E4*F4 -> 22499.995 | I4: =(H4*50%) -> 11249.998 | J4: =(1600/E4)*F4 -> 1600 | K4: =(L4-H4-I4-J4) -> 6767.757 | L4: =(D4-W4)/E4*F4-Y4 -> 42117.75 | M4: =IF($H4*0.12>1800,1800,$H4*0.12) -> 1800 | N4: =IF(L4<=21000,L4*0.75%,0) -> 0 | O4: 200 | P4: 0 | Q4: 0 | R4: 0 | S4: =L4+P4+Q4+R4 -> 42117.75 | T4: 0 | U4: =ROUND((L4/E4)*G4,0) -> 0 | V4: 0 | W4: =IF($H4*0.12>1800,1800,$H4*0.12) -> 1800 | X4: =IF(L4<=21000,L4*3.25%,0) -> 0 | Y4: =H4*4.81% -> 1082.2498 | Z4: =M4+N4+O4+U4+V4+T4+W4+X4+Y4 -> 4882.2498 | AA4: =L4-Z4+Y4+W4 -> 40117.75
A5: AGS26013 | B5: Kalepu Vijay | C5: 46083 | D5: 45000 | E5: 31 | F5: =E5-G5 -> 31 | G5: 0 | H5: =(+D5*49.99999%)/E5*F5 -> 22499.995 | I5: =(H5*50%) -> 11249.998 | J5: =(1600/E5)*F5 -> 1600 | K5: =(L5-H5-I5-J5) -> 6767.757 | L5: =(D5-W5)/E5*F5-Y5 -> 42117.75 | M5: =IF($H5*0.12>1800,1800,$H5*0.12) -> 1800 | N5: =IF(L5<=21000,L5*0.75%,0) -> 0 | O5: 200 | P5: 0 | Q5: 0 | R5: 0 | S5: =L5+P5+Q5+R5 -> 42117.75 | T5: 0 | U5: =ROUND((L5/E5)*G5,0) -> 0 | V5: 0 | W5: =IF($H5*0.12>1800,1800,$H5*0.12) -> 1800 | X5: =IF(L5<=21000,L5*3.25%,0) -> 0 | Y5: =H5*4.81% -> 1082.2498 | Z5: =M5+N5+O5+U5+V5+T5+W5+X5+Y5 -> 4882.2498 | AA5: =L5-Z5+Y5+W5 -> 40117.75
A6: AGS26021 | B6: Kontham Sushma | C6: 46083 | D6: 50000 | E6: 31 | F6: =E6-G6 -> 31 | G6: 0 | H6: =(+D6*49.99999%)/E6*F6 -> 24999.995 | I6: =(H6*50%) -> 12499.997 | J6: =(1600/E6)*F6 -> 1600 | K6: =(L6-H6-I6-J6) -> 7897.5077 | L6: =(D6-W6)/E6*F6-Y6 -> 46997.5 | M6: =IF($H6*0.12>1800,1800,$H6*0.12) -> 1800 | N6: =IF(L6<=21000,L6*0.75%,0) -> 0 | O6: 200 | P6: 0 | Q6: 0 | R6: 0 | S6: =L6+P6+Q6+R6 -> 46997.5 | T6: 0 | U6: =ROUND((L6/E6)*G6,0) -> 0 | V6: 0 | W6: =IF($H6*0.12>1800,1800,$H6*0.12) -> 1800 | X6: =IF(L6<=21000,L6*3.25%,0) -> 0 | Y6: =H6*4.81% -> 1202.4998 | Z6: =M6+N6+O6+U6+V6+T6+W6+X6+Y6 -> 5002.4998 | AA6: =L6-Z6+Y6+W6 -> 44997.5
A7: AGS26026 | B7: Surampudi Roop Sai | C7: 46083 | D7: 60000 | E7: 31 | F7: =E7-G7 -> 31 | G7: 0 | H7: =(+D7*49.99999%)/E7*F7 -> 29999.994 | I7: =(H7*50%) -> 14999.997 | J7: =(1600/E7)*F7 -> 1600 | K7: =(L7-H7-I7-J7) -> 10157.009 | L7: =(D7-W7)/E7*F7-Y7 -> 56757 | M7: =IF($H7*0.12>1800,1800,$H7*0.12) -> 1800 | N7: =IF(L7<=21000,L7*0.75%,0) -> 0 | O7: 200 | P7: 0 | Q7: 0 | R7: 0 | S7: =L7+P7+Q7+R7 -> 56757 | T7: 0 | U7: =ROUND((L7/E7)*G7,0) -> 0 | V7: 0 | W7: =IF($H7*0.12>1800,1800,$H7*0.12) -> 1800 | X7: =IF(L7<=21000,L7*3.25%,0) -> 0 | Y7: =H7*4.81% -> 1442.9997 | Z7: =M7+N7+O7+U7+V7+T7+W7+X7+Y7 -> 5242.9997 | AA7: =L7-Z7+Y7+W7 -> 54757
A8: AGS26029 | B8: Mula Sai Preetham Goud | C8: 46083 | D8: 35000 | E8: 31 | F8: =E8-G8 -> 31 | G8: 0 | H8: =(+D8*49.99999%)/E8*F8 -> 17499.996 | I8: =(H8*50%) -> 8749.9982 | J8: =(1600/E8)*F8 -> 1600 | K8: =(L8-H8-I8-J8) -> 4508.2554 | L8: =(D8-W8)/E8*F8-Y8 -> 32358.25 | M8: =IF($H8*0.12>1800,1800,$H8*0.12) -> 1800 | N8: =IF(L8<=21000,L8*0.75%,0) -> 0 | O8: 200 | P8: 0 | Q8: 0 | R8: 0 | S8: =L8+P8+Q8+R8 -> 32358.25 | T8: 0 | U8: =ROUND((L8/E8)*G8,0) -> 0 | V8: 0 | W8: =IF($H8*0.12>1800,1800,$H8*0.12) -> 1800 | X8: =IF(L8<=21000,L8*3.25%,0) -> 0 | Y8: =H8*4.81% -> 841.74983 | Z8: =M8+N8+O8+U8+V8+T8+W8+X8+Y8 -> 4641.7498 | AA8: =L8-Z8+Y8+W8 -> 30358.25
A9: AGS26030 | B9: Sruthin Kumar Basa | C9: 46083 | D9: 35000 | E9: 31 | F9: =E9-G9 -> 31 | G9: 0 | H9: =(+D9*49.99999%)/E9*F9 -> 17499.996 | I9: =(H9*50%) -> 8749.9982 | J9: =(1600/E9)*F9 -> 1600 | K9: =(L9-H9-I9-J9) -> 4508.2554 | L9: =(D9-W9)/E9*F9-Y9 -> 32358.25 | M9: =IF($H9*0.12>1800,1800,$H9*0.12) -> 1800 | N9: =IF(L9<=21000,L9*0.75%,0) -> 0 | O9: 200 | P9: 0 | Q9: 0 | R9: 0 | S9: =L9+P9+Q9+R9 -> 32358.25 | T9: 0 | U9: =ROUND((L9/E9)*G9,0) -> 0 | V9: 0 | W9: =IF($H9*0.12>1800,1800,$H9*0.12) -> 1800 | X9: =IF(L9<=21000,L9*3.25%,0) -> 0 | Y9: =H9*4.81% -> 841.74983 | Z9: =M9+N9+O9+U9+V9+T9+W9+X9+Y9 -> 4641.7498 | AA9: =L9-Z9+Y9+W9 -> 30358.25
A10: AGS26035 | B10: Varakantham Surender Reddy | C10: 46083 | D10: 60000 | E10: 31 | F10: =E10-G10 -> 31 | G10: 0 | H10: =(+D10*49.99999%)/E10*F10 -> 29999.994 | I10: =(H10*50%) -> 14999.997 | J10: =(1600/E10)*F10 -> 1600 | K10: =(L10-H10-I10-J10) -> 10157.009 | L10: =(D10-W10)/E10*F10-Y10 -> 56757 | M10: =IF($H10*0.12>1800,1800,$H10*0.12) -> 1800 | N10: =IF(L10<=21000,L10*0.75%,0) -> 0 | O10: 200 | P10: 0 | Q10: 0 | R10: 0 | S10: =L10+P10+Q10+R10 -> 56757 | T10: 0 | U10: 0 | V10: 0 | W10: =IF($H10*0.12>1800,1800,$H10*0.12) -> 1800 | X10: =IF(L10<=21000,L10*3.25%,0) -> 0 | Y10: =H10*4.81% -> 1442.9997 | Z10: =M10+N10+O10+U10+V10+T10+W10+X10+Y10 -> 5242.9997 | AA10: =L10-Z10+Y10+W10 -> 54757
A11: AGS26072 | B11: Mohd Sameer | C11: 46146 | D11: 15000 | E11: 31 | F11: =E11-G11 -> 31 | G11: 0 | H11: =(+D11*49.99999%)/E11*F11 -> 7499.9985 | I11: =(H11*50%) -> 3749.9992 | J11: =(1600/E11)*F11 -> 1600 | K11: =(L11-H11-I11-J11) -> 889.2525 | L11: =(D11-W11)/E11*F11-Y11 -> 13739.25 | M11: =IF($H11*0.12>1800,1800,$H11*0.12) -> 899.99982 | N11: 0 | O11: 150 | P11: 0 | Q11: 0 | R11: 0 | S11: =L11+P11+Q11+R11 -> 13739.25 | T11: 0 | U11: 0 | V11: 0 | W11: =IF($H11*0.12>1800,1800,$H11*0.12) -> 899.99982 | X11: 0 | Y11: =H11*4.81% -> 360.74993 | Z11: =M11+N11+O11+U11+V11+T11+W11+X11+Y11 -> 2310.7496 | AA11: =L11-Z11+Y11+W11 -> 12689.25
A14: Oct Bench | B14: Thumula Dinesh | D14: 23000 | E14: 30 | F14: =E14-G14 -> 30 | H14: =(+D14*49.99999%)/E14*F14 -> 11499.998 | I14: =(H14*50%) -> 5749.9988 | J14: =(1600/E14)*F14 -> 1600 | K14: =(L14-H14-I14-J14) -> 2216.8538 | L14: =(D14-W14)/E14*F14-Y14 -> 21066.85 | M14: =IF($H14*0.12>1800,1800,$H14*0.12) -> 1379.9997 | N14: 0 | O14: 150 | P14: 0 | Q14: 0 | R14: 0 | S14: =L14+P14+Q14+R14 -> 21066.85 | T14: 0 | U14: 0 | V14: 0 | W14: =IF($H14*0.12>1800,1800,$H14*0.12) -> 1379.9997 | X14: 4 | Y14: =H14*4.81% -> 553.14989 | Z14: =M14+N14+O14+U14+V14+T14+W14+X14+Y14 -> 3467.1493 | AA14: =L14-Z14+Y14+W14 -> 19532.851
A15: Oct Bench | B15: Bommala Naveen Kumar | D15: 45000 | E15: 30 | F15: 30 | H15: =(+D15*49.99999%)/E15*F15 -> 22499.995 | I15: =(H15*50%) -> 11249.998 | J15: =(1600/E15)*F15 -> 1600 | K15: =(L15-H15-I15-J15) -> 6767.757 | L15: =(D15-W15)/E15*F15-Y15 -> 42117.75 | M15: =IF($H15*0.12>1800,1800,$H15*0.12) -> 1800 | N15: 0 | O15: 150 | P15: 0 | Q15: 0 | R15: 0 | S15: =L15+P15+Q15+R15 -> 42117.75 | T15: 0 | U15: 0 | V15: 0 | W15: =IF($H15*0.12>1800,1800,$H15*0.12) -> 1800 | X15: 5 | Y15: =H15*4.81% -> 1082.2498 | Z15: =M15+N15+O15+U15+V15+T15+W15+X15+Y15 -> 4837.2498 | AA15: =L15-Z15+Y15+W15 -> 40162.75
A16: Oct Bench | B16: Narmeta Srujan Reddy | D16: 15000 | E16: 30 | F16: 30 | H16: =(+D16*49.99999%)/E16*F16 -> 7499.9985 | I16: =(H16*50%) -> 3749.9992 | J16: =(1600/E16)*F16 -> 1600 | K16: =(L16-H16-I16-J16) -> 889.2525 | L16: =(D16-W16)/E16*F16-Y16 -> 13739.25 | M16: =IF($H16*0.12>1800,1800,$H16*0.12) -> 899.99982 | N16: 0 | O16: 150 | P16: 0 | Q16: 0 | R16: 0 | S16: =L16+P16+Q16+R16 -> 13739.25 | T16: 0 | U16: 0 | V16: 0 | W16: =IF($H16*0.12>1800,1800,$H16*0.12) -> 899.99982 | X16: 6 | Y16: =H16*4.81% -> 360.74993 | Z16: =M16+N16+O16+U16+V16+T16+W16+X16+Y16 -> 2316.7496 | AA16: =L16-Z16+Y16+W16 -> 12683.25
A17: Oct Bench | B17: Yanamagandla Raghavendar | D17: 45000 | E17: 30 | F17: 30 | H17: =(+D17*49.99999%)/E17*F17 -> 22499.995 | I17: =(H17*50%) -> 11249.998 | J17: =(1600/E17)*F17 -> 1600 | K17: =(L17-H17-I17-J17) -> 6767.757 | L17: =(D17-W17)/E17*F17-Y17 -> 42117.75 | M17: =IF($H17*0.12>1800,1800,$H17*0.12) -> 1800 | N17: 0 | O17: 150 | P17: 0 | Q17: 0 | R17: 0 | S17: =L17+P17+Q17+R17 -> 42117.75 | T17: 0 | U17: 0 | V17: 0 | W17: =IF($H17*0.12>1800,1800,$H17*0.12) -> 1800 | X17: 7 | Y17: =H17*4.81% -> 1082.2498 | Z17: =M17+N17+O17+U17+V17+T17+W17+X17+Y17 -> 4839.2498 | AA17: =L17-Z17+Y17+W17 -> 40160.75

Sheet Bench Employees
A1: Employee ID | B1: Employee Name | C1: DOJ | D1: CTC | E1: Calendar Days | F1: Paid Days | G1: LOP day's | H1: Basic | I1: HRA | J1: Special Allowance | K1: Other Allowance | L1: Gross Income | M1: Employee PF (12%) | N1: Employee ESI (0.75%) | O1: Professional Tax | P1: Arrears | Q1: Reimbursements | R1: Bonus/ Incentive | S1: Gross Earnings | T1: TDS | U1: LOP Deduction | V1: Other Deductions | W1: Employer PF (12%) | X1: Employer ESI (3.25%) | Y1: Gratuity (4.81%) | Z1: Total Deductions | AA1: Net Salary Payable
A2: AGS26016 | B2: Manisha Ashroba Virkar | C2: 46083 | D2: 45000 | E2: 31 | F2: =E2-G2 -> 31 | G2: 0 | H2: =(+D2*49.99999%)/E2*F2 -> 22499.995 | I2: =(H2*50%) -> 11249.998 | J2: =(1600/E2)*F2 -> 1600 | K2: =(L2-H2-I2-J2) -> 6767.757 | L2: =(D2-W2)/E2*F2-Y2 -> 42117.75 | M2: =IF($H2*0.12>1800,1800,$H2*0.12) -> 1800 | N2: =IF(L2<=21000,L2*0.75%,0) -> 0 | O2: 200 | P2: 0 | Q2: 0 | R2: 0 | S2: =L2+P2+Q2+R2 -> 42117.75 | T2: 0 | U2: =ROUND((L2/E2)*G2,0) -> 0 | V2: 0 | W2: =IF($H2*0.12>1800,1800,$H2*0.12) -> 1800 | X2: =IF(L2<=21000,L2*3.25%,0) -> 0 | Y2: =H2*4.81% -> 1082.2498 | Z2: =M2+N2+O2+U2+V2+T2+W2+X2+Y2 -> 4882.2498 | AA2: =L2-Z2+Y2+W2 -> 40117.75
A3: AGS26015 | B3: Karne Narsimha Reddy | C3: 46083 | D3: 45000 | E3: 31 | F3: =E3-G3 -> 31 | G3: 0 | H3: =(+D3*49.99999%)/E3*F3 -> 22499.995 | I3: =(H3*50%) -> 11249.998 | J3: =(1600/E3)*F3 -> 1600 | K3: =(L3-H3-I3-J3) -> 6767.757 | L3: =(D3-W3)/E3*F3-Y3 -> 42117.75 | M3: =IF($H3*0.12>1800,1800,$H3*0.12) -> 1800 | N3: =IF(L3<=21000,L3*0.75%,0) -> 0 | O3: 200 | P3: 0 | Q3: 0 | R3: 0 | S3: =L3+P3+Q3+R3 -> 42117.75 | T3: 0 | U3: =ROUND((L3/E3)*G3,0) -> 0 | V3: 0 | W3: =IF($H3*0.12>1800,1800,$H3*0.12) -> 1800 | X3: =IF(L3<=21000,L3*3.25%,0) -> 0 | Y3: =H3*4.81% -> 1082.2498 | Z3: =M3+N3+O3+V3+T3+W3+X3+Y3 -> 4882.2498 | AA3: =L3-Z3+Y3+W3 -> 40117.75
A4: AGS26028 | B4: Mohammed Abdul Moid | C4: 46083 | D4: 15000 | E4: 31 | F4: =E4-G4 -> 31 | G4: 0 | H4: =(+D4*49.99999%)/E4*F4 -> 7499.9985 | I4: =(H4*50%) -> 3749.9992 | J4: =(1600/E4)*F4 -> 1600 | K4: =(L4-H4-I4-J4) -> 889.2525 | L4: =(D4-W4)/E4*F4-Y4 -> 13739.25 | M4: =IF($H4*0.12>1800,1800,$H4*0.12) -> 899.99982 | N4: 0 | O4: 200 | P4: 0 | Q4: 0 | R4: 0 | S4: =L4+P4+Q4+R4 -> 13739.25 | T4: 0 | U4: =ROUND((L4/E4)*G4,0) -> 0 | V4: 0 | W4: =IF($H4*0.12>1800,1800,$H4*0.12) -> 899.99982 | X4: 0 | Y4: =H4*4.81% -> 360.74993 | Z4: =M4+N4+O4+U4+V4+T4+W4+X4+Y4 -> 2360.7496 | AA4: =L4-Z4+Y4+W4 -> 12639.25
A5: AGS26043 | B5: Chebrolu Yashaswini | C5: 46113 | D5: 30000 | E5: 31 | F5: =E5-G5 -> 31 | G5: 0 | H5: =(+D5*49.99999%)/E5*F5 -> 14999.997 | I5: =(H5*50%) -> 7499.9985 | J5: =(1600/E5)*F5 -> 1600 | K5: =(L5-H5-I5-J5) -> 3378.505 | L5: =(D5-W5)/E5*F5-Y5 -> 27478.501 | M5: =IF($H5*0.12>1800,1800,$H5*0.12) -> 1799.9996 | N5: =IF(L5<=21000,L5*0.75%,0) -> 0 | O5: 200 | P5: 0 | Q5: 0 | R5: 0 | S5: =L5+P5+Q5+R5 -> 27478.501 | T5: 0 | U5: 0 | V5: 0 | W5: =IF($H5*0.12>1800,1800,$H5*0.12) -> 1799.9996 | X5: =IF(L5<=21000,L5*3.25%,0) -> 0 | Y5: =H5*4.81% -> 721.49986 | Z5: =M5+N5+O5+U5+V5+T5+W5+X5+Y5 -> 4521.4991 | AA5: =L5-Z5+Y5+W5 -> 25478.501
A6: AGS26053 | B6: Palavelli Praveen Reddy | C6: 46113 | D6: 15000 | E6: 31 | F6: =E6-G6 -> 31 | G6: 0 | H6: =(+D6*49.99999%)/E6*F6 -> 7499.9985 | I6: =(H6*50%) -> 3749.9992 | J6: =(1600/E6)*F6 -> 1600 | K6: =(L6-H6-I6-J6) -> 889.2525 | L6: =(D6-W6)/E6*F6-Y6 -> 13739.25 | M6: =IF($H6*0.12>1800,1800,$H6*0.12) -> 899.99982 | N6: 0 | O6: 150 | P6: 0 | Q6: 0 | R6: 0 | S6: =L6+P6+Q6+R6 -> 13739.25 | T6: 0 | U6: 0 | V6: 0 | W6: =IF($H6*0.12>1800,1800,$H6*0.12) -> 899.99982 | X6: 0 | Y6: =H6*4.81% -> 360.74993 | Z6: =M6+N6+O6+U6+V6+T6+W6+X6+Y6 -> 2310.7496 | AA6: =L6-Z6+Y6+W6 -> 12689.25
A7: AGS26054 | B7: Yaramothu Himaja | C7: 46113 | D7: 15000 | E7: 31 | F7: =E7-G7 -> 31 | G7: 0 | H7: =(+D7*49.99999%)/E7*F7 -> 7499.9985 | I7: =(H7*50%) -> 3749.9992 | J7: =(1600/E7)*F7 -> 1600 | K7: =(L7-H7-I7-J7) -> 889.2525 | L7: =(D7-W7)/E7*F7-Y7 -> 13739.25 | M7: =IF($H7*0.12>1800,1800,$H7*0.12) -> 899.99982 | N7: 0 | O7: 150 | P7: 0 | Q7: 0 | R7: 0 | S7: =L7+P7+Q7+R7 -> 13739.25 | T7: 0 | U7: 0 | V7: 0 | W7: =IF($H7*0.12>1800,1800,$H7*0.12) -> 899.99982 | X7: 0 | Y7: =H7*4.81% -> 360.74993 | Z7: =M7+N7+O7+U7+V7+T7+W7+X7+Y7 -> 2310.7496 | AA7: =L7-Z7+Y7+W7 -> 12689.25
A8: AGS26058 | B8: Matha Sai Prasad | C8: 46113 | D8: 15000 | E8: 31 | F8: =E8-G8 -> 31 | G8: 0 | H8: =(+D8*49.99999%)/E8*F8 -> 7499.9985 | I8: =(H8*50%) -> 3749.9992 | J8: =(1600/E8)*F8 -> 1600 | K8: =(L8-H8-I8-J8) -> 889.2525 | L8: =(D8-W8)/E8*F8-Y8 -> 13739.25 | M8: =IF($H8*0.12>1800,1800,$H8*0.12) -> 899.99982 | N8: 0 | O8: 150 | P8: 0 | Q8: 0 | R8: 0 | S8: =L8+P8+Q8+R8 -> 13739.25 | T8: 0 | U8: 0 | V8: 0 | W8: =IF($H8*0.12>1800,1800,$H8*0.12) -> 899.99982 | X8: 0 | Y8: =H8*4.81% -> 360.74993 | Z8: =M8+N8+O8+U8+V8+T8+W8+X8+Y8 -> 2310.7496 | AA8: =L8-Z8+Y8+W8 -> 12689.25
A9: AGS26059 | B9: Chamakuri Raghuram | C9: 46113 | D9: 15000 | E9: 31 | F9: =E9-G9 -> 31 | G9: 0 | H9: =(+D9*49.99999%)/E9*F9 -> 7499.9985 | I9: =(H9*50%) -> 3749.9992 | J9: =(1600/E9)*F9 -> 1600 | K9: =(L9-H9-I9-J9) -> 889.2525 | L9: =(D9-W9)/E9*F9-Y9 -> 13739.25 | M9: =IF($H9*0.12>1800,1800,$H9*0.12) -> 899.99982 | N9: 0 | O9: 150 | P9: 0 | Q9: 0 | R9: 0 | S9: =L9+P9+Q9+R9 -> 13739.25 | T9: 0 | U9: 0 | V9: 0 | W9: =IF($H9*0.12>1800,1800,$H9*0.12) -> 899.99982 | X9: 0 | Y9: =H9*4.81% -> 360.74993 | Z9: =M9+N9+O9+U9+V9+T9+W9+X9+Y9 -> 2310.7496 | AA9: =L9-Z9+Y9+W9 -> 12689.25
A10: AGS26065 | B10: Boddupalli Krishna Prasad | C10: 46146 | D10: 30000 | E10: 31 | F10: =E10-G10 -> 31 | G10: 0 | H10: =(+D10*49.99999%)/E10*F10 -> 14999.997 | I10: =(H10*50%) -> 7499.9985 | J10: =(1600/E10)*F10 -> 1600 | K10: =(L10-H10-I10-J10) -> 3378.505 | L10: =(D10-W10)/E10*F10-Y10 -> 27478.501 | M10: =IF($H10*0.12>1800,1800,$H10*0.12) -> 1799.9996 | N10: =IF(L10<=21000,L10*0.75%,0) -> 0 | O10: 200 | P10: 0 | Q10: 0 | R10: 0 | S10: =L10+P10+Q10+R10 -> 27478.501 | T10: 0 | U10: 0 | V10: 0 | W10: =IF($H10*0.12>1800,1800,$H10*0.12) -> 1799.9996 | X10: =IF(L10<=21000,L10*3.25%,0) -> 0 | Y10: =H10*4.81% -> 721.49986 | Z10: =M10+N10+O10+U10+V10+T10+W10+X10+Y10 -> 4521.4991 | AA10: =L10-Z10+Y10+W10 -> 25478.501
A11: AGS26076 | B11: Shaik Arif | C11: 46148 | D11: 15000 | E11: 31 | F11: =E11-G11 -> 31 | G11: 0 | H11: =(+D11*49.99999%)/E11*F11 -> 7499.9985 | I11: =(H11*50%) -> 3749.9992 | J11: =(1600/E11)*F11 -> 1600 | K11: =(L11-H11-I11-J11) -> 889.2525 | L11: =(D11-W11)/E11*F11-Y11 -> 13739.25 | M11: =IF($H11*0.12>1800,1800,$H11*0.12) -> 899.99982 | N11: 0 | O11: 150 | P11: 0 | Q11: 0 | R11: 0 | S11: =L11+P11+Q11+R11 -> 13739.25 | T11: 0 | U11: 0 | V11: 0 | W11: =IF($H11*0.12>1800,1800,$H11*0.12) -> 899.99982 | X11: 0 | Y11: =H11*4.81% -> 360.74993 | Z11: =M11+N11+O11+U11+V11+T11+W11+X11+Y11 -> 2310.7496 | AA11: =L11-Z11+Y11+W11 -> 12689.25
A12: AGS26073 | B12: KONDAPALLY AKHIL | C12: 46113 | D12: 100000 | E12: 31 | F12: =E12-G12 -> 31 | G12: 0 | H12: =(+D12*49.99999%)/E12*F12 -> 49999.99 | I12: =(H12*50%) -> 24999.995 | J12: =(1600/E12)*F12 -> 1600 | K12: =(L12-H12-I12-J12) -> 19195.015 | L12: =(D12-W12)/E12*F12-Y12 -> 95795 | M12: =IF($H12*0.12>1800,1800,$H12*0.12) -> 1800 | N12: =IF(L12<=21000,L12*0.75%,0) -> 0 | O12: 200 | P12: 0 | Q12: 0 | R12: 0 | S12: =L12+P12+Q12+R12 -> 95795 | T12: 0 | U12: 0 | V12: 0 | W12: =IF($H12*0.12>1800,1800,$H12*0.12) -> 1800 | X12: =IF(L12<=21000,L12*3.25%,0) -> 0 | Y12: =H12*4.81% -> 2404.9995 | Z12: =M12+N12+O12+U12+V12+T12+W12+X12+Y12 -> 6204.9995 | AA12: =L12-Z12+Y12+W12 -> 93795
A13: AGS26073 | B13: Boya Indrasena Naidu | C13: 46146 | D13: 15000 | E13: 31 | F13: =E13-G13 -> 31 | G13: 0 | H13: =(+D13*49.99999%)/E13*F13 -> 7499.9985 | I13: =(H13*50%) -> 3749.9992 | J13: =(1600/E13)*F13 -> 1600 | K13: =(L13-H13-I13-J13) -> 889.2525 | L13: =(D13-W13)/E13*F13-Y13 -> 13739.25 | M13: =IF($H13*0.12>1800,1800,$H13*0.12) -> 899.99982 | N13: 0 | O13: 150 | P13: 0 | Q13: 0 | R13: 0 | S13: =L13+P13+Q13+R13 -> 13739.25 | T13: 0 | U13: 0 | V13: 0 | W13: =IF($H13*0.12>1800,1800,$H13*0.12) -> 899.99982 | X13: 0 | Y13: =H13*4.81% -> 360.74993 | Z13: =M13+N13+O13+U13+V13+T13+W13+X13+Y13 -> 2310.7496 | AA13: =L13-Z13+Y13+W13+X13 -> 12689.25
A14: AGS26062 | B14: K Tharun Kumar Reddy | C14: 46146 | D14: 15000 | E14: 31 | F14: =E14-G14 -> 31 | G14: 0 | H14: =(+D14*49.99999%)/E14*F14 -> 7499.9985 | I14: =(H14*50%) -> 3749.9992 | J14: =(1600/E14)*F14 -> 1600 | K14: =(L14-H14-I14-J14) -> 889.2525 | L14: =(D14-W14)/E14*F14-Y14 -> 13739.25 | M14: =IF($H14*0.12>1800,1800,$H14*0.12) -> 899.99982 | N14: 0 | O14: 150 | P14: 0 | Q14: 0 | R14: 0 | S14: =L14+P14+Q14+R14 -> 13739.25 | T14: 0 | U14: 0 | V14: 0 | W14: =IF($H14*0.12>1800,1800,$H14*0.12) -> 899.99982 | X14: 0 | Y14: =H14*4.81% -> 360.74993 | Z14: =M14+N14+O14+U14+V14+T14+W14+X14+Y14 -> 2310.7496 | AA14: =L14-Z14+Y14+W14+X14 -> 12689.25
A15: AGS26061 | B15: Indla Kiran Kumar | C15: 46146 | D15: 35000 | E15: 31 | F15: =E15-G15 -> 31 | G15: 0 | H15: =(+D15*49.99999%)/E15*F15 -> 17499.996 | I15: =(H15*50%) -> 8749.9982 | J15: =(1600/E15)*F15 -> 1600 | K15: =(L15-H15-I15-J15) -> 4508.2554 | L15: =(D15-W15)/E15*F15-Y15 -> 32358.25 | M15: =IF($H15*0.12>1800,1800,$H15*0.12) -> 1800 | N15: =IF(L15<=21000,L15*0.75%,0) -> 0 | O15: 200 | P15: 0 | Q15: 0 | R15: 0 | S15: =L15+P15+Q15+R15 -> 32358.25 | T15: 0 | U15: 0 | V15: 0 | W15: =IF($H15*0.12>1800,1800,$H15*0.12) -> 1800 | X15: =IF(L15<=21000,L15*3.25%,0) -> 0 | Y15: =H15*4.81% -> 841.74983 | Z15: =M15+N15+O15+U15+V15+T15+W15+X15+Y15 -> 4641.7498 | AA15: =L15-Z15+Y15+W15 -> 30358.25
A16: AGS26045 | B16: Chebrolu Monika | C16: 46113 | D16: 50000 | E16: 31 | F16: 31 | H16: =(+D16*49.99999%)/E16*F16 -> 24999.995 | I16: =(H16*50%) -> 12499.997 | J16: =(1600/E16)*F16 -> 1600 | K16: =(L16-H16-I16-J16) -> 7897.5077 | L16: =(D16-W16)/E16*F16-Y16 -> 46997.5 | M16: =IF($H16*0.12>1800,1800,$H16*0.12) -> 1800 | N16: =IF(L16<=21000,L16*0.75%,0) -> 0 | O16: 200 | P16: 0 | Q16: 0 | R16: 0 | S16: =L16+P16+Q16+R16 -> 46997.5 | T16: 0 | U16: 0 | V16: 0 | W16: =IF($H16*0.12>1800,1800,$H16*0.12) -> 1800 | X16: =IF(L16<=21000,L16*3.25%,0) -> 0 | Y16: =H16*4.81% -> 1202.4998 | Z16: =M16+N16+O16+U16+V16+T16+W16+X16+Y16 -> 5002.4998 | AA16: =L16-Z16+Y16+W16 -> 44997.5
C18: Total | K18: =SUM(AA2:AA17) -> 401807.26

Sheet LOP
A1: Employee ID | B1: Employee Name | C1: LOP day's
A2: AGS26011 | B2: Siddula Hemasai | C2: 1
A3: AGS26010 | B3: Vemula Varshith | C3: 1
A4: AGS26019 | B4: Nelapatla Srinivas | C4: 1
C7: =SUM(C2:C6) -> 3

Sheet Salaries_to be processed
A1: Sno | B1: Employee ID | C1: Employee Name | D1: DOJ | E1: Net Salary Payable | F1: Bank Account Number | G1: IFSC code | H1: Bank Name | I1: Remarks
A2: 1 | B2: AGS26038 | C2: Ainala Saiesha | D2: 46086 | E2: =VLOOKUP(B2,Employees!A2:AB2,28,0) -> 93795 | F2: 99980130961795 | G2: FDRL0001555 | H2: Federal Bank
A3: 2 | B3: AGS26004 | C3: Ande Sharath Chandra | D3: 46055 | E3: =VLOOKUP(B3,Consultant!A1:H4,8,0) -> 79800 | F3: 50100677371816 | G3: HDFC0001042 | H3: HDFC Bank
A4: 3 | B4: AGS26005 | C4: Tanakala Janardhan | D4: 46055 | E4: =VLOOKUP(B4,Consultant!A2:H4,8,0) -> 69800 | F4: 99980130961985 | G4: FDRL0001555 | H4: Federal Bank
A5: 4 | B5: AGS26024 | C5: Priya Darshini Pola | D5: 46072 | E5: =VLOOKUP(B5,Consultant!A4:H6,8,0) -> 79800 | F5: 99980130963916 | G5: FDRL0001555 | H5: Federal Bank
A6: 5 | B6: AGS26011 | C6: Siddula Hemasai | D6: 46083 | E6: =VLOOKUP(B6,'Tech Team'!B1:AB21,27,0) -> 38713.825 | F6: 3327101004003 | G6: CNRB0003327 | H6: Canara Bank
A7: 6 | B7: AGS26010 | C7: Vemula Varshith | D7: 46083 | E7: =VLOOKUP(B7,'Tech Team'!B2:AB23,27,0) -> 29279.642 | F7: 99980130961993 | G7: FDRL0001555 | H7: Federal Bank
A8: 7 | B8: AGS26019 | C8: Nelapatla Srinivas | D8: 46083 | E8: =VLOOKUP(B8,'Tech Team'!B2:AB24,27,0) -> 18875.089 | F8: 99980130961951 | G8: FDRL0001555 | H8: Federal Bank
A9: 8 | B9: AGS26023 | C9: Bobbarala Varshini | D9: 46083 | E9: =VLOOKUP(B9,'Tech Team'!B5:AB29,27,0) -> 30358.25 | F9: 99980130961878 | G9: FDRL0001555 | H9: Federal Bank
A10: 9 | B10: AGS26032 | C10: Vempadapu Uday Sai Tarun | D10: 46083 | E10: =VLOOKUP(B10,'Tech Team'!B6:AB34,27,0) -> 14351.15 | F10: 37182972098 | G10: SBIN0008054 | H10: State Bank of India
A11: 10 | B11: AGS26034 | C11: Sripada Shivakumar | D11: 46083 | E11: =VLOOKUP(B11,'Tech Team'!B6:AB35,27,0) -> 44997.5 | F11: 15550100112371 | G11: FDRL0001555 | H11: Federal Bank
A12: 11 | B12: AGS26041 | C12: Sudhagani Sai Charan | D12: 46113 | E12: =VLOOKUP(B12,'Tech Team'!B8:AB37,27,0) -> 19486.851 | F12: 15550100112314 | G12: FDRL0001555 | H12: Federal Bank
A13: 12 | B13: AGS26047 | C13: Upadhyayula Naga Lakshmi Deepthi | D13: 46114 | E13: =VLOOKUP(B13,'Tech Team'!B9:AB40,27,0) -> 19486.851 | F13: 55560103431927 | G13: FDRL0005556 | H13: Federal Bank
A14: 13 | B14: AGS26048 | C14: Rapolu Rekha | D14: 46113 | E14: =VLOOKUP(B14,Employees!A2:AB9,28,0) -> 21198.751 | F14: 15550100112355 | G14: FDRL0001555 | H14: Federal Bank
A15: 14 | B15: AGS26049 | C15: Ragiru Nikhitha | D15: 46113 | E15: =VLOOKUP(B15,'Tech Team'!B10:AB42,27,0) -> 12689.25 | F15: 15550100112280 | G15: FDRL0001555 | H15: Federal Bank
A16: 15 | B16: AGS26051 | C16: Mundlamuri Mrudula | D16: 46113 | E16: =VLOOKUP(B16,Employees!A2:AB9,28,0) -> 19911.858 | F16: 15550100112272 | G16: FDRL0001555 | H16: Federal Bank
A17: 16 | B17: AGS26031 | C17: Y Raghavendar | D17: 46113 | E17: =VLOOKUP(B17,'Tech Team'!B11:AB46,27,0) -> 40117.75 | F17: 99980130961787 | G17: FDRL0001555 | H17: Federal Bank
A18: 17 | B18: AGS26056 | C18: Bommala Naveen Kumar | D18: 46113 | E18: =VLOOKUP(B18,'Tech Team'!B11:AB47,27,0) -> 40117.75 | F18: 37097117593 | G18: SBIN0008833 | H18: State Bank of India
A19: 18 | B19: AGS26057 | C19: Odeti Srinivas | D19: 46113 | E19: =VLOOKUP(B19,Employees!A2:AB9,28,0) -> 36865 | F19: 99980130961779 | G19: FDRL0001555 | H19: Federal Bank
A20: 19 | B20: AGS26025 | C20: Tumula Dinesh Kumar | D20: 46113 | E20: =VLOOKUP(B20,'Tech Team'!B13:AB51,27,0) -> 19486.851 | F20: 44610100006654 | G20: BARB0SIDDIP | H20: Bank of Baroda
A21: 20 | B21: AGS26060 | C21: Thallada Venkatasagar | D21: 46114 | E21: =VLOOKUP(B21,Employees!A2:AB9,28,0) -> 30358 | F21: 15550100112363 | G21: FDRL0001555 | H21: Federal Bank
A22: 21 | B22: AGS26074 | C22: Manikonda Nagasurya Koundinya | D22: 46113 | E22: =VLOOKUP(B22,'Tech Team'!B15:AB55,27,0) -> 28731.342 | F22: 180701000002091 | G22: IOBA0001807 | H22: Indian Overseas Bank
A23: 22 | B23: AGS26061 | C23: Indla Kiran Kumar | D23: 46146 | E23: =VLOOKUP(B23,'Tech Team'!B16:AB56,27,0) -> 30358.25 | F23: 99980130961803 | G23: FDRL0001555 | H23: Federal Bank
A24: 23 | B24: AGS26063 | C24: Bondada Jayanth | D24: 46146 | E24: =VLOOKUP(B24,'Tech Team'!B16:AB58,27,0) -> 19486.851 | F24: 99980130961811 | G24: FDRL0001555 | H24: Federal Bank
A25: 24 | B25: AGS26066 | C25: Mohammad Sulthan | D25: 46146 | E25: =VLOOKUP(B25,'Tech Team'!B17:AB60,27,0) -> 40117.75 | F25: 62412658053 | G25: SBIN0020947 | H25: State Bank of India
A26: 25 | B26: AGS26067 | C26: Md Imran Khan | D26: 46146 | E26: =VLOOKUP(B26,'Tech Team'!B17:AB61,27,0) -> 12689.25 | F26: 40592463089 | G26: SBIN0020248 | H26: State Bank of India
A27: 26 | B27: AGS26068 | C27: Narmeta Srujanreddy | D27: 46146 | E27: =VLOOKUP(B27,'Tech Team'!B18:AB62,27,0) -> 12689.25 | F27: 1814100100000327 | G27: PUNB0181410 | H27: Punjab National Bank
A28: 27 | B28: AGS26069 | C28: Neetapalli Sreekanth Reddy | D28: 46146 | E28: =VLOOKUP(B28,'Tech Team'!B19:AB63,27,0) -> 40117.75 | F28: 55560103591175 | G28: FDRL0005556 | H28: Federal Bank
A29: 28 | B29: AGS26070 | C29: Melath Ashwin | D29: 46146 | E29: =VLOOKUP(B29,'Tech Team'!B20:AB64,27,0) -> 30358.25 | F29: 99980130963841 | G29: FDRL0001555 | H29: Federal Bank
A30: 29 | B30: AGS26077 | C30: Batta Jyotsna | D30: 46174 | E30: =VLOOKUP(B30,'Hiring Team'!A2:AA14,27,0) -> 17800.422 | F30: 23240100021018 | G30: FDRL0002324 | H30: Federal Bank
A31: 30 | B31: AGS26078 | C31: Kankanala Sravani | D31: 46174 | E31: =VLOOKUP(B31,'Hiring Team'!A3:AA15,27,0) -> 14800.352 | F31: 23070100029541 | G31: FDRL0002307 | H31: Federal Bank
A32: 31 | B32: AGS26079 | C32: Vadicharla Sandeep Kumar | D32: 46174 | E32: =VLOOKUP(B32,'Hiring Team'!A4:AA16,27,0) -> 17800.422 | F32: 17560100050974 | G32: FDRL0001756 | H32: Federal Bank
A33: 32 | B33: AGS26080 | C33: Thota Varsha | D33: 46174 | E33: =VLOOKUP(B33,'Hiring Team'!A5:AA17,27,0) -> 14800.352 | F33: 24570100002876 | G33: FDRL0002457 | H33: Federal Bank
A34: 33 | B34: AGS26081 | C34: Shaik Faiza | D34: 46174 | E34: =VLOOKUP(B34,'Hiring Team'!A6:AA18,27,0) -> 12849.654 | F34: 924010050412952 | G34: UTIB0002158 | H34: Union Bank
A35: 34 | B35: AGS26082 | C35: Shaik Shaheen | D35: 46174 | E35: =VLOOKUP(B35,'Hiring Team'!A7:AA19,27,0) -> 11850.281 | F35: 25140100010136 | G35: FDRL0002514 | H35: Federal Bank
A36: 35 | B36: AGS26083 | C36: Guduru Subhanbee | D36: 46174 | E36: =VLOOKUP(B36,'Hiring Team'!A8:AA20,27,0) -> 12849.654 | F36: 23710100006391 | G36: FDRL0002371 | H36: Federal Bank
A37: 36 | B37: AGS26084 | C37: Yapakayala Sampath | D37: 46174 | E37: =VLOOKUP(B37,'Hiring Team'!A9:AA21,27,0) -> 27800.006 | F37: 24570100005333 | G37: FDRL0002457 | H37: Federal Bank
A38: 37 | B38: AGS26085 | C38: Shaik Akram | D38: 46174 | E38: =VLOOKUP(B38,'Hiring Team'!A10:AA22,27,0) -> 24799.935 | F38: 99980128937682 | G38: FDRL0001555 | H38: Federal Bank
A39: 38 | B39: AGS26086 | C39: Mesu Lion Kumar | D39: 46174 | E39: =VLOOKUP(B39,'Hiring Team'!A11:AA23,27,0) -> 22800.214 | F39: 99980128338519 | G39: FDRL0001583 | H39: Federal Bank
A40: 39 | B40: AGS26087 | C40: Bashaboina Srilatha | D40: 46174 | E40: =VLOOKUP(B40,'Hiring Team'!A12:AA24,27,0) -> 44800.079 | F40: 24780100008456 | G40: FDRL0002478 | H40: Federal Bank
...

Sheet Rental Payment
A1: Account holder Name | B1: Actual Cost | C1: GST | D1: Total Cost | E1: Bank Account Number | F1: IFSC code | G1: Bank Name | H1: Transfer
A2: ODCET CONSULTANCY SERVICES PVT LTD GST Number : 36AADCO5390F1ZD | B2: 160000 | C2: 0 | D2: =B2+C2 -> 160000 | E2: 50200062999445 | F2: HDFC0000364 | G2: HDFC | H2: Cash
A3: ODCET CONSULTANCY SERVICES PVT LTD GST Number : 36AADCO5390F1ZD | B3: 20000 | C3: 0 | D3: =B3+C3 -> 20000 | E3: 50200062999445 | F3: HDFC0000364 | G3: HDFC | H3: Cash
D5: =SUM(D2:D4) -> 180000

Sheet Salaries_30042026
A1: Employee ID | B1: Employee Name | C1: DOJ | D1: Net Salary Payable | E1: Bank Account Number | F1: IFSC code | G1: Bank Name | H1: Remarks
A2: AGS26004 | B2: Ande Sharath Chandra | C2: 46054 | D2: =VLOOKUP(A2,Consultant!A2:H4,8,0) -> 79800 | E2: 50100677371816 | F2: HDFC0001042 | G2: HDFC Bank
A3: AGS26005 | B3: Tanakala Janardhan | C3: 46054 | D3: =VLOOKUP(A3,Consultant!A3:H4,8,0) -> 69800 | E3: 99980130961985 | F3: FDRL0001555 | G3: Federal Bank
A4: AGS26006 | B4: Abhijeet Vijaysingh Pardeshi | C4: 46062 | D4: =VLOOKUP(A4,Employees!2:2,29,0) -> #N/A | E4: 41280100007853 | F4: BARB0WALUJX | G4: BANK OF BARODA
A5: AGS26010 | B5: Vemula Varshith | C5: 46083 | D5: =VLOOKUP(A5,'Tech Team'!B2:AB15,28,0) -> #REF! | E5: 99980130961993 | F5: FDRL0001555 | G5: Federal Bank
A6: AGS26011 | B6: Siddula Hemasai | C6: 46083 | D6: =VLOOKUP(A6,'Tech Team'!B3:AB13,28,0) -> #REF! | E6: 3327101004003 | F6: CNRB0003327 | G6: Canara Bank
A7: AGS26013 | B7: Kalepu Vijay | C7: 46083 | D7: =VLOOKUP(A7,'Tech Team'!B5:AB18,28,0) -> #N/A | E7: 159502740717 | F7: INDB0000329 | G7: INDUSIND BANK
A8: AGS26014 | B8: Vulli Pavan | C8: 46083 | D8: =VLOOKUP(A8,'Tech Team'!B5:AB15,28,0) -> #N/A | E8: 77770116800885 | F8: FDRL0007777 | G8: Federal Bank
A9: AGS26015 | B9: Karne Narsimha Reddy | C9: 46083 | D9: =VLOOKUP(A9,'Tech Team'!B5:AB17,28,0) -> #N/A | E9: 99980130961886 | F9: FDRL0001555 | G9: Federal Bank
A10: AGS26016 | B10: Manisha Ashroba Virkar | C10: 46083 | D10: =VLOOKUP(A10,'Tech Team'!B5:AB16,28,0) -> #N/A | E10: 62297418711 | F10: SBIN0003801 | G10: State Bank of India
A11: AGS26017 | B11: Vavilla Saikumar | C11: 46083 | D11: =VLOOKUP(A11,'Tech Team'!B5:AB16,28,0) -> #N/A | E11: 99980130963940 | F11: FDRL0001555 | G11: Federal Bank
A12: AGS26018 | B12: Settybathini Sathish | C12: 46083 | D12: =VLOOKUP(A12,'Tech Team'!B2:AB13,28,0) -> #N/A | E12: 50100595290241 | F12: HDFC0000075 | G12: HDFC Bank
A13: AGS26019 | B13: Nelapatla Srinivas | C13: 46083 | D13: =VLOOKUP(A13,'Tech Team'!B4:AB15,28,0) -> #REF! | E13: 99980130961951 | F13: FDRL0001555 | G13: Federal Bank
A14: AGS26020 | B14: Gurindapalli Krishna Chaitanya | C14: 46066 | D14: =VLOOKUP(A14,Consultant!A4:H5,8,0) -> #N/A | E14: 020201545829 | F14: ICIC0000202 | G14: ICICI Bank
A15: AGS26021 | B15: Kontham Sushma | C15: 46083 | D15: =VLOOKUP(A15,'Tech Team'!B5:AB19,28,0) -> #N/A | E15: 99980130961894 | F15: FDRL0001555 | G15: Federal Bank
