Workbook

Sheet Employees
A1: Employee ID | B1: Employee Name | C1: DOJ | D1: CTC | E1: Calendar Days | F1: Paid Days | G1: LOP day's | I1: Basic | J1: HRA | K1: Special Allowance | L1: Other Allowance | M1: Gross Income | N1: Employee PF (12%) | O1: Employee ESI (0.75%) | P1: Professional Tax | Q1: Arrears | R1: Reimbursements | S1: Bonus/Incentive | T1: Gross Earnings | U1: TDS | V1: LOP Deduction | W1: Other Deductions | X1: Employer PF (12%) | Y1: Employer ESI (3.25%) | Z1: Gratuity (4.81%) | AA1: Total Deductions | AB1: Correction | AC1: Net Salary Payable
A2: AGS26006 | B2: Abhijeet Vijaysingh Pardeshi | C2: 46062 | D2: 70833 | E2: 30 | F2: 30 | G2: 0 | I2: =(+D2*50%)/E2*F2 -> 35416.5 | J2: =(I2*50%) -> 17708.25 | K2: =(1600/E2)*F2 -> 1600 | L2: =(M2-I2-J2-K2) -> 12604.716 | M2: =((D2-X2)/E2*F2)-Z2 -> 67329.466 | N2: =IF($I2*0.12>1800,1800,$I2*0.12) -> 1800 | O2: =IF(M2<=21000,M2*0.75%,0) -> 0 | P2: 200 | Q2: 0 | R2: 1999 | S2: 0 | T2: =M2+Q2+R2+S2 -> 69328.466 | U2: 0 | V2: 0 | W2: 0 | X2: =IF($I2*0.12>1800,1800,$I2*0.12) -> 1800 | Y2: =IF(M2<=21000,M2*3.25%,0) -> 0 | Z2: =I2*4.81% -> 1703.5336 | AA2: =N2+O2+P2+V2+W2+U2+X2+Y2+Z2 -> 5503.5336 | AB2: 1 | AC2: =M2-AA2+AB2+N2+Z2+R2 -> 67329.466
A3: AGS26038 | B3: Ainala Saiesha | C3: 46086 | D3: 100000 | E3: 30 | F3: 29 | G3: 1 | I3: =(+D3*49.99999%)/E3*F3 -> 48333.324 | J3: =(I3*50%) -> 24166.662 | K3: =(1600/E3)*F3 -> 1546.6667 | L3: =(M3-I3-J3-K3) -> 18475.015 | M3: =(D3-X3)/E3*F3-Z3 -> 92521.667 | N3: =IF($I3*0.12>1800,1800,$I3*0.12) -> 1800 | O3: =IF(M3<=21000,M3*0.75%,0) -> 0 | P3: 200 | Q3: 0 | R3: 0 | S3: 0 | T3: =M3+Q3+R3+S3 -> 92521.667 | U3: 0 | V3: 0 | W3: 0 | X3: =IF($I3*0.12>1800,1800,$I3*0.12) -> 1800 | Y3: =IF(M3<=21000,M3*3.25%,0) -> 0 | Z3: 2405 | AA3: =N3+O3+P3+V3+W3+U3+X3+Y3+Z3 -> 6205 | AC3: =M3-AA3+AB3+N3+Z3 -> 90521.667
C7: Total | D7: =SUM(D2:D6) -> 170833 | I7: =SUM(I2:I6) -> 83749.824 | J7: =SUM(J2:J6) -> 41874.912 | K7: =SUM(K2:K6) -> 3146.6667 | L7: =SUM(L2:L6) -> 31079.731 | M7: =SUM(M2:M6) -> 159851.13 | N7: =SUM(N2:N6) -> 3600 | O7: =SUM(O2:O6) -> 0 | P7: =SUM(P2:P6) -> 400 | ... AA7: =SUM(AA2:AA6) -> 11708.534 | AC7: =SUM(AC2:AC6) -> 157851.13

Sheet Consultant
A1: Employee ID | B1: Employee Name | C1: DOJ | D1: CTC | E1: Actuals | F1: TDS | G1: PT | H1: Payable | I1: LOP
A2: AGS26004 | B2: Ande Sharath Chandra | C2: 46055 | D2: 80000 | E2: =D2/30*30 -> 80000 | F2: 0 | G2: 200 | H2: =E2-G2 -> 79800
A3: AGS26005 | B3: Tanakala Janardhan | C3: 46055 | D3: 70000 | E3: =D3/30*30 -> 70000 | F3: 0 | G3: 200 | H3: =E3-G3 -> 69800
A4: AGS26020 | B4: Gurindapalli Krishna Chaitanya | C4: 46066 | D4: 60000 | E4: =D4/30*28 -> 56000 | F4: 0 | G4: 200 | H4: =E4-G4 -> 55800 | I4: 2 Days
A5: AGS26024 | B5: Priya Darshini Pola | C5: 46072 | D5: 80000 | E5: =D5/30*28 -> 74666.667 | F5: 0 | G5: 200 | H5: =E5-G5 -> 74466.667 | I5: 2- SL
A6: AGS26039 | B6: Esther Deva Priya | C6: 46092 | D6: 20000 | E6: =D6/30*27 -> 18000 | F6: 0 | G6: 200 | H6: =E6-G6 -> 17800 | I6: 3-SL
G7: Total | H7: =SUM(H2:H6) -> 297666.67

Sheet Tech Employees
A1: Employee ID | B1: Employee Name | C1: DOJ | D1: CTC | E1: Calendar Days | F1: Paid Days | G1: LOP day's | I1: Basic | J1: HRA | K1: Special Allowance | L1: Other Allowance | M1: Gross Income | N1: Employee PF (12%) | O1: Employee ESI (0.75%) | P1: Professional Tax | Q1: Arrears | R1: Reimbursements | S1: Bonus/Incentive | T1: Gross Earnings | U1: TDS | V1: LOP Deduction | W1: Other Deductions | X1: Employer PF (12%) | Y1: Employer ESI (3.25%) | Z1: Gratuity (4.81%) | AA1: Total Deductions | AB1: Net Salary Payable
A2: AGS26011 | B2: Siddula Hemasai | C2: 46083 | D2: 45000 | E2: 30 | F2: 30 | G2: 0 | I2: =(+D2*49.99999%)/E2*F2 -> 22499.995 | J2: =(I2*50%) -> 11249.998 | K2: =(1600/E2)*F2 -> 1600 | L2: =(M2-I2-J2-K2) -> 6767.757 | M2: =(D2-X2)/E2*F2-Z2 -> 42117.75 | N2: =IF($I2*0.12>1800,1800,$I2*0.12) -> 1800 | O2: =IF(M2<=21000,M2*0.75%,0) -> 0 | P2: 200 | Q2: 0 | R2: 0 | S2: 0 | T2: =M2+Q2+R2+S2 -> 42117.75 | U2: 0 | V2: 0 | W2: 0 | X2: =IF($I2*0.12>1800,1800,$I2*0.12) -> 1800 | Y2: =IF(M2<=21000,M2*3.25%,0) -> 0 | Z2: =I2*4.81% -> 1082.2498 | AA2: =N2+O2+P2+V2+W2+U2+X2+Y2+Z2 -> 4882.2498 | AB2: =M2-AA2+Z2+X2 -> 40117.75
A3: AGS26018 | B3: Settybathini Sathish | C3: 46083 | D3: 45000 | E3: 30 | F3: 30 | G3: 0 | I3: =(+D3*49.99999%)/E3*F3 -> 22499.995 | J3: =(I3*50%) -> 11249.998 | K3: =(1600/E3)*F3 -> 1600 | L3: =(M3-I3-J3-K3) -> 6767.757 | M3: =(D3-X3)/E3*F3-Z3 -> 42117.75 | N3: =IF($I3*0.12>1800,1800,$I3*0.12) -> 1800 | O3: =IF(M3<=21000,M3*0.75%,0) -> 0 | P3: 200 | Q3: 0 | R3: 0 | S3: 0 | T3: =M3+Q3+R3+S3 -> 42117.75 | U3: 0 | V3: 0 | W3: 0 | X3: =IF($I3*0.12>1800,1800,$I3*0.12) -> 1800 | Y3: =IF(M3<=21000,M3*3.25%,0) -> 0 | Z3: =I3*4.81% -> 1082.2498 | AA3: =N3+O3+P3+V3+W3+U3+X3+Y3+Z3 -> 4882.2498 | AB3: =M3-AA3+Z3+X3 -> 40117.75
A4: AGS26010 | B4: Vemula Varshith | C4: 46083 | D4: 60000 | E4: 30 | F4: 29 | G4: 1 | I4: =(+D4*49.99999%)/E4*F4 -> 28999.994 | J4: =(I4*50%) -> 14499.997 | K4: =(1600/E4)*F4 -> 1546.6667 | L4: =(M4-I4-J4-K4) -> 9818.4423 | M4: =(D4-X4)/E4*F4-Z4 -> 54865.1 | N4: =IF($I4*0.12>1800,1800,$I4*0.12) -> 1800 | O4: =IF(M4<=21000,M4*0.75%,0) -> 0 | P4: 200 | Q4: 0 | R4: 0 | S4: 0 | T4: =M4+Q4+R4+S4 -> 54865.1 | U4: 0 | V4: 0 | W4: 0 | X4: =IF($I4*0.12>1800,1800,$I4*0.12) -> 1800 | Y4: =IF(M4<=21000,M4*3.25%,0) -> 0 | Z4: =I4*4.81% -> 1394.8997 | AA4: =N4+O4+P4+V4+W4+U4+X4+Y4+Z4 -> 5194.8997 | AB4: =M4-AA4+Z4+X4 -> 52865.1
A5: AGS26019 | B5: Nelapatla Srinivas | C5: 46083 | D5: 23000 | E5: 30 | F5: 30 | G5: 0 | I5: =(+D5*49.99999%)/E5*F5 -> 11499.998 | J5: =(I5*50%) -> 5749.9988 | K5: =(1600/E5)*F5 -> 1600 | L5: =(M5-I5-J5-K5) -> 2216.8538 | M5: =(D5-X5)/E5*F5-Z5 -> 21066.85 | N5: =IF($I5*0.12>1800,1800,$I5*0.12) -> 1379.9997 | O5: =IF(M5<=21000,M5*0.75%,0) -> 0 | P5: 200 | Q5: 0 | R5: 0 | S5: 0 | T5: =M5+Q5+R5+S5 -> 21066.85 | U5: 0 | V5: 0 | W5: 0 | X5: =IF($I5*0.12>1800,1800,$I5*0.12) -> 1379.9997 | Y5: =IF(M5<=21000,M5*3.25%,0) -> 0 | Z5: =I5*4.81% -> 553.14989 | AA5: =N5+O5+P5+V5+W5+U5+X5+Y5+Z5 -> 3513.1493 | AB5: =M5-AA5+Z5+X5 -> 19486.851
A6: AGS26014 | B6: Vulli Pavan | C6: 46083 | D6: 50000 | E6: 30 | F6: 30 | G6: 0 | I6: =(+D6*49.99999%)/E6*F6 -> 24999.995 | J6: =(I6*50%) -> 12499.997 | K6: =(1600/E6)*F6 -> 1600 | L6: =(M6-I6-J6-K6) -> 7897.5077 | M6: =(D6-X6)/E6*F6-Z6 -> 46997.5 | N6: =IF($I6*0.12>1800,1800,$I6*0.12) -> 1800 | O6: =IF(M6<=21000,M6*0.75%,0) -> 0 | P6: 200 | Q6: 0 | R6: 0 | S6: 0 | T6: =M6+Q6+R6+S6 -> 46997.5 | U6: 0 | V6: 0 | W6: 0 | X6: =IF($I6*0.12>1800,1800,$I6*0.12) -> 1800 | Y6: =IF(M6<=21000,M6*3.25%,0) -> 0 | Z6: =I6*4.81% -> 1202.4998 | AA6: =N6+O6+P6+V6+W6+U6+X6+Y6+Z6 -> 5002.4998 | AB6: =M6-AA6+Z6+X6 -> 44997.5
A7: AGS26017 | B7: Vavilla Saikumar | C7: 46083 | D7: 45000 | E7: 30 | F7: 30 | G7: 0 | I7: =(+D7*49.99999%)/E7*F7 -> 22499.995 | J7: =(I7*50%) -> 11249.998 | K7: =(1600/E7)*F7 -> 1600 | L7: =(M7-I7-J7-K7) -> 6767.757 | M7: =(D7-X7)/E7*F7-Z7 -> 42117.75 | N7: =IF($I7*0.12>1800,1800,$I7*0.12) -> 1800 | O7: =IF(M7<=21000,M7*0.75%,0) -> 0 | P7: 200 | Q7: 0 | R7: 0 | S7: 0 | T7: =M7+Q7+R7+S7 -> 42117.75 | U7: 0 | V7: 0 | W7: 0 | X7: =IF($I7*0.12>1800,1800,$I7*0.12) -> 1800 | Y7: =IF(M7<=21000,M7*3.25%,0) -> 0 | Z7: =I7*4.81% -> 1082.2498 | AA7: =N7+O7+P7+V7+W7+U7+X7+Y7+Z7 -> 4882.2498 | AB7: =M7-AA7+Z7+X7 -> 40117.75
A8: AGS26016 | B8: Manisha Ashroba Virkar | C8: 46083 | D8: 45000 | E8: 30 | F8: 30 | G8: 0 | I8: =(+D8*49.99999%)/E8*F8 -> 22499.995 | J8: =(I8*50%) -> 11249.998 | K8: =(1600/E8)*F8 -> 1600 | L8: =(M8-I8-J8-K8) -> 6767.757 | M8: =(D8-X8)/E8*F8-Z8 -> 42117.75 | N8: =IF($I8*0.12>1800,1800,$I8*0.12) -> 1800 | O8: =IF(M8<=21000,M8*0.75%,0) -> 0 | P8: 200 | Q8: 0 | R8: 0 | S8: 0 | T8: =M8+Q8+R8+S8 -> 42117.75 | U8: 0 | V8: 0 | W8: 0 | X8: =IF($I8*0.12>1800,1800,$I8*0.12) -> 1800 | Y8: =IF(M8<=21000,M8*3.25%,0) -> 0 | Z8: =I8*4.81% -> 1082.2498 | AA8: =N8+O8+P8+V8+W8+U8+X8+Y8+Z8 -> 4882.2498 | AB8: =M8-AA8+Z8+X8 -> 40117.75
A9: AGS26015 | B9: Karne Narsimha Reddy | C9: 46083 | D9: 45000 | E9: 30 | F9: 30 | G9: 0 | I9: =(+D9*49.99999%)/E9*F9 -> 22499.995 | J9: =(I9*50%) -> 11249.998 | K9: =(1600/E9)*F9 -> 1600 | L9: =(M9-I9-J9-K9) -> 6767.757 | M9: =(D9-X9)/E9*F9-Z9 -> 42117.75 | N9: =IF($I9*0.12>1800,1800,$I9*0.12) -> 1800 | O9: =IF(M9<=21000,M9*0.75%,0) -> 0 | P9: 200 | Q9: 0 | R9: 0 | S9: 0 | T9: =M9+Q9+R9+S9 -> 42117.75 | U9: 0 | V9: 0 | W9: 0 | X9: =IF($I9*0.12>1800,1800,$I9*0.12) -> 1800 | Y9: =IF(M9<=21000,M9*3.25%,0) -> 0 | Z9: =I9*4.81% -> 1082.2498 | AA9: =N9+O9+P9+V9+W9+U9+X9+Y9+Z9 -> 4882.2498 | AB9: =M9-AA9+Z9+X9 -> 40117.75
A10: AGS26013 | B10: Kalepu Vijay | C10: 46083 | D10: 45000 | E10: 30 | F10: 30 | G10: 0 | I10: =(+D10*49.99999%)/E10*F10 -> 22499.995 | J10: =(I10*50%) -> 11249.998 | K10: =(1600/E10)*F10 -> 1600 | L10: =(M10-I10-J10-K10) -> 6767.757 | M10: =(D10-X10)/E10*F10-Z10 -> 42117.75 | N10: =IF($I10*0.12>1800,1800,$I10*0.12) -> 1800 | O10: =IF(M10<=21000,M10*0.75%,0) -> 0 | P10: 200 | Q10: 0 | R10: 0 | S10: 0 | T10: =M10+Q10+R10+S10 -> 42117.75 | U10: 0 | V10: 0 | W10: 0 | X10: =IF($I10*0.12>1800,1800,$I10*0.12) -> 1800 | Y10: =IF(M10<=21000,M10*3.25%,0) -> 0 | Z10: =I10*4.81% -> 1082.2498 | AA10: =N10+O10+P10+V10+W10+U10+X10+Y10+Z10 -> 4882.2498 | AB10: =M10-AA10+Z10+X10 -> 40117.75
A11: AGS26021 | B11: Kontham Sushma | C11: 46083 | D11: 50000 | E11: 30 | F11: 30 | G11: 0 | I11: =(+D11*49.99999%)/E11*F11 -> 24999.995 | J11: =(I11*50%) -> 12499.997 | K11: =(1600/E11)*F11 -> 1600 | L11: =(M11-I11-J11-K11) -> 7897.5077 | M11: =(D11-X11)/E11*F11-Z11 -> 46997.5 | N11: =IF($I11*0.12>1800,1800,$I11*0.12) -> 1800 | O11: =IF(M11<=21000,M11*0.75%,0) -> 0 | P11: 200 | Q11: 0 | R11: 0 | S11: 0 | T11: =M11+Q11+R11+S11 -> 46997.5 | U11: 0 | V11: 0 | W11: 0 | X11: =IF($I11*0.12>1800,1800,$I11*0.12) -> 1800 | Y11: =IF(M11<=21000,M11*3.25%,0) -> 0 | Z11: =I11*4.81% -> 1202.4998 | AA11: =N11+O11+P11+V11+W11+U11+X11+Y11+Z11 -> 5002.4998 | AB11: =M11-AA11+Z11+X11 -> 44997.5
A12: AGS26022 | B12: Akkma Sai Teja | C12: 46083 | D12: 50000 | E12: 30 | F12: 30 | G12: 0 | I12: =(+D12*49.99999%)/E12*F12 -> 24999.995 | J12: =(I12*50%) -> 12499.997 | K12: =(1600/E12)*F12 -> 1600 | L12: =(M12-I12-J12-K12) -> 7897.5077 | M12: =(D12-X12)/E12*F12-Z12 -> 46997.5 | N12: =IF($I12*0.12>1800,1800,$I12*0.12) -> 1800 | O12: =IF(M12<=21000,M12*0.75%,0) -> 0 | P12: 200 | Q12: 0 | R12: 0 | S12: 0 | T12: =M12+Q12+R12+S12 -> 46997.5 | U12: 0 | V12: 0 | W12: 0 | X12: =IF($I12*0.12>1800,1800,$I12*0.12) -> 1800 | Y12: =IF(M12<=21000,M12*3.25%,0) -> 0 | Z12: =I12*4.81% -> 1202.4998 | AA12: =N12+O12+P12+V12+W12+U12+X12+Y12+Z12 -> 5002.4998 | AB12: =M12-AA12+Z12+X12 -> 44997.5
A13: AGS26023 | B13: Bobbarala Varshini | C13: 46083 | D13: 60000 | E13: 30 | F13: 28 | G13: 2 | I13: =(+D13*49.99999%)/E13*F13 -> 27999.994 | J13: =(I13*50%) -> 13999.997 | K13: =(1600/E13)*F13 -> 1493.3333 | L13: =(M13-I13-J13-K13) -> 9479.8753 | M13: =(D13-X13)/E13*F13-Z13 -> 52973.2 | N13: =IF($I13*0.12>1800,1800,$I13*0.12) -> 1800 | O13: =IF(M13<=21000,M13*0.75%,0) -> 0 | P13: 200 | Q13: 0 | R13: 0 | S13: 0 | T13: =M13+Q13+R13+S13 -> 52973.2 | U13: 0 | V13: 0 | W13: 0 | X13: =IF($I13*0.12>1800,1800,$I13*0.12) -> 1800 | Y13: =IF(M13<=21000,M13*3.25%,0) -> 0 | Z13: =I13*4.81% -> 1346.7997 | AA13: =N13+O13+P13+V13+W13+U13+X13+Y13+Z13 -> 5146.7997 | AB13: =M13-AA13+Z13+X13 -> 50973.2
A14: AGS26026 | B14: Surampudi Roop Sai | C14: 46083 | D14: 60000 | E14: 30 | F14: 30 | G14: 0 | I14: =(+D14*49.99999%)/E14*F14 -> 29999.994 | J14: =(I14*50%) -> 14999.997 | K14: =(1600/E14)*F14 -> 1600 | L14: =(M14-I14-J14-K14) -> 10157.009 | M14: =(D14-X14)/E14*F14-Z14 -> 56757 | N14: =IF($I14*0.12>1800,1800,$I14*0.12) -> 1800 | O14: =IF(M14<=21000,M14*0.75%,0) -> 0 | P14: 200 | Q14: 0 | R14: 0 | S14: 0 | T14: =M14+Q14+R14+S14 -> 56757 | U14: 0 | V14: 0 | W14: 0 | X14: =IF($I14*0.12>1800,1800,$I14*0.12) -> 1800 | Y14: =IF(M14<=21000,M14*3.25%,0) -> 0 | Z14: =I14*4.81% -> 1442.9997 | AA14: =N14+O14+P14+V14+W14+U14+X14+Y14+Z14 -> 5242.9997 | AB14: =M14-AA14+Z14+X14 -> 54757
A15: AGS26028 | B15: Mohammed Abdul Moid | C15: 46083 | D15: 15000 | E15: 30 | F15: 30 | G15: 0 | I15: =(+D15*49.99999%)/E15*F15 -> 7499.9985 | J15: =(I15*50%) -> 3749.9992 | K15: =(1600/E15)*F15 -> 1600 | L15: =(M15-I15-J15-K15) -> 889.2525 | M15: =(D15-X15)/E15*F15-Z15 -> 13739.25 | N15: =IF($I15*0.12>1800,1800,$I15*0.12) -> 899.99982 | O15: 0 | P15: 200 | Q15: 0 | R15: 0 | S15: 0 | T15: =M15+Q15+R15+S15 -> 13739.25 | U15: 0 | V15: 0 | W15: 0 | X15: =IF($I15*0.12>1800,1800,$I15*0.12) -> 899.99982 | Y15: 0 | Z15: =I15*4.81% -> 360.74993 | AA15: =N15+O15+P15+V15+W15+U15+X15+Y15+Z15 -> 2360.7496 | AB15: =M15-AA15+Z15+X15 -> 12639.25
A16: AGS26029 | B16: Mula Sai Preetham Goud | C16: 46083 | D16: 35000 | E16: 30 | F16: 30 | G16: 0 | I16: =(+D16*49.99999%)/E16*F16 -> 17499.996 | J16: =(I16*50%) -> 8749.9982 | K16: =(1600/E16)*F16 -> 1600 | L16: =(M16-I16-J16-K16) -> 4508.2554 | M16: =(D16-X16)/E16*F16-Z16 -> 32358.25 | N16: =IF($I16*0.12>1800,1800,$I16*0.12) -> 1800 | O16: =IF(M16<=21000,M16*0.75%,0) -> 0 | P16: 200 | Q16: 0 | R16: 0 | S16: 0 | T16: =M16+Q16+R16+S16 -> 32358.25 | U16: 0 | V16: 0 | W16: 0 | X16: =IF($I16*0.12>1800,1800,$I16*0.12) -> 1800 | Y16: =IF(M16<=21000,M16*3.25%,0) -> 0 | Z16: =I16*4.81% -> 841.74983 | AA16: =N16+O16+P16+V16+W16+U16+X16+Y16+Z16 -> 4641.7498 | AB16: =M16-AA16+Z16+X16 -> 30358.25
A17: AGS26030 | B17: Sruthin Kumar Basa | C17: 46083 | D17: 35000 | E17: 30 | F17: 30 | G17: 0 | I17: =(+D17*49.99999%)/E17*F17 -> 17499.996 | J17: =(I17*50%) -> 8749.9982 | K17: =(1600/E17)*F17 -> 1600 | L17: =(M17-I17-J17-K17) -> 4508.2554 | M17: =(D17-X17)/E17*F17-Z17 -> 32358.25 | N17: =IF($I17*0.12>1800,1800,$I17*0.12) -> 1800 | O17: =IF(M17<=21000,M17*0.75%,0) -> 0 | P17: 200 | Q17: 0 | R17: 0 | S17: 0 | T17: =M17+Q17+R17+S17 -> 32358.25 | U17: 0 | V17: 0 | W17: 0 | X17: =IF($I17*0.12>1800,1800,$I17*0.12) -> 1800 | Y17: =IF(M17<=21000,M17*3.25%,0) -> 0 | Z17: =I17*4.81% -> 841.74983 | AA17: =N17+O17+P17+V17+W17+U17+X17+Y17+Z17 -> 4641.7498 | AB17: =M17-AA17+Z17+X17 -> 30358.25
A18: AGS26032 | B18: Vempadapu Uday Sai Tarun | C18: 46083 | D18: 23000 | E18: 30 | F18: 30 | G18: 0 | I18: =(+D18*49.99999%)/E18*F18 -> 11499.998 | J18: =(I18*50%) -> 5749.9988 | K18: =(1600/E18)*F18 -> 1600 | L18: =(M18-I18-J18-K18) -> 2216.8538 | M18: =(D18-X18)/E18*F18-Z18 -> 21066.85 | N18: =IF($I18*0.12>1800,1800,$I18*0.12) -> 1379.9997 | O18: =IF(M18<=21000,M18*0.75%,0) -> 0 | P18: 200 | Q18: 0 | R18: 0 | S18: 0 | T18: =M18+Q18+R18+S18 -> 21066.85 | U18: 0 | V18: 0 | W18: 0 | X18: =IF($I18*0.12>1800,1800,$I18*0.12) -> 1379.9997 | Y18: =IF(M18<=21000,M18*3.25%,0) -> 0 | Z18: =I18*4.81% -> 553.14989 | AA18: =N18+O18+P18+V18+W18+U18+X18+Y18+Z18 -> 3513.1493 | AB18: =M18-AA18+Z18+X18 -> 19486.851
A19: AGS26033 | B19: Kethavath Sai Raj | C19: 46083 | D19: 35000 | E19: 30 | F19: 30 | G19: 0 | I19: =(+D19*49.99999%)/E19*F19 -> 17499.996 | J19: =(I19*50%) -> 8749.9982 | K19: =(1600/E19)*F19 -> 1600 | L19: =(M19-I19-J19-K19) -> 4508.2554 | M19: =(D19-X19)/E19*F19-Z19 -> 32358.25 | N19: =IF($I19*0.12>1800,1800,$I19*0.12) -> 1800 | O19: =IF(M19<=21000,M19*0.75%,0) -> 0 | P19: 200 | Q19: 0 | R19: 0 | S19: 0 | T19: =M19+Q19+R19+S19 -> 32358.25 | U19: 0 | V19: 0 | W19: 0 | X19: =IF($I19*0.12>1800,1800,$I19*0.12) -> 1800 | Y19: =IF(M19<=21000,M19*3.25%,0) -> 0 | Z19: =I19*4.81% -> 841.74983 | AA19: =N19+O19+P19+V19+W19+U19+X19+Y19+Z19 -> 4641.7498 | AB19: =M19-AA19+Z19+X19 -> 30358.25
A20: AGS26034 | B20: Sripada Shivakumar | C20: 46083 | D20: 60000 | E20: 30 | F20: 30 | G20: 0 | I20: =(+D20*49.99999%)/E20*F20 -> 29999.994 | J20: =(I20*50%) -> 14999.997 | K20: =(1600/E20)*F20 -> 1600 | L20: =(M20-I20-J20-K20) -> 10157.009 | M20: =(D20-X20)/E20*F20-Z20 -> 56757 | N20: =IF($I20*0.12>1800,1800,$I20*0.12) -> 1800 | O20: =IF(M20<=21000,M20*0.75%,0) -> 0 | P20: 200 | Q20: 0 | R20: 0 | S20: 0 | T20: =M20+Q20+R20+S20 -> 56757 | U20: 0 | V20: 0 | W20: 0 | X20: =IF($I20*0.12>1800,1800,$I20*0.12) -> 1800 | Y20: =IF(M20<=21000,M20*3.25%,0) -> 0 | Z20: =I20*4.81% -> 1442.9997 | AA20: =N20+O20+P20+V20+W20+U20+X20+Y20+Z20 -> 5242.9997 | AB20: =M20-AA20+Z20+X20 -> 54757
A21: AGS26035 | B21: Varakantham Surender Reddy | C21: 46083 | D21: 60000 | E21: 30 | F21: 29 | G21: 1 | I21: =(+D21*49.99999%)/E21*F21 -> 28999.994 | J21: =(I21*50%) -> 14499.997 | K21: =(1600/E21)*F21 -> 1546.6667 | L21: =(M21-I21-J21-K21) -> 9818.4423 | M21: =(D21-X21)/E21*F21-Z21 -> 54865.1 | N21: =IF($I21*0.12>1800,1800,$I21*0.12) -> 1800 | O21: =IF(M21<=21000,M21*0.75%,0) -> 0 | P21: 200 | Q21: 0 | R21: 0 | S21: 0 | T21: =M21+Q21+R21+S21 -> 54865.1 | U21: 0 | V21: 0 | W21: 0 | X21: =IF($I21*0.12>1800,1800,$I21*0.12) -> 1800 | Y21: =IF(M21<=21000,M21*3.25%,0) -> 0 | Z21: =I21*4.81% -> 1394.8997 | AA21: =N21+O21+P21+V21+W21+U21+X21+Y21+Z21 -> 5194.8997 | AB21: =M21-AA21+Z21+X21 -> 52865.1
A22: AGS26041 | B22: Sudhagani Sai Charan | C22: 46113 | D22: 35000 | E22: 30 | F22: 30 | G22: 0 | I22: =(+D22*49.99999%)/E22*F22 -> 17499.996 | J22: =(I22*50%) -> 8749.9982 | K22: =(1600/E22)*F22 -> 1600 | L22: =(M22-I22-J22-K22) -> 4508.2554 | M22: =(D22-X22)/E22*F22-Z22 -> 32358.25 | N22: =IF($I22*0.12>1800,1800,$I22*0.12) -> 1800 | O22: =IF(M22<=21000,M22*0.75%,0) -> 0 | P22: 200 | Q22: 0 | R22: 0 | S22: 0 | T22: =M22+Q22+R22+S22 -> 32358.25 | U22: 0 | V22: 0 | W22: 0 | X22: =IF($I22*0.12>1800,1800,$I22*0.12) -> 1800 | Y22: =IF(M22<=21000,M22*3.25%,0) -> 0 | Z22: =I22*4.81% -> 841.74983 | AA22: =N22+O22+P22+V22+W22+U22+X22+Y22+Z22 -> 4641.7498 | AB22: =M22-AA22+Z22+X22 -> 30358.25
A23: AGS26043 | B23: Chebrolu Yashaswini | C23: 46113 | D23: 30000 | E23: 30 | F23: 30 | G23: 0 | I23: =(+D23*49.99999%)/E23*F23 -> 14999.997 | J23: =(I23*50%) -> 7499.9985 | K23: =(1600/E23)*F23 -> 1600 | L23: =(M23-I23-J23-K23) -> 3378.505 | M23: =(D23-X23)/E23*F23-Z23 -> 27478.501 | N23: =IF($I23*0.12>1800,1800,$I23*0.12) -> 1799.9996 | O23: =IF(M23<=21000,M23*0.75%,0) -> 0 | P23: 200 | Q23: 0 | R23: 0 | S23: 0 | T23: =M23+Q23+R23+S23 -> 27478.501 | U23: 0 | V23: 0 | W23: 0 | X23: =IF($I23*0.12>1800,1800,$I23*0.12) -> 1799.9996 | Y23: =IF(M23<=21000,M23*3.25%,0) -> 0 | Z23: =I23*4.81% -> 721.49986 | AA23: =N23+O23+P23+V23+W23+U23+X23+Y23+Z23 -> 4521.4991 | AB23: =M23-AA23+Z23+X23 -> 25478.501
A24: AGS26045 | B24: Chebrolu Monika | C24: 46113 | D24: 50000 | E24: 30 | F24: 30 | G24: 0 | I24: =(+D24*49.99999%)/E24*F24 -> 24999.995 | J24: =(I24*50%) -> 12499.997 | K24: =(1600/E24)*F24 -> 1600 | L24: =(M24-I24-J24-K24) -> 7897.5077 | M24: =(D24-X24)/E24*F24-Z24 -> 46997.5 | N24: =IF($I24*0.12>1800,1800,$I24*0.12) -> 1800 | O24: =IF(M24<=21000,M24*0.75%,0) -> 0 | P24: 200 | Q24: 0 | R24: 0 | S24: 0 | T24: =M24+Q24+R24+S24 -> 46997.5 | U24: 0 | V24: 0 | W24: 1850 | X24: =IF($I24*0.12>1800,1800,$I24*0.12) -> 1800 | Y24: =IF(M24<=21000,M24*3.25%,0) -> 0 | Z24: =I24*4.81% -> 1202.4998 | AA24: =N24+O24+P24+V24+W24+U24+X24+Y24+Z24 -> 6852.4998 | AB24: =M24-AA24+Z24+X24 -> 43147.5
A25: AGS26047 | B25: Upadhyayula Naga Lakshmi Deepthi | C25: 46114 | D25: 23000 | E25: 29 | F25: 28 | G25: 1 | I25: =(+D25*49.99999%)/E25*F25 -> 11103.446 | J25: =(I25*50%) -> 5551.723 | K25: =(1600/E25)*F25 -> 1544.8276 | L25: =(M25-I25-J25-K25) -> 2186.3559 | M25: =(D25-X25)/E25*F25-Z25 -> 20386.353 | N25: =IF($I25*0.12>1800,1800,$I25*0.12) -> 1332.4135 | O25: 0 | P25: 200 | Q25: 0 | R25: 0 | S25: 0 | T25: =M25+Q25+R25+S25 -> 20386.353 | U25: 0 | V25: 0 | W25: 0 | X25: =IF($I25*0.12>1800,1800,$I25*0.12) -> 1332.4135 | Y25: 0 | Z25: =I25*4.81% -> 534.07576 | AA25: =N25+O25+P25+V25+W25+U25+X25+Y25+Z25 -> 3398.9028 | AB25: =M25-AA25+Z25+X25 -> 18853.939
A26: AGS26048 | B26: Rapolu Rekha | C26: 46113 | D26: 15000 | E26: 30 | F26: 30 | G26: 0 | I26: =(+D26*49.99999%)/E26*F26 -> 7499.9985 | J26: =(I26*50%) -> 3749.9992 | K26: =(1600/E26)*F26 -> 1600 | L26: =(M26-I26-J26-K26) -> 889.2525 | M26: =(D26-X26)/E26*F26-Z26 -> 13739.25 | N26: =IF($I26*0.12>1800,1800,$I26*0.12) -> 899.99982 | O26: 0 | P26: 150 | Q26: 0 | R26: 0 | S26: 0 | T26: =M26+Q26+R26+S26 -> 13739.25 | U26: 0 | V26: 0 | W26: 0 | X26: =IF($I26*0.12>1800,1800,$I26*0.12) -> 899.99982 | Y26: 0 | Z26: =I26*4.81% -> 360.74993 | AA26: =N26+O26+P26+V26+W26+U26+X26+Y26+Z26 -> 2310.7496 | AB26: =M26-AA26+Z26+X26 -> 12689.25
A27: AGS26049 | B27: Ragiru Nikhitha | C27: 46113 | D27: 15000 | E27: 30 | F27: 30 | G27: 0 | I27: =(+D27*49.99999%)/E27*F27 -> 7499.9985 | J27: =(I27*50%) -> 3749.9992 | K27: =(1600/E27)*F27 -> 1600 | L27: =(M27-I27-J27-K27) -> 889.2525 | M27: =(D27-X27)/E27*F27-Z27 -> 13739.25 | N27: =IF($I27*0.12>1800,1800,$I27*0.12) -> 899.99982 | O27: 0 | P27: 150 | Q27: 0 | R27: 0 | S27: 0 | T27: =M27+Q27+R27+S27 -> 13739.25 | U27: 0 | V27: 0 | W27: 0 | X27: =IF($I27*0.12>1800,1800,$I27*0.12) -> 899.99982 | Y27: 0 | Z27: =I27*4.81% -> 360.74993 | AA27: =N27+O27+P27+V27+W27+U27+X27+Y27+Z27 -> 2310.7496 | AB27: =M27-AA27+Z27+X27 -> 12689.25
A28: AGS26051 | B28: Mundlamuri Mrudula | C28: 46113 | D28: 15000 | E28: 30 | F28: 30 | G28: 0 | I28: =(+D28*49.99999%)/E28*F28 -> 7499.9985 | J28: =(I28*50%) -> 3749.9992 | K28: =(1600/E28)*F28 -> 1600 | L28: =(M28-I28-J28-K28) -> 889.2525 | M28: =(D28-X28)/E28*F28-Z28 -> 13739.25 | N28: =IF($I28*0.12>1800,1800,$I28*0.12) -> 899.99982 | O28: 0 | P28: 150 | Q28: 0 | R28: 0 | S28: 0 | T28: =M28+Q28+R28+S28 -> 13739.25 | U28: 0 | V28: 0 | W28: 0 | X28: =IF($I28*0.12>1800,1800,$I28*0.12) -> 899.99982 | Y28: 0 | Z28: =I28*4.81% -> 360.74993 | AA28: =N28+O28+P28+V28+W28+U28+X28+Y28+Z28 -> 2310.7496 | AB28: =M28-AA28+Z28+X28 -> 12689.25
A29: AGS26055 | B29: Cholleti Sai Kumar | C29: 46113 | D29: 15000 | E29: 30 | F29: 28 | G29: 2 | I29: =(+D29*49.99999%)/E29*F29 -> 6999.9986 | J29: =(I29*50%) -> 3499.9993 | K29: =(1600/E29)*F29 -> 1493.3333 | L29: =(M29-I29-J29-K29) -> 885.96899 | M29: =(D29-X29)/E29*F29-Z29 -> 12879.3 | N29: =IF($I29*0.12>1800,1800,$I29*0.12) -> 839.99983 | O29: 0 | P29: 150 | Q29: 0 | R29: 0 | S29: 0 | T29: =M29+Q29+R29+S29 -> 12879.3 | U29: 0 | V29: 0 | W29: 0 | X29: =IF($I29*0.12>1800,1800,$I29*0.12) -> 839.99983 | Y29: 0 | Z29: =I29*4.81% -> 336.69993 | AA29: =N29+O29+P29+V29+W29+U29+X29+Y29+Z29 -> 2166.6996 | AB29: =M29-AA29+Z29+X29 -> 11889.3
A30: AGS26053 | B30: Palavelli Praveen Reddy | C30: 46113 | D30: 15000 | E30: 30 | F30: 30 | G30: 0 | I30: =(+D30*49.99999%)/E30*F30 -> 7499.9985 | J30: =(I30*50%) -> 3749.9992 | K30: =(1600/E30)*F30 -> 1600 | L30: =(M30-I30-J30-K30) -> 889.2525 | M30: =(D30-X30)/E30*F30-Z30 -> 13739.25 | N30: =IF($I30*0.12>1800,1800,$I30*0.12) -> 899.99982 | O30: 0 | P30: 150 | Q30: 0 | R30: 0 | S30: 0 | T30: =M30+Q30+R30+S30 -> 13739.25 | U30: 0 | V30: 0 | W30: 0 | X30: =IF($I30*0.12>1800,1800,$I30*0.12) -> 899.99982 | Y30: 0 | Z30: =I30*4.81% -> 360.74993 | AA30: =N30+O30+P30+V30+W30+U30+X30+Y30+Z30 -> 2310.7496 | AB30: =M30-AA30+Z30+X30 -> 12689.25
A31: AGS26054 | B31: Yaramothu Himaja | C31: 46113 | D31: 15000 | E31: 30 | F31: 30 | G31: 0 | I31: =(+D31*49.99999%)/E31*F31 -> 7499.9985 | J31: =(I31*50%) -> 3749.9992 | K31: =(1600/E31)*F31 -> 1600 | L31: =(M31-I31-J31-K31) -> 889.2525 | M31: =(D31-X31)/E31*F31-Z31 -> 13739.25 | N31: =IF($I31*0.12>1800,1800,$I31*0.12) -> 899.99982 | O31: 0 | P31: 150 | Q31: 0 | R31: 0 | S31: 0 | T31: =M31+Q31+R31+S31 -> 13739.25 | U31: 0 | V31: 0 | W31: 0 | X31: =IF($I31*0.12>1800,1800,$I31*0.12) -> 899.99982 | Y31: 0 | Z31: =I31*4.81% -> 360.74993 | AA31: =N31+O31+P31+V31+W31+U31+X31+Y31+Z31 -> 2310.7496 | AB31: =M31-AA31+Z31+X31 -> 12689.25
A32: AGS26031 | B32: Y Raghavendar | C32: 46113 | D32: 45000 | E32: 30 | F32: 30 | G32: 0 | I32: =(+D32*49.99999%)/E32*F32 -> 22499.995 | J32: =(I32*50%) -> 11249.998 | K32: =(1600/E32)*F32 -> 1600 | L32: =(M32-I32-J32-K32) -> 6767.757 | M32: =(D32-X32)/E32*F32-Z32 -> 42117.75 | N32: =IF($I32*0.12>1800,1800,$I32*0.12) -> 1800 | O32: 0 | P32: 200 | Q32: 0 | R32: 0 | S32: 0 | T32: =M32+Q32+R32+S32 -> 42117.75 | U32: 0 | V32: 0 | W32: 0 | X32: =IF($I32*0.12>1800,1800,$I32*0.12) -> 1800 | Y32: 0 | Z32: =I32*4.81% -> 1082.2498 | AA32: =N32+O32+P32+V32+W32+U32+X32+Y32+Z32 -> 4882.2498 | AB32: =M32-AA32+Z32+X32 -> 40117.75
A33: AGS26056 | B33: Bommala Naveen Kumar | C33: 46113 | D33: 45000 | E33: 30 | F33: 30 | G33: 0 | I33: =(+D33*49.99999%)/E33*F33 -> 22499.995 | J33: =(I33*50%) -> 11249.998 | K33: =(1600/E33)*F33 -> 1600 | L33: =(M33-I33-J33-K33) -> 6767.757 | M33: =(D33-X33)/E33*F33-Z33 -> 42117.75 | N33: =IF($I33*0.12>1800,1800,$I33*0.12) -> 1800 | O33: 0 | P33: 200 | Q33: 0 | R33: 0 | S33: 0 | T33: =M33+Q33+R33+S33 -> 42117.75 | U33: 0 | V33: 0 | W33: 0 | X33: =IF($I33*0.12>1800,1800,$I33*0.12) -> 1800 | Y33: 0 | Z33: =I33*4.81% -> 1082.2498 | AA33: =N33+O33+P33+V33+W33+U33+X33+Y33+Z33 -> 4882.2498 | AB33: =M33-AA33+Z33+X33 -> 40117.75
A34: AGS26057 | B34: Odeti Srinivas | C34: 46113 | D34: 30000 | E34: 30 | F34: 30 | G34: 0 | I34: =(+D34*49.99999%)/E34*F34 -> 14999.997 | J34: =(I34*50%) -> 7499.9985 | K34: =(1600/E34)*F34 -> 1600 | L34: =(M34-I34-J34-K34) -> 3378.505 | M34: =(D34-X34)/E34*F34-Z34 -> 27478.501 | N34: =IF($I34*0.12>1800,1800,$I34*0.12) -> 1799.9996 | O34: 0 | P34: 200 | Q34: 0 | R34: 0 | S34: 0 | T34: =M34+Q34+R34+S34 -> 27478.501 | U34: 0 | V34: 0 | W34: 0 | X34: =IF($I34*0.12>1800,1800,$I34*0.12) -> 1799.9996 | Y34: 0 | Z34: =I34*4.81% -> 721.49986 | AA34: =N34+O34+P34+V34+W34+U34+X34+Y34+Z34 -> 4521.4991 | AB34: =M34-AA34+Z34+X34 -> 25478.501
A35: AGS26058 | B35: Matha Sai Prasad | C35: 46113 | D35: 15000 | E35: 30 | F35: 30 | G35: 0 | I35: =(+D35*49.99999%)/E35*F35 -> 7499.9985 | J35: =(I35*50%) -> 3749.9992 | K35: =(1600/E35)*F35 -> 1600 | L35: =(M35-I35-J35-K35) -> 889.2525 | M35: =(D35-X35)/E35*F35-Z35 -> 13739.25 | N35: =IF($I35*0.12>1800,1800,$I35*0.12) -> 899.99982 | O35: 0 | P35: 150 | Q35: 0 | R35: 0 | S35: 0 | T35: =M35+Q35+R35+S35 -> 13739.25 | U35: 0 | V35: 0 | W35: 1650 | X35: =IF($I35*0.12>1800,1800,$I35*0.12) -> 899.99982 | Y35: 0 | Z35: =I35*4.81% -> 360.74993 | AA35: =N35+O35+P35+V35+W35+U35+X35+Y35+Z35 -> 3960.7496 | AB35: =M35-AA35+Z35+X35 -> 11039.25
A36: AGS26059 | B36: Chamakuri Raghuram | C36: 46113 | D36: 15000 | E36: 30 | F36: 30 | G36: 0 | I36: =(+D36*49.99999%)/E36*F36 -> 7499.9985 | J36: =(I36*50%) -> 3749.9992 | K36: =(1600/E36)*F36 -> 1600 | L36: =(M36-I36-J36-K36) -> 889.2525 | M36: =(D36-X36)/E36*F36-Z36 -> 13739.25 | N36: =IF($I36*0.12>1800,1800,$I36*0.12) -> 899.99982 | O36: 0 | P36: 150 | Q36: 0 | R36: 0 | S36: 0 | T36: =M36+Q36+R36+S36 -> 13739.25 | U36: 0 | V36: 0 | W36: 0 | X36: =IF($I36*0.12>1800,1800,$I36*0.12) -> 899.99982 | Y36: 0 | Z36: =I36*4.81% -> 360.74993 | AA36: =N36+O36+P36+V36+W36+U36+X36+Y36+Z36 -> 2310.7496 | AB36: =M36-AA36+Z36+X36 -> 12689.25
A37: AGS26025 | B37: Tumula Dinesh Kumar | C37: 46113 | D37: 23000 | E37: 30 | F37: 30 | G37: 0 | I37: =(+D37*49.99999%)/E37*F37 -> 11499.998 | J37: =(I37*50%) -> 5749.9988 | K37: =(1600/E37)*F37 -> 1600 | L37: =(M37-I37-J37-K37) -> 2216.8538 | M37: =(D37-X37)/E37*F37-Z37 -> 21066.85 | N37: =IF($I37*0.12>1800,1800,$I37*0.12) -> 1379.9997 | O37: =IF(M37<=21000,M37*0.75%,0) -> 0 | P37: 200 | Q37: 0 | R37: 0 | S37: 0 | T37: =M37+Q37+R37+S37 -> 21066.85 | U37: 0 | V37: 0 | W37: 1450 | X37: =IF($I37*0.12>1800,1800,$I37*0.12) -> 1379.9997 | Y37: =IF(M37<=21000,M37*3.25%,0) -> 0 | Z37: =I37*4.81% -> 553.14989 | AA37: =N37+O37+P37+V37+W37+U37+X37+Y37+Z37 -> 4963.1493 | AB37: =M37-AA37+Z37+X37 -> 18036.851
A38: AGS26060 | B38: Thallada Venkatasagar | C38: 46114 | D38: 24000 | E38: 30 | F38: 30 | G38: 0 | I38: =(+D38*49.99999%)/E38*F38 -> 11999.998 | J38: =(I38*50%) -> 5999.9988 | K38: =(1600/E38)*F38 -> 1600 | L38: =(M38-I38-J38-K38) -> 2382.804 | M38: =(D38-X38)/E38*F38-Z38 -> 21982.8 | N38: =IF($I38*0.12>1800,1800,$I38*0.12) -> 1439.9997 | O38: =IF(M38<=21000,M38*0.75%,0) -> 0 | P38: 200 | Q38: 0 | R38: 0 | S38: 0 | T38: =M38+Q38+R38+S38 -> 21982.8 | U38: 0 | V38: 0 | W38: 0 | X38: =IF($I38*0.12>1800,1800,$I38*0.12) -> 1439.9997 | Y38: =IF(M38<=21000,M38*3.25%,0) -> 0 | Z38: =I38*4.81% -> 577.19988 | AA38: =N38+O38+P38+V38+W38+U38+X38+Y38+Z38 -> 3657.1993 | AB38: =M38-AA38+Z38+X38 -> 20342.801
A39: AGS26044 | B39: Naveen Pulikonda | C39: 46113 | D39: 35000 | E39: 30 | F39: 30 | G39: 0 | I39: =(+D39*49.99999%)/E39*F39 -> 17499.996 | J39: =(I39*50%) -> 8749.9982 | K39: =(1600/E39)*F39 -> 1600 | L39: =(M39-I39-J39-K39) -> 4508.2554 | M39: =(D39-X39)/E39*F39-Z39 -> 32358.25 | N39: =IF($I39*0.12>1800,1800,$I39*0.12) -> 1800 | O39: =IF(M39<=21000,M39*0.75%,0) -> 0 | P39: 200 | Q39: 0 | R39: 0 | S39: 0 | T39: =M39+Q39+R39+S39 -> 32358.25 | U39: 0 | V39: 0 | W39: 0 | X39: =IF($I39*0.12>1800,1800,$I39*0.12) -> 1800 | Y39: =IF(M39<=21000,M39*3.25%,0) -> 0 | Z39: =I39*4.81% -> 841.74983 | AA39: =N39+O39+P39+V39+W39+U39+X39+Y39+Z39 -> 4641.7498 | AB39: =M39-AA39+Z39+X39 -> 30358.25
A40: AGS26073 | B40: KONDAPALLY AKHIL | C40: 46113 | D40: 100000 | E40: 30 | F40: 30 | G40: 0 | I40: =(+D40*49.99999%)/E40*F40 -> 49999.99 | J40: =(I40*50%) -> 24999.995 | K40: =(1600/E40)*F40 -> 1600 | L40: =(M40-I40-J40-K40) -> 19195.015 | M40: =(D40-X40)/E40*F40-Z40 -> 95795 | N40: =IF($I40*0.12>1800,1800,$I40*0.12) -> 1800 | O40: =IF(M40<=21000,M40*0.75%,0) -> 0 | P40: 200 | Q40: 0 | R40: 0 | S40: 0 | T40: =M40+Q40+R40+S40 -> 95795 | U40: 0 | V40: 0 | W40: 0 | X40: =IF($I40*0.12>1800,1800,$I40*0.12) -> 1800 | Y40: =IF(M40<=21000,M40*3.25%,0) -> 0 | Z40: =I40*4.81% -> 2404.9995 | AA40: =N40+O40+P40+V40+W40+U40+X40+Y40+Z40 -> 6204.9995 | AB40: =M40-AA40+Z40+X40 -> 93795
...

Sheet Trainers
A1: S.No | B1: Name | C1: No of Hours | D1: Cost per Hour | E1: Total Cost | F1: Bank Account Number | G1: IFSC code | H1: Account holder Name | I1: Bank Name
A2: 1 | B2: Sridhar | E2: 230000 | F2: 32862142889 | G2: SBIN0011121 | H2: ERGAMREDDY SARADHA | I2: SBI
A3: 2 | B3: Sreekanth (Arjun) | C3: 22 | D3: 1200 | E3: =C3*D3 -> 26400 | F3: 004001579702 | G3: ICIC0001806 | H3: Sreekanth Koraboina | I3: ICICI Bank
A4: 3 | B4: Ravi | C4: 22 | D4: 1200 | E4: =C4*D4 -> 26400 | F4: 653101004326 | G4: ICIC0000053 | H4: G Ravi Teja | I4: ICICI Bank
A5: 4 | B5: Venkatesh Salla | C5: 30 | D5: 1000 | E5: =C5*D5 -> 30000 | F5: 922020060410761 | G5: UTIB0003985 | H5: KAKARLA PRASAD BABU | I5: Axis Bank
A6: 5 | B6: Madhuri | C6: 30 | D6: 1000 | E6: =C6*D6 -> 30000 | F6: 814649188 | G6: IDIB000C026 | H6: K GOPINADH | I6: INDIAN BANK
A7: 6 | B7: Chetna | C7: 13.5 | D7: 1000 | E7: =C7*D7 -> 13500 | F7: 50100115451901 | G7: HDFC0000485 | H7: HDFC0000485 | I7: HDFC
A8: 7 | B8: Akshay | C8: 19 | D8: 800 | E8: =C8*D8 -> 15200 | F8: 45080524946 | G8: SBIN0020030 | H8: Shweta Akshay Painjane | I8: SBI
E11: =SUM(E2:E10) -> 371500

Sheet Rental Payment
A1: Account holder Name | B1: Total Cost | C1: GST | D1: Bank Account Number | E1: IFSC code | F1: Bank Name | G1: Account Type
A2: ODCET CONSULTANCY SERVICES PVT LTD GST Number : 36AADCO5390F1ZD | B2: 160000 | C2: 0 | D2: 50200062999445 | E2: HDFC0000364 | F2: HDFC | G2: CURRENT
A3: ZOHO Corporation Private Limited | B3: 22583.06 | C3: 3444.87 | D3: 50200026430541 | E3: HDFC0001225 | F3: HDFC | G3: CURRENT
H9: =371500+160000+22583.06 -> 554083.06

Sheet Salaries_30042026
A1: Employee ID | B1: Employee Name | C1: DOJ | D1: Net Salary Payable | E1: Bank Account Number | F1: IFSC code | G1: Bank Name | H1: Remarks
A2: AGS26022 | B2: Akkma Sai Teja | C2: 46083 | D2: =VLOOKUP(A2,'Tech Employees'!A12:AB49,28,0) -> 44997.5 | E2: 50100565431077 | F2: HDFC0005175 | G2: HDFC Bank | H2: Hold
A3: AGS26004 | B3: Ande Sharath Chandra | C3: 46054 | D3: =VLOOKUP(A3,Consultant!A2:H6,8,0) -> 79800 | E3: 50100677371816 | F3: HDFC0001042 | G3: HDFC Bank
A4: AGS26005 | B4: Tanakala Janardhan | C4: 46054 | D4: =VLOOKUP(A4,Consultant!A3:H7,8,0) -> 69800 | E4: 99980130961985 | F4: FDRL0001555 | G4: Federal Bank
A5: AGS26006 | B5: Abhijeet Vijaysingh Pardeshi | C5: 46062 | D5: =VLOOKUP(A5,Employees!2:3,29,0) -> 67329.466 | E5: 41280100007853 | F5: BARB0WALUJX | G5: BANK OF BARODA
A6: AGS26010 | B6: Vemula Varshith | C6: 46083 | D6: =VLOOKUP(A6,'Tech Employees'!A4:AB41,28,0) -> 52865.1 | E6: 99980130961993 | F6: FDRL0001555 | G6: Federal Bank
A7: AGS26011 | B7: Siddula Hemasai | C7: 46083 | D7: =VLOOKUP(A7,'Tech Employees'!A2:AB39,28,0) -> 40117.75 | E7: 3327101004003 | F7: CNRB0003327 | G7: Canara Bank
A8: AGS26013 | B8: Kalepu Vijay | C8: 46083 | D8: =VLOOKUP(A8,'Tech Employees'!A10:AB47,28,0) -> 40117.75 | E8: 159502740717 | F8: INDB0000329 | G8: INDUSIND BANK
A9: AGS26014 | B9: Vulli Pavan | C9: 46083 | D9: =VLOOKUP(A9,'Tech Employees'!A6:AB43,28,0) -> 44997.5 | E9: 77770116800885 | F9: FDRL0007777 | G9: Federal Bank
A10: AGS26015 | B10: Karne Narsimha Reddy | C10: 46083 | D10: =VLOOKUP(A10,'Tech Employees'!A9:AB46,28,0) -> 40117.75 | E10: 99980130961886 | F10: FDRL0001555 | G10: Federal Bank
A11: AGS26016 | B11: Manisha Ashroba Virkar | C11: 46083 | D11: =VLOOKUP(A11,'Tech Employees'!A8:AB45,28,0) -> 40117.75 | E11: 62297418711 | F11: SBIN0003801 | G11: State Bank of India
A12: AGS26017 | B12: Vavilla Saikumar | C12: 46083 | D12: =VLOOKUP(A12,'Tech Employees'!A7:AB44,28,0) -> 40117.75 | E12: 99980130963940 | F12: FDRL0001555 | G12: Federal Bank
A13: AGS26018 | B13: Settybathini Sathish | C13: 46083 | D13: =VLOOKUP(A13,'Tech Employees'!A3:AB40,28,0) -> 40117.75 | E13: 50100595290241 | F13: HDFC0000075 | G13: HDFC Bank
A14: AGS26019 | B14: Nelapatla Srinivas | C14: 46083 | D14: =VLOOKUP(A14,'Tech Employees'!A5:AB42,28,0) -> 19486.851 | E14: 99980130961951 | F14: FDRL0001555 | G14: Federal Bank
A15: AGS26020 | B15: Gurindapalli Krishna Chaitanya | C15: 46066 | D15: =VLOOKUP(A15,Consultant!A4:H8,8,0) -> 55800 | E15: 020201545829 | F15: ICIC0000202 | G15: ICICI Bank
A16: AGS26021 | B16: Kontham Sushma | C16: 46083 | D16: =VLOOKUP(A16,'Tech Employees'!A11:AB48,28,0) -> 44997.5 | E16: 99980130961894 | F16: FDRL0001555 | G16: Federal Bank
A17: AGS26023 | B17: Bobbarala Varshini | C17: 46083 | D17: =VLOOKUP(A17,'Tech Employees'!A13:AB50,28,0) -> 50973.2 | E17: 99980130961878 | F17: FDRL0001555 | G17: Federal Bank
A18: AGS26024 | B18: Priya Darshini Pola | C18: 46072 | D18: =VLOOKUP(A18,Consultant!A5:H9,8,0) -> 74466.667 | E18: 99980130963916 | F18: FDRL0001555 | G18: Federal Bank
A19: AGS26025 | B19: Tumula Dinesh Kumar | C19: 46113 | D19: =VLOOKUP(A19,'Tech Employees'!A37:AB74,28,0) -> 18036.851 | E19: 44610100006654 | F19: BARB0SIDDIP | G19: Bank of Baroda
A20: AGS26026 | B20: Surampudi Roop Sai | C20: 46083 | D20: =VLOOKUP(A20,'Tech Employees'!A14:AB51,28,0) -> 54757 | E20: 615728726 | F20: IDIB000P121 | G20: Indian Bank
A21: AGS26028 | B21: Mohammed Abdul Moid | C21: 46083 | D21: =VLOOKUP(A21,'Tech Employees'!A15:AB52,28,0) -> 12639.25 | E21: 99980130963882 | F21: FDRL0001555 | G21: Federal Bank
A22: AGS26029 | B22: Mula Sai Preetham Goud | C22: 46083 | D22: =VLOOKUP(A22,'Tech Employees'!A16:AB53,28,0) -> 30358.25 | E22: 99980130961902 | F22: FDRL0001555 | G22: Federal Bank
A23: AGS26030 | B23: Sruthin Kumar Basa | C23: 46083 | D23: =VLOOKUP(A23,'Tech Employees'!A17:AB54,28,0) -> 30358.25 | E23: 99980130961761 | F23: FDRL0001555 | G23: Federal Bank
A24: AGS26031 | B24: Y Raghavendar | C24: 46113 | D24: =VLOOKUP(A24,'Tech Employees'!A32:AB69,28,0) -> 40117.75 | E24: 99980130961787 | F24: FDRL0001555 | G24: Federal Bank
A25: AGS26032 | B25: Vempadapu Uday Sai Tarun | C25: 46083 | D25: =VLOOKUP(A25,'Tech Employees'!A18:AB55,28,0) -> 19486.851 | E25: 37182972098 | F25: SBIN0008054 | G25: State Bank of India
A26: AGS26033 | B26: Kethavath Sai Raj | C26: 46083 | D26: =VLOOKUP(A26,'Tech Employees'!A19:AB56,28,0) -> 30358.25 | E26: 39971511897 | F26: SBIN0021227 | G26: State Bank of India
A27: AGS26034 | B27: Sripada Shivakumar | C27: 46083 | D27: =VLOOKUP(A27,'Tech Employees'!A20:AB57,28,0) -> 54757 | E27: 41536691505 | F27: SBIN0008807 | G27: State Bank of India
A28: AGS26035 | B28: Varakantham Surender Reddy | C28: 46083 | D28: =VLOOKUP(A28,'Tech Employees'!A21:AB58,28,0) -> 52865.1 | E28: 50100141200194 | F28: HDFC0004480 | G28: HDFC Bank
A29: AGS26038 | B29: Ainala Saiesha | C29: 46086 | D29: =VLOOKUP(A29,Employees!3:4,29,0) -> 90521.667 | E29: 99980130961795 | F29: FDRL0001555 | G29: Federal Bank
A30: AGS26039 | B30: Esther Deva Priya | C30: 46092 | D30: =VLOOKUP(A30,Consultant!A6:H10,8,0) -> 17800 | E30: 99980130950434 | F30: FDRL0001555 | G30: Federal Bank
A31: AGS26041 | B31: Sudhagani Sai Charan | C31: 46113 | D31: =VLOOKUP(A31,'Tech Employees'!A22:AB59,28,0) -> 30358.25 | E31: 15550100112314 | F31: FDRL0001555 | G31: Federal Bank
A32: AGS26043 | B32: Chebrolu Yashaswini | C32: 46113 | D32: =VLOOKUP(A32,'Tech Employees'!A23:AB60,28,0) -> 25478.501 | E32: 40590710609 | F32: SBIN0011984 | G32: State Bank of India
A33: AGS26044 | B33: Naveen Pulikonda | C33: 46113 | D33: =VLOOKUP(A33,'Tech Employees'!A39:AB76,28,0) -> 30358.25 | E33: 15550100112330 | F33: FDRL0001555 | G33: Federal Bank
A34: AGS26045 | B34: Chebrolu Monika | C34: 46113 | D34: =VLOOKUP(A34,'Tech Employees'!A24:AB61,28,0) -> 43147.5 | E34: 801663119 | F34: ICIC0000008 | G34: ICICI Bank
A35: AGS26047 | B35: Upadhyayula Naga Lakshmi Deepthi | C35: 46113 | D35: =VLOOKUP(A35,'Tech Employees'!A25:AB62,28,0) -> 18853.939 | E35: 55560103431927 | F35: FDRL0005556 | G35: Federal bank
A36: AGS26048 | B36: Rapolu Rekha | C36: 46113 | D36: =VLOOKUP(A36,'Tech Employees'!A26:AB63,28,0) -> 12689.25 | E36: 15550100112355 | F36: FDRL0001555 | G36: Federal Bank
A37: AGS26049 | B37: Ragiru Nikhitha | C37: 46113 | D37: =VLOOKUP(A37,'Tech Employees'!A27:AB64,28,0) -> 12689.25 | E37: 15550100112280 | F37: FDRL0001555 | G37: Federal Bank
A38: AGS26051 | B38: Mundlamuri Mrudula | C38: 46113 | D38: =VLOOKUP(A38,'Tech Employees'!A28:AB65,28,0) -> 12689.25 | E38: 386701504229 | F38: ICIC0003867 | G38: ICICI Bank
A39: AGS26053 | B39: Palavelli Praveen Reddy | C39: 46113 | D39: =VLOOKUP(A39,'Tech Employees'!A30:AB67,28,0) -> 12689.25 | E39: 15550100112306 | F39: FDRL0001555 | G39: Federal Bank
A40: AGS26054 | B40: Yaramothu Himaja | C40: 46113 | D40: =VLOOKUP(A40,'Tech Employees'!A31:AB68,28,0) -> 12689.25 | E40: 15550100112298 | F40: FDRL0001555 | G40: Federal Bank
...

Sheet Payments_30042026
A1: S.No | B1: Name | C1: No of Hours | D1: Cost per Hour | E1: Total Cost | F1: Bank Account Number | G1: IFSC code | H1: Account holder Name | I1: Bank Name
A2: 1 | B2: Sridhar | E2: 230000 | F2: 32862142889 | G2: SBIN0011121 | H2: ERGAMREDDY SARADHA | I2: SBI
A3: 2 | B3: Sreekanth (Arjun) | C3: 22 | D3: 1200 | E3: =C3*D3 -> 26400 | F3: 004001579702 | G3: ICIC0001806 | H3: Sreekanth Koraboina | I3: ICICI Bank
A4: 3 | B4: Ravi | C4: 22 | D4: 1200 | E4: =C4*D4 -> 26400 | F4: 653101004326 | G4: ICIC0000053 | H4: G Ravi Teja | I4: ICICI Bank
A5: 4 | B5: Venkatesh Salla | C5: 30 | D5: 1000 | E5: =C5*D5 -> 30000 | F5: 922020060410761 | G5: UTIB0003985 | H5: KAKARLA PRASAD BABU | I5: Axis Bank
A6: 5 | B6: Madhuri | C6: 30 | D6: 1000 | E6: =C6*D6 -> 30000 | F6: 814649188 | G6: IDIB000C026 | H6: K GOPINADH | I6: INDIAN BANK
A7: 6 | B7: Chetna | C7: 13.5 | D7: 1000 | E7: =C7*D7 -> 13500 | F7: 50100115451901 | G7: HDFC0000485 | H7: HDFC0000485 | I7: HDFC
A8: 7 | B8: Akshay | C8: 19 | D8: 800 | E8: =C8*D8 -> 15200 | F8: 45080524946 | G8: SBIN0020030 | H8: Shweta Akshay Painjane | I8: SBI
A9: 8 | B9: ODCET | E9: 160000 | F9: 50200062999445 | G9: HDFC0000364 | H9: ODCET CONSULTANCY SERVICES PVT LTD | I9: HDFC
A10: 9 | B10: ZOHO Corporation Private Limited | E10: 22583.06 | F10: 50200026430541 | G10: HDFC0001225 | H10: ZOHO Corporation Private Limited | I10: HDFC
B12: Total | E12: =SUM(E2:E10) -> 554083.06

Sheet Non Federal
A4: Employee Name | B4: Bank Account Number | C4: Net Salary Payable | D4: IFSC code | E4: Bank Name
A5: Ande Sharath Chandra | B5: 50100677371816 | C5: 79800 | D5: HDFC0001042 | E5: HDFC Bank
A6: Abhijeet Vijaysingh Pardeshi | B6: 41280100007853 | C6: 67329.466 | D6: BARB0WALUJX | E6: BANK OF BARODA
A7: Siddula Hemasai | B7: 3327101004003 | C7: 40117.75 | D7: CNRB0003327 | E7: Canara Bank
A8: Kalepu Vijay | B8: 159502740717 | C8: 40117.75 | D8: INDB0000329 | E8: INDUSIND BANK
A9: Manisha Ashroba Virkar | B9: 62297418711 | C9: 40117.75 | D9: SBIN0003801 | E9: State Bank of India
A10: Settybathini Sathish | B10: 50100595290241 | C10: 40117.75 | D10: HDFC0000075 | E10: HDFC Bank
A11: Gurindapalli Krishna Chaitanya | B11: 020201545829 | C11: 55800 | D11: ICIC0000202 | E11: ICICI Bank
A12: Tumula Dinesh Kumar | B12: 44610100006654 | C12: 18036.851 | D12: BARB0SIDDIP | E12: Bank of Baroda
A13: Surampudi Roop Sai | B13: 615728726 | C13: 54757 | D13: IDIB000P121 | E13: Indian Bank
A14: Vempadapu Uday Sai Tarun | B14: 37182972098 | C14: 19486.851 | D14: SBIN0008054 | E14: State Bank of India
A15: Kethavath Sai Raj | B15: 39971511897 | C15: 30358.25 | D15: SBIN0021227 | E15: State Bank of India
A16: Sripada Shivakumar | B16: 41536691505 | C16: 54757 | D16: SBIN0008807 | E16: State Bank of India
A17: Varakantham Surender Reddy | B17: 50100141200194 | C17: 52865.1 | D17: HDFC0004480 | E17: HDFC Bank
A18: Chebrolu Yashaswini | B18: 40590710609 | C18: 25478.501 | D18: SBIN0011984 | E18: State Bank of India
A19: Chebrolu Monika | B19: 801663119 | C19: 43147.5 | D19: ICIC0000008 | E19: ICICI Bank
A20: Mundlamuri Mrudula | B20: 386701504229 | C20: 12689.25 | D20: ICIC0003867 | E20: ICICI Bank
A21: Cholleti Sai Kumar | B21: 44652833670 | C21: 11889.3 | D21: SBIN0021487 | E21: State Bank of India
A22: Bommala Naveen Kumar | B22: 37097117593 | C22: 40117.75 | D22: SBIN0008833 | E22: State Bank of India
A23: Matha Sai Prasad | B23: 50100405907963 | C23: 11039.25 | D23: HDFC0009817 | E23: HDFC
... A26: ERGAMREDDY SARADHA | B26: 32862142889 | C26: 230000 | D26: SBIN0011121 | E26: SBI
A27: Sreekanth Koraboina | B27: 004001579702 | C27: 26400 | D27: ICIC0001806 | E27: ICICI Bank
A28: G Ravi Teja | B28: 653101004326 | C28: 26400 | D28: ICIC0000053 | E28: ICICI Bank
A29: KAKARLA PRASAD BABU | B29: 922020060410761 | C29: 30000 | D29: UTIB0003985 | E29: Axis Bank
A30: K GOPINADH | B30: 814649188 | C30: 30000 | D30: IDIB000C026 | E30: INDIAN BANK
A31: Chetna | B31: 50100115451901 | C31: 13500 | D31: HDFC0000485 | E31: HDFC
A32: Shweta Akshay Painjane | B32: 45080524946 | C32: 15200 | D32: SBIN0020030 | E32: SBI
B34: Total | C34: =SUM(C5:C32) -> 1232049.4

Sheet Federal
A4: Employee Name | B4: Bank Account Number | C4: Net Salary Payable | D4: IFSC code | E4: Bank Name
A5: Tanakala Janardhan | B5: 99980130961985 | C5: 69800 | D5: FDRL0001555 | E5: Federal Bank
A6: Vemula Varshith | B6: 99980130961993 | C6: 52865.1 | D6: FDRL0001555 | E6: Federal Bank
A7: Vulli Pavan | B7: 77770116800885 | C7: 44997.5 | D7: FDRL0007777 | E7: Federal Bank
A8: Karne Narsimha Reddy | B8: 99980130961886 | C8: 40117.75 | D8: FDRL0001555 | E8: Federal Bank
A9: Vavilla Saikumar | B9: 99980130963940 | C9: 40117.75 | D9: FDRL0001555 | E9: Federal Bank
A10: Nelapatla Srinivas | B10: 99980130961951 | C10: 19486.851 | D10: FDRL0001555 | E10: Federal Bank
A11: Kontham Sushma | B11: 99980130961894 | C11: 44997.5 | D11: FDRL0001555 | E11: Federal Bank
A12: Bobbarala Varshini | B12: 99980130961878 | C12: 50973.2 | D12: FDRL0001555 | E12: Federal Bank
A13: Priya Darshini Pola | B13: 99980130963916 | C13: 74466.667 | D13: FDRL0001555 | E13: Federal Bank
A14: Mohammed Abdul Moid | B14: 99980130963882 | C14: 12639.25 | D14: FDRL0001555 | E14: Federal Bank
A15: Mula Sai Preetham Goud | B15: 99980130961902 | C15: 30358.25 | D15: FDRL0001555 | E15: Federal Bank
A16: Sruthin Kumar Basa | B16: 99980130961761 | C16: 30358.25 | D16: FDRL0001555 | E16: Federal Bank
... A29: Thallada Venkatasagar | B29: 15550100112363 | C29: 20342.801 | D29: FDRL0001555 | E29: Federal Bank
B31: Total | C31: =SUM(C5:C30) -> 848455.48

Sheet Payment
A1: Employee ID | B1: Employee Name | C1: DOJ | D1: Net Salary Payable | E1: Bank Account Number | F1: IFSC code | G1: Bank Name | H1: Remarks
A2: AGS26022 | B2: Akkma Sai Teja | C2: 46083 | D2: =VLOOKUP(A2,'Tech Employees'!A12:AB49,28,0) -> 44997.5 | E2: 50100565431077 | F2: HDFC0005175 | G2: HDFC Bank | H2: Hold
A3: AGS26004 | B3: Ande Sharath Chandra | C3: 46054 | D3: =VLOOKUP(A3,Consultant!A2:H6,8,0) -> 79800 | E3: 50100677371816 | F3: HDFC0001042 | G3: HDFC Bank
A4: AGS26005 | B4: Tanakala Janardhan | C4: 46054 | D4: =VLOOKUP(A4,Consultant!A3:H7,8,0) -> 69800 | E4: 154710100018477 | F4: UBIN0815471 | G4: Union Bank
A5: AGS26006 | B5: Abhijeet Vijaysingh Pardeshi | C5: 46062 | D5: =VLOOKUP(A5,Employees!2:3,29,0) -> 67329.466 | E5: 41280100007853 | F5: BARB0WALUJX | G5: BANK OF BARODA
A6: AGS26010 | B6: Vemula Varshith | C6: 46083 | D6: =VLOOKUP(A6,'Tech Employees'!A4:AB41,28,0) -> 52865.1 | E6: 62428832885 | F6: SBIN0020959 | G6: State Bank of India
A7: AGS26011 | B7: Siddula Hemasai | C7: 46083 | D7: =VLOOKUP(A7,'Tech Employees'!A2:AB39,28,0) -> 40117.75 | E7: 3327101004003 | F7: CNRB0003327 | G7: Canara Bank
A8: AGS26013 | B8: Kalepu Vijay | C8: 46083 | D8: =VLOOKUP(A8,'Tech Employees'!A10:AB47,28,0) -> 40117.75 | E8: 159502740717 | F8: INDB0000329 | G8: INDUSIND BANK
A9: AGS26014 | B9: Vulli Pavan | C9: 46083 | D9: =VLOOKUP(A9,'Tech Employees'!A6:AB43,28,0) -> 44997.5 | E9: 77770116800885 | F9: FDRL0007777 | G9: Federal Bank
A10: AGS26015 | B10: Karne Narsimha Reddy | C10: 46083 | D10: =VLOOKUP(A10,'Tech Employees'!A9:AB46,28,0) -> 40117.75 | E10: 1.446178e+15 | F10: KVBL0001446 | G10: Karur Vysya Bank
A11: AGS26016 | B11: Manisha Ashroba Virkar | C11: 46083 | D11: =VLOOKUP(A11,'Tech Employees'!A8:AB45,28,0) -> 40117.75 | E11: 62297418711 | F11: SBIN0003801 | G11: State Bank of India
A12: AGS26017 | B12: Vavilla Saikumar | C12: 46083 | D12: =VLOOKUP(A12,'Tech Employees'!A7:AB44,28,0) -> 40117.75 | E12: 41085488775 | F12: SBIN0016293 | G12: State Bank of India
A13: AGS26018 | B13: Settybathini Sathish | C13: 46083 | D13: =VLOOKUP(A13,'Tech Employees'!A3:AB40,28,0) -> 40117.75 | E13: 50100595290241 | F13: HDFC0000075 | G13: HDFC Bank
A14: AGS26019 | B14: Nelapatla Srinivas | C14: 46083 | D14: =VLOOKUP(A14,'Tech Employees'!A5:AB42,28,0) -> 19486.851 | E14: 62442668281 | F14: SBIN0020176 | G14: State Bank of India
A15: AGS26020 | B15: Gurindapalli Krishna Chaitanya | C15: 46066 | D15: =VLOOKUP(A15,Consultant!A4:H8,8,0) -> 55800 | E15: 020201545829 | F15: ICIC0000202 | G15: ICICI Bank
A16: AGS26021 | B16: Kontham Sushma | C16: 46083 | D16: =VLOOKUP(A16,'Tech Employees'!A11:AB48,28,0) -> 44997.5 | E16: 39569845546 | F16: SBIN0008024 | G16: State Bank of India
A17: AGS26023 | B17: Bobbarala Varshini | C17: 46083 | D17: =VLOOKUP(A17,'Tech Employees'!A13:AB50,28,0) -> 50973.2 | E17: 41202390653 | F17: SBIN0000910 | G17: State Bank of India
A18: AGS26024 | B18: Priya Darshini Pola | C18: 46072 | D18: =VLOOKUP(A18,Consultant!A5:H9,8,0) -> 74466.667 | E18: 770301501355 | F18: ICIC0007703 | G18: ICICI Bank
A19: AGS26025 | B19: Tumula Dinesh Kumar | C19: 46113 | D19: =VLOOKUP(A19,'Tech Employees'!A37:AB74,28,0) -> 18036.851 | E19: 44610100006654 | F19: BARB0SIDDIP | G19: Bank of Baroda
A20: AGS26026 | B20: Surampudi Roop Sai | C20: 46083 | D20: =VLOOKUP(A20,'Tech Employees'!A14:AB51,28,0) -> 54757 | E20: 615728726 | F20: IDIB000P121 | G20: Indian Bank
A21: AGS26028 | B21: Mohammed Abdul Moid | C21: 46083 | D21: =VLOOKUP(A21,'Tech Employees'!A15:AB52,28,0) -> 12639.25 | E21: 9147600708 | F21: KKBK0007474 | G21: Kotak
A22: AGS26029 | B22: Mula Sai Preetham Goud | C22: 46083 | D22: =VLOOKUP(A22,'Tech Employees'!A16:AB53,28,0) -> 30358.25 | E22: 7445588605 | F22: KKBK0007462 | G22: Kotak
A23: AGS26030 | B23: Sruthin Kumar Basa | C23: 46083 | D23: =VLOOKUP(A23,'Tech Employees'!A17:AB54,28,0) -> 30358.25 | E23: 4495101004331 | F23: CNRB0004495 | G23: Canara Bank
A24: AGS26031 | B24: Y Raghavendar | C24: 46113 | D24: =VLOOKUP(A24,'Tech Employees'!A32:AB69,28,0) -> 40117.75 | E24: 20086309269 | F24: SBIN0013071 | G24: State Bank of India
A25: AGS26032 | B25: Vempadapu Uday Sai Tarun | C25: 46083 | D25: =VLOOKUP(A25,'Tech Employees'!A18:AB55,28,0) -> 19486.851 | E25: 37182972098 | F25: SBIN0008054 | G25: State Bank of India
A26: AGS26033 | B26: Kethavath Sai Raj | C26: 46083 | D26: =VLOOKUP(A26,'Tech Employees'!A19:AB56,28,0) -> 30358.25 | E26: 39971511897 | F26: SBIN0021227 | G26: State Bank of India
A27: AGS26034 | B27: Sripada Shivakumar | C27: 46083 | D27: =VLOOKUP(A27,'Tech Employees'!A20:AB57,28,0) -> 54757 | E27: 41536691505 | F27: SBIN0008807 | G27: State Bank of India
A28: AGS26035 | B28: Varakantham Surender Reddy | C28: 46083 | D28: =VLOOKUP(A28,'Tech Employees'!A21:AB58,28,0) -> 52865.1 | E28: 50100141200194 | F28: HDFC0004480 | G28: HDFC Bank
A29: AGS26038 | B29: Ainala Saiesha | C29: 46086 | D29: =VLOOKUP(A29,Employees!3:4,29,0) -> 90521.667 | E29: 50100868298601 | F29: HDFC0003665 | G29: HDFC Bank
A30: AGS26039 | B30: Esther Deva Priya | C30: 46092 | D30: =VLOOKUP(A30,Consultant!A6:H10,8,0) -> 17800 | E30: 50100743220366 | F30: HDFC0000545 | G30: HDFC Bank
A31: AGS26041 | B31: Sudhagani Sai Charan | C31: 46113 | D31: =VLOOKUP(A31,'Tech Employees'!A22:AB59,28,0) -> 30358.25 | E31: 920010070801185 | F31: UTIB0000008 | G31: Axis Bank
A32: AGS26043 | B32: Chebrolu Yashaswini | C32: 46113 | D32: =VLOOKUP(A32,'Tech Employees'!A23:AB60,28,0) -> 25478.501 | E32: 40590710609 | F32: SBIN0011984 | G32: SBI
A33: AGS26044 | B33: Naveen Pulikonda | C33: 46113 | D33: =VLOOKUP(A33,'Tech Employees'!A39:AB76,28,0) -> 30358.25 | E33: 111101513423 | F33: ICIC0001111 | G33: ICICI Bank
A34: AGS26045 | B34: Chebrolu Monika | C34: 46113 | D34: =VLOOKUP(A34,'Tech Employees'!A24:AB61,28,0) -> 43147.5 | E34: 801663119 | F34: ICIC0000008 | G34: ICICI Bank
A35: AGS26047 | B35: Upadhyayula Naga Lakshmi Deepthi | C35: 46113 | D35: =VLOOKUP(A35,'Tech Employees'!A25:AB62,28,0) -> 18853.939 | E35: 55560103431927 | F35: FDRL0005556 | G35: Federal bank
A36: AGS26048 | B36: Rapolu Rekha | C36: 46113 | D36: =VLOOKUP(A36,'Tech Employees'!A26:AB63,28,0) -> 12689.25 | E36: 55560103536675 | F36: FDRL0005556 | G36: Federal bank
A37: AGS26049 | B37: Ragiru Nikhitha | C37: 46113 | D37: =VLOOKUP(A37,'Tech Employees'!A27:AB64,28,0) -> 12689.25 | E37: 110240929810 | F37: CNRB0007792 | G37: Canara Bank
A38: AGS26051 | B38: Mundlamuri Mrudula | C38: 46113 | D38: =VLOOKUP(A38,'Tech Employees'!A28:AB65,28,0) -> 12689.25 | E38: 386701504229 | F38: ICIC0003867 | G38: ICICI Bank
A39: AGS26053 | B39: Palavelli Praveen Reddy | C39: 46113 | D39: =VLOOKUP(A39,'Tech Employees'!A30:AB67,28,0) -> 12689.25 | E39: 520101254028703 | F39: UBIN0826383 | G39: Union Bank of India
A40: AGS26054 | B40: Yaramothu Himaja | C40: 46113 | D40: =VLOOKUP(A40,'Tech Employees'!A31:AB68,28,0) -> 12689.25 | E40: 263812010000686 | F40: UBIN0826383 | G40: Union Bank Of India
...
