Workbook

Sheet Employees
A1: Employee ID | B1: Employee Name | C1: DOJ | D1: CTC | E1: Calendar Days | F1: Paid Days | G1: LOP day's | I1: Basic | J1: HRA | K1: Special Allowance | L1: Other Allowance | M1: Gross Income | N1: Employee PF (12%) | O1: Employee ESI (0.75%) | P1: Professional Tax | Q1: Arrears | R1: Reimbursements | S1: Bonus/Incentive | T1: Gross Earnings | U1: TDS | V1: LOP Deduction | W1: Other Deductions | X1: Employer PF (12%) | Y1: Employer ESI (3.25%) | Z1: Gratuity (4.81%) | AA1: Total Deductions | AB1: Correction | AC1: Net Salary Payable
A2: AGS26006 | B2: Abhijeet Vijaysingh Pardeshi | C2: 46062 | D2: 70833 | E2: 31 | F2: =E2-G2 -> 31 | G2: 0 | I2: =(+D2*50%)/E2*F2 -> 35416.5 | J2: =(I2*50%) -> 17708.25 | K2: =(1600/E2)*F2 -> 1600 | L2: =(M2-I2-J2-K2) -> 12604.716 | M2: =((D2-X2)/E2*F2)-Z2 -> 67329.466 | N2: =IF($I2*0.12>1800,1800,$I2*0.12) -> 1800 | O2: =IF(M2<=21000,M2*0.75%,0) -> 0 | P2: 200 | Q2: 0 | S2: 0 | T2: =M2+Q2+R2+S2 -> 67329.466 | U2: 0 | V2: =ROUND((M2/E2)*G2,0) -> 0 | W2: 0 | X2: =IF($I2*0.12>1800,1800,$I2*0.12) -> 1800 | Y2: =IF(M2<=21000,M2*3.25%,0) -> 0 | Z2: =I2*4.81% -> 1703.5336 | AA2: =N2+O2+P2+V2+W2+U2+X2+Y2+Z2 -> 5503.5336 | AC2: =M2-AA2+AB2+N2+Z2+R2 -> 65329.466
A3: AGS26038 | B3: Ainala Saiesha | C3: 46086 | D3: 100000 | E3: 31 | F3: =E3-G3 -> 30 | G3: 1 | I3: =(+D3*49.99999%)/E3*F3 -> 48387.087 | J3: =(I3*50%) -> 24193.544 | K3: =(1600/E3)*F3 -> 1548.3871 | L3: =(M3-I3-J3-K3) -> 18498.24 | M3: =(D3-X3)/E3*F3-Z3 -> 92627.258 | N3: =IF($I3*0.12>1800,1800,$I3*0.12) -> 1800 | O3: =IF(M3<=21000,M3*0.75%,0) -> 0 | P3: 200 | Q3: 0 | S3: 0 | T3: =M3+Q3+R3+S3 -> 92627.258 | U3: 0 | V3: 0 | W3: 0 | X3: =IF($I3*0.12>1800,1800,$I3*0.12) -> 1800 | Y3: =IF(M3<=21000,M3*3.25%,0) -> 0 | Z3: 2405 | AA3: =N3+O3+P3+V3+W3+U3+X3+Y3+Z3 -> 6205 | AC3: =M3-AA3+AB3+N3+Z3 -> 90627.258
C7: Total | D7: =SUM(D2:D6) -> 170833 | I7: =SUM(I2:I6) -> 83803.587 | J7: =SUM(J2:J6) -> 41901.794 | K7: =SUM(K2:K6) -> 3148.3871 | L7: =SUM(L2:L6) -> 31102.957 | M7: =SUM(M2:M6) -> 159956.72 | N7: =SUM(N2:N6) -> 3600 | O7: =SUM(O2:O6) -> 0 | P7: =SUM(P2:P6) -> 400 | ... AA7: =SUM(AA2:AA6) -> 11708.534 | AC7: =SUM(AC2:AC6) -> 155956.72

Sheet Consultant
A1: Employee ID | B1: Employee Name | C1: DOJ | D1: CTC | E1: Actuals | F1: TDS | G1: PT | H1: Payable | I1: LOP
A2: AGS26004 | B2: Ande Sharath Chandra | C2: 46055 | D2: 80000 | E2: =D2/31*31 -> 80000 | F2: 0 | G2: 200 | H2: =E2-G2 -> 79800
A3: AGS26005 | B3: Tanakala Janardhan | C3: 46055 | D3: 70000 | E3: =D3/31*31 -> 70000 | F3: 0 | G3: 200 | H3: =E3-G3 -> 69800
A4: AGS26020 | B4: Gurindapalli Krishna Chaitanya | C4: 46066 | D4: 60000 | E4: =D4/31*30 -> 58064.516 | F4: 0 | G4: 200 | H4: =E4-G4 -> 57864.516 | I4: 1 Day
A5: AGS26024 | B5: Priya Darshini Pola | C5: 46072 | D5: 80000 | E5: =D5/31*31 -> 80000 | F5: 0 | G5: 200 | H5: =E5-G5 -> 79800
A6: AGS26039 | B6: Esther Deva Priya | C6: 46092 | D6: 20000 | E6: =D6/31*30 -> 19354.839 | F6: 0 | G6: 200 | H6: =E6-G6 -> 19154.839 | I6: 1 Day
G7: Total | H7: =SUM(H2:H6) -> 306419.35

Sheet Tech Employees
A1: Employee ID | B1: Employee Name | C1: DOJ | D1: CTC | E1: Calendar Days | F1: Paid Days | G1: LOP day's | I1: Basic | J1: HRA | K1: Special Allowance | L1: Other Allowance | M1: Gross Income | N1: Employee PF (12%) | O1: Employee ESI (0.75%) | P1: Professional Tax | Q1: Arrears | R1: Reimbursements | S1: Bonus/ Incentive | T1: Gross Earnings | U1: TDS | V1: LOP Deduction | W1: Other Deductions | X1: Employer PF (12%) | Y1: Employer ESI (3.25%) | Z1: Gratuity (4.81%) | AA1: Total Deductions | AB1: Net Salary Payable
A2: AGS26011 | B2: Siddula Hemasai | C2: 46083 | D2: 45000 | E2: 31 | F2: =E2-G2 -> 31 | G2: 0 | I2: =(+D2*49.99999%)/E2*F2 -> 22499.995 | J2: =(I2*50%) -> 11249.998 | K2: =(1600/E2)*F2 -> 1600 | L2: =(M2-I2-J2-K2) -> 6767.757 | M2: =(D2-X2)/E2*F2-Z2 -> 42117.75 | N2: =IF($I2*0.12>1800,1800,$I2*0.12) -> 1800 | O2: =IF(M2<=21000,M2*0.75%,0) -> 0 | P2: 200 | Q2: 0 | R2: 0 | S2: 0 | T2: =M2+Q2+R2+S2 -> 42117.75 | U2: 0 | V2: =ROUND((M2/E2)*G2,0) -> 0 | W2: 0 | X2: =IF($I2*0.12>1800,1800,$I2*0.12) -> 1800 | Y2: =IF(M2<=21000,M2*3.25%,0) -> 0 | Z2: =I2*4.81% -> 1082.2498 | AA2: =N2+O2+P2+V2+W2+U2+X2+Y2+Z2 -> 4882.2498 | AB2: =M2-AA2+Z2+X2+Y2 -> 40117.75
A3: AGS26018 | B3: Settybathini Sathish | C3: 46083 | D3: 45000 | E3: 31 | F3: =E3-G3 -> 29 | G3: 2 | I3: =(+D3*49.99999%)/E3*F3 -> 21048.383 | J3: =(I3*50%) -> 10524.191 | K3: =(1600/E3)*F3 -> 1496.7742 | L3: =(M3-I3-J3-K3) -> 6331.1275 | M3: =(D3-X3)/E3*F3-Z3 -> 39400.476 | N3: =IF($I3*0.12>1800,1800,$I3*0.12) -> 1800 | O3: =IF(M3<=21000,M3*0.75%,0) -> 0 | P3: 200 | Q3: 0 | R3: 0 | S3: 0 | T3: =M3+Q3+R3+S3 -> 39400.476 | U3: 0 | V3: 0 | W3: 0 | X3: =IF($I3*0.12>1800,1800,$I3*0.12) -> 1800 | Y3: =IF(M3<=21000,M3*3.25%,0) -> 0 | Z3: =I3*4.81% -> 1012.4272 | AA3: =N3+O3+P3+V3+W3+U3+X3+Y3+Z3 -> 4812.4272 | AB3: =M3-AA3+Z3+X3 -> 37400.476
A4: AGS26010 | B4: Vemula Varshith | C4: 46083 | D4: 60000 | E4: 31 | F4: =E4-G4 -> 31 | G4: 0 | I4: =(+D4*49.99999%)/E4*F4 -> 29999.994 | J4: =(I4*50%) -> 14999.997 | K4: =(1600/E4)*F4 -> 1600 | L4: =(M4-I4-J4-K4) -> 10157.009 | M4: =(D4-X4)/E4*F4-Z4 -> 56757 | N4: =IF($I4*0.12>1800,1800,$I4*0.12) -> 1800 | O4: =IF(M4<=21000,M4*0.75%,0) -> 0 | P4: 200 | Q4: 0 | R4: 0 | S4: 0 | T4: =M4+Q4+R4+S4 -> 56757 | U4: 0 | V4: =ROUND((M4/E4)*G4,0) -> 0 | W4: 0 | X4: =IF($I4*0.12>1800,1800,$I4*0.12) -> 1800 | Y4: =IF(M4<=21000,M4*3.25%,0) -> 0 | Z4: =I4*4.81% -> 1442.9997 | AA4: =N4+O4+P4+V4+W4+U4+X4+Y4+Z4 -> 5242.9997 | AB4: =M4-AA4+Z4+X4 -> 54757
A5: AGS26019 | B5: Nelapatla Srinivas | C5: 46083 | D5: 23000 | E5: 31 | F5: =E5-G5 -> 31 | G5: 0 | I5: =(+D5*49.99999%)/E5*F5 -> 11499.998 | J5: =(I5*50%) -> 5749.9988 | K5: =(1600/E5)*F5 -> 1600 | L5: =(M5-I5-J5-K5) -> 2216.8538 | M5: =(D5-X5)/E5*F5-Z5 -> 21066.85 | N5: =IF($I5*0.12>1800,1800,$I5*0.12) -> 1379.9997 | O5: =IF(M5<=21000,M5*0.75%,0) -> 0 | P5: 200 | Q5: 0 | R5: 0 | S5: 0 | T5: =M5+Q5+R5+S5 -> 21066.85 | U5: 0 | V5: =ROUND((M5/E5)*G5,0) -> 0 | W5: 0 | X5: =IF($I5*0.12>1800,1800,$I5*0.12) -> 1379.9997 | Y5: =IF(M5<=21000,M5*3.25%,0) -> 0 | Z5: =I5*4.81% -> 553.14989 | AA5: =N5+O5+P5+V5+W5+U5+X5+Y5+Z5 -> 3513.1493 | AB5: =M5-AA5+Z5+X5 -> 19486.851
A6: AGS26014 | B6: Vulli Pavan | C6: 46083 | D6: 50000 | E6: 31 | F6: =E6-G6 -> 31 | G6: 0 | I6: =(+D6*49.99999%)/E6*F6 -> 24999.995 | J6: =(I6*50%) -> 12499.997 | K6: =(1600/E6)*F6 -> 1600 | L6: =(M6-I6-J6-K6) -> 7897.5077 | M6: =(D6-X6)/E6*F6-Z6 -> 46997.5 | N6: =IF($I6*0.12>1800,1800,$I6*0.12) -> 1800 | O6: =IF(M6<=21000,M6*0.75%,0) -> 0 | P6: 200 | Q6: 0 | R6: 0 | S6: 0 | T6: =M6+Q6+R6+S6 -> 46997.5 | U6: 0 | V6: =ROUND((M6/E6)*G6,0) -> 0 | W6: 0 | X6: =IF($I6*0.12>1800,1800,$I6*0.12) -> 1800 | Y6: =IF(M6<=21000,M6*3.25%,0) -> 0 | Z6: =I6*4.81% -> 1202.4998 | AA6: =N6+O6+P6+V6+W6+U6+X6+Y6+Z6 -> 5002.4998 | AB6: =M6-AA6+Z6+X6 -> 44997.5
A7: AGS26017 | B7: Vavilla Saikumar | C7: 46083 | D7: 45000 | E7: 31 | F7: =E7-G7 -> 31 | G7: 0 | I7: =(+D7*49.99999%)/E7*F7 -> 22499.995 | J7: =(I7*50%) -> 11249.998 | K7: =(1600/E7)*F7 -> 1600 | L7: =(M7-I7-J7-K7) -> 6767.757 | M7: =(D7-X7)/E7*F7-Z7 -> 42117.75 | N7: =IF($I7*0.12>1800,1800,$I7*0.12) -> 1800 | O7: =IF(M7<=21000,M7*0.75%,0) -> 0 | P7: 200 | Q7: 0 | R7: 0 | S7: 0 | T7: =M7+Q7+R7+S7 -> 42117.75 | U7: 0 | V7: =ROUND((M7/E7)*G7,0) -> 0 | W7: 0 | X7: =IF($I7*0.12>1800,1800,$I7*0.12) -> 1800 | Y7: =IF(M7<=21000,M7*3.25%,0) -> 0 | Z7: =I7*4.81% -> 1082.2498 | AA7: =N7+O7+P7+V7+W7+U7+X7+Y7+Z7 -> 4882.2498 | AB7: =M7-AA7+Z7+X7 -> 40117.75
A8: AGS26016 | B8: Manisha Ashroba Virkar | C8: 46083 | D8: 45000 | E8: 31 | F8: =E8-G8 -> 31 | G8: 0 | I8: =(+D8*49.99999%)/E8*F8 -> 22499.995 | J8: =(I8*50%) -> 11249.998 | K8: =(1600/E8)*F8 -> 1600 | L8: =(M8-I8-J8-K8) -> 6767.757 | M8: =(D8-X8)/E8*F8-Z8 -> 42117.75 | N8: =IF($I8*0.12>1800,1800,$I8*0.12) -> 1800 | O8: =IF(M8<=21000,M8*0.75%,0) -> 0 | P8: 200 | Q8: 0 | R8: 0 | S8: 0 | T8: =M8+Q8+R8+S8 -> 42117.75 | U8: 0 | V8: =ROUND((M8/E8)*G8,0) -> 0 | W8: 0 | X8: =IF($I8*0.12>1800,1800,$I8*0.12) -> 1800 | Y8: =IF(M8<=21000,M8*3.25%,0) -> 0 | Z8: =I8*4.81% -> 1082.2498 | AA8: =N8+O8+P8+V8+W8+U8+X8+Y8+Z8 -> 4882.2498 | AB8: =M8-AA8+Z8+X8 -> 40117.75
A9: AGS26015 | B9: Karne Narsimha Reddy | C9: 46083 | D9: 45000 | E9: 31 | F9: =E9-G9 -> 31 | G9: 0 | I9: =(+D9*49.99999%)/E9*F9 -> 22499.995 | J9: =(I9*50%) -> 11249.998 | K9: =(1600/E9)*F9 -> 1600 | L9: =(M9-I9-J9-K9) -> 6767.757 | M9: =(D9-X9)/E9*F9-Z9 -> 42117.75 | N9: =IF($I9*0.12>1800,1800,$I9*0.12) -> 1800 | O9: =IF(M9<=21000,M9*0.75%,0) -> 0 | P9: 200 | Q9: 0 | R9: 0 | S9: 0 | T9: =M9+Q9+R9+S9 -> 42117.75 | U9: 0 | V9: =ROUND((M9/E9)*G9,0) -> 0 | W9: 0 | X9: =IF($I9*0.12>1800,1800,$I9*0.12) -> 1800 | Y9: =IF(M9<=21000,M9*3.25%,0) -> 0 | Z9: =I9*4.81% -> 1082.2498 | AA9: =N9+O9+P9+V9+W9+U9+X9+Y9+Z9 -> 4882.2498 | AB9: =M9-AA9+Z9+X9 -> 40117.75
A10: AGS26013 | B10: Kalepu Vijay | C10: 46083 | D10: 45000 | E10: 31 | F10: =E10-G10 -> 31 | G10: 0 | I10: =(+D10*49.99999%)/E10*F10 -> 22499.995 | J10: =(I10*50%) -> 11249.998 | K10: =(1600/E10)*F10 -> 1600 | L10: =(M10-I10-J10-K10) -> 6767.757 | M10: =(D10-X10)/E10*F10-Z10 -> 42117.75 | N10: =IF($I10*0.12>1800,1800,$I10*0.12) -> 1800 | O10: =IF(M10<=21000,M10*0.75%,0) -> 0 | P10: 200 | Q10: 0 | R10: 0 | S10: 0 | T10: =M10+Q10+R10+S10 -> 42117.75 | U10: 0 | V10: =ROUND((M10/E10)*G10,0) -> 0 | W10: 0 | X10: =IF($I10*0.12>1800,1800,$I10*0.12) -> 1800 | Y10: =IF(M10<=21000,M10*3.25%,0) -> 0 | Z10: =I10*4.81% -> 1082.2498 | AA10: =N10+O10+P10+V10+W10+U10+X10+Y10+Z10 -> 4882.2498 | AB10: =M10-AA10+Z10+X10 -> 40117.75
A11: AGS26021 | B11: Kontham Sushma | C11: 46083 | D11: 50000 | E11: 31 | F11: =E11-G11 -> 31 | G11: 0 | I11: =(+D11*49.99999%)/E11*F11 -> 24999.995 | J11: =(I11*50%) -> 12499.997 | K11: =(1600/E11)*F11 -> 1600 | L11: =(M11-I11-J11-K11) -> 7897.5077 | M11: =(D11-X11)/E11*F11-Z11 -> 46997.5 | N11: =IF($I11*0.12>1800,1800,$I11*0.12) -> 1800 | O11: =IF(M11<=21000,M11*0.75%,0) -> 0 | P11: 200 | Q11: 0 | R11: 0 | S11: 0 | T11: =M11+Q11+R11+S11 -> 46997.5 | U11: 0 | V11: =ROUND((M11/E11)*G11,0) -> 0 | W11: 0 | X11: =IF($I11*0.12>1800,1800,$I11*0.12) -> 1800 | Y11: =IF(M11<=21000,M11*3.25%,0) -> 0 | Z11: =I11*4.81% -> 1202.4998 | AA11: =N11+O11+P11+V11+W11+U11+X11+Y11+Z11 -> 5002.4998 | AB11: =M11-AA11+Z11+X11 -> 44997.5
A12: AGS26023 | B12: Bobbarala Varshini | C12: 46083 | D12: 60000 | E12: 31 | F12: =E12-G12 -> 30 | G12: 1 | I12: =(+D12*49.99999%)/E12*F12 -> 29032.252 | J12: =(I12*50%) -> 14516.126 | K12: =(1600/E12)*F12 -> 1548.3871 | L12: =(M12-I12-J12-K12) -> 9829.3638 | M12: =(D12-X12)/E12*F12-Z12 -> 54926.129 | N12: =IF($I12*0.12>1800,1800,$I12*0.12) -> 1800 | O12: =IF(M12<=21000,M12*0.75%,0) -> 0 | P12: 200 | Q12: 0 | R12: 0 | S12: 0 | T12: =M12+Q12+R12+S12 -> 54926.129 | U12: 0 | V12: 0 | W12: 0 | X12: =IF($I12*0.12>1800,1800,$I12*0.12) -> 1800 | Y12: =IF(M12<=21000,M12*3.25%,0) -> 0 | Z12: =I12*4.81% -> 1396.4513 | AA12: =N12+O12+P12+V12+W12+U12+X12+Y12+Z12 -> 5196.4513 | AB12: =M12-AA12+Z12+X12 -> 52926.129
A13: AGS26026 | B13: Surampudi Roop Sai | C13: 46083 | D13: 60000 | E13: 31 | F13: =E13-G13 -> 31 | G13: 0 | I13: =(+D13*49.99999%)/E13*F13 -> 29999.994 | J13: =(I13*50%) -> 14999.997 | K13: =(1600/E13)*F13 -> 1600 | L13: =(M13-I13-J13-K13) -> 10157.009 | M13: =(D13-X13)/E13*F13-Z13 -> 56757 | N13: =IF($I13*0.12>1800,1800,$I13*0.12) -> 1800 | O13: =IF(M13<=21000,M13*0.75%,0) -> 0 | P13: 200 | Q13: 0 | R13: 0 | S13: 0 | T13: =M13+Q13+R13+S13 -> 56757 | U13: 0 | V13: =ROUND((M13/E13)*G13,0) -> 0 | W13: 0 | X13: =IF($I13*0.12>1800,1800,$I13*0.12) -> 1800 | Y13: =IF(M13<=21000,M13*3.25%,0) -> 0 | Z13: =I13*4.81% -> 1442.9997 | AA13: =N13+O13+P13+V13+W13+U13+X13+Y13+Z13 -> 5242.9997 | AB13: =M13-AA13+Z13+X13 -> 54757
A14: AGS26028 | B14: Mohammed Abdul Moid | C14: 46083 | D14: 15000 | E14: 31 | F14: =E14-G14 -> 31 | G14: 0 | I14: =(+D14*49.99999%)/E14*F14 -> 7499.9985 | J14: =(I14*50%) -> 3749.9992 | K14: =(1600/E14)*F14 -> 1600 | L14: =(M14-I14-J14-K14) -> 889.2525 | M14: =(D14-X14)/E14*F14-Z14 -> 13739.25 | N14: =IF($I14*0.12>1800,1800,$I14*0.12) -> 899.99982 | O14: 0 | P14: 200 | Q14: 0 | R14: 0 | S14: 0 | T14: =M14+Q14+R14+S14 -> 13739.25 | U14: 0 | V14: =ROUND((M14/E14)*G14,0) -> 0 | W14: 0 | X14: =IF($I14*0.12>1800,1800,$I14*0.12) -> 899.99982 | Y14: 0 | Z14: =I14*4.81% -> 360.74993 | AA14: =N14+O14+P14+V14+W14+U14+X14+Y14+Z14 -> 2360.7496 | AB14: =M14-AA14+Z14+X14 -> 12639.25
A15: AGS26029 | B15: Mula Sai Preetham Goud | C15: 46083 | D15: 35000 | E15: 31 | F15: =E15-G15 -> 31 | G15: 0 | I15: =(+D15*49.99999%)/E15*F15 -> 17499.996 | J15: =(I15*50%) -> 8749.9982 | K15: =(1600/E15)*F15 -> 1600 | L15: =(M15-I15-J15-K15) -> 4508.2554 | M15: =(D15-X15)/E15*F15-Z15 -> 32358.25 | N15: =IF($I15*0.12>1800,1800,$I15*0.12) -> 1800 | O15: =IF(M15<=21000,M15*0.75%,0) -> 0 | P15: 200 | Q15: 0 | R15: 0 | S15: 0 | T15: =M15+Q15+R15+S15 -> 32358.25 | U15: 0 | V15: =ROUND((M15/E15)*G15,0) -> 0 | W15: 0 | X15: =IF($I15*0.12>1800,1800,$I15*0.12) -> 1800 | Y15: =IF(M15<=21000,M15*3.25%,0) -> 0 | Z15: =I15*4.81% -> 841.74983 | AA15: =N15+O15+P15+V15+W15+U15+X15+Y15+Z15 -> 4641.7498 | AB15: =M15-AA15+Z15+X15 -> 30358.25
A16: AGS26030 | B16: Sruthin Kumar Basa | C16: 46083 | D16: 35000 | E16: 31 | F16: =E16-G16 -> 31 | G16: 0 | I16: =(+D16*49.99999%)/E16*F16 -> 17499.996 | J16: =(I16*50%) -> 8749.9982 | K16: =(1600/E16)*F16 -> 1600 | L16: =(M16-I16-J16-K16) -> 4508.2554 | M16: =(D16-X16)/E16*F16-Z16 -> 32358.25 | N16: =IF($I16*0.12>1800,1800,$I16*0.12) -> 1800 | O16: =IF(M16<=21000,M16*0.75%,0) -> 0 | P16: 200 | Q16: 0 | R16: 0 | S16: 0 | T16: =M16+Q16+R16+S16 -> 32358.25 | U16: 0 | V16: =ROUND((M16/E16)*G16,0) -> 0 | W16: 0 | X16: =IF($I16*0.12>1800,1800,$I16*0.12) -> 1800 | Y16: =IF(M16<=21000,M16*3.25%,0) -> 0 | Z16: =I16*4.81% -> 841.74983 | AA16: =N16+O16+P16+V16+W16+U16+X16+Y16+Z16 -> 4641.7498 | AB16: =M16-AA16+Z16+X16 -> 30358.25
A17: AGS26032 | B17: Vempadapu Uday Sai Tarun | C17: 46083 | D17: 23000 | E17: 31 | F17: =E17-G17 -> 30 | G17: 1 | I17: =(+D17*49.99999%)/E17*F17 -> 11129.03 | J17: =(I17*50%) -> 5564.515 | K17: =(1600/E17)*F17 -> 1548.3871 | L17: =(M17-I17-J17-K17) -> 2188.4225 | M17: =(D17-X17)/E17*F17-Z17 -> 20430.355 | N17: =IF($I17*0.12>1800,1800,$I17*0.12) -> 1335.4836 | O17: =IF(M17<=21000,M17*0.75%,0) -> 153.22766 | P17: 200 | Q17: 0 | R17: 0 | S17: 0 | T17: =M17+Q17+R17+S17 -> 20430.355 | U17: 0 | V17: 0 | W17: 0 | X17: =IF($I17*0.12>1800,1800,$I17*0.12) -> 1335.4836 | Y17: =IF(M17<=21000,M17*3.25%,0) -> 663.98653 | Z17: =I17*4.81% -> 535.30634 | AA17: =N17+O17+P17+V17+W17+U17+X17+Y17+Z17 -> 4223.4877 | AB17: =M17-AA17+Z17+X17 -> 18077.657
A18: AGS26034 | B18: Sripada Shivakumar | C18: 46083 | D18: 60000 | E18: 31 | F18: =E18-G18 -> 29 | G18: 2 | I18: =(+D18*49.99999%)/E18*F18 -> 28064.511 | J18: =(I18*50%) -> 14032.255 | K18: =(1600/E18)*F18 -> 1496.7742 | L18: =(M18-I18-J18-K18) -> 9501.7184 | M18: =(D18-X18)/E18*F18-Z18 -> 53095.258 | N18: =IF($I18*0.12>1800,1800,$I18*0.12) -> 1800 | O18: =IF(M18<=21000,M18*0.75%,0) -> 0 | P18: 200 | Q18: 0 | R18: 0 | S18: 0 | T18: =M18+Q18+R18+S18 -> 53095.258 | U18: 0 | V18: 0 | W18: 0 | X18: =IF($I18*0.12>1800,1800,$I18*0.12) -> 1800 | Y18: =IF(M18<=21000,M18*3.25%,0) -> 0 | Z18: =I18*4.81% -> 1349.903 | AA18: =N18+O18+P18+V18+W18+U18+X18+Y18+Z18 -> 5149.903 | AB18: =M18-AA18+Z18+X18 -> 51095.258
A19: AGS26035 | B19: Varakantham Surender Reddy | C19: 46083 | D19: 60000 | E19: 31 | F19: =E19-G19 -> 31 | G19: 0 | I19: =(+D19*49.99999%)/E19*F19 -> 29999.994 | J19: =(I19*50%) -> 14999.997 | K19: =(1600/E19)*F19 -> 1600 | L19: =(M19-I19-J19-K19) -> 10157.009 | M19: =(D19-X19)/E19*F19-Z19 -> 56757 | N19: =IF($I19*0.12>1800,1800,$I19*0.12) -> 1800 | O19: =IF(M19<=21000,M19*0.75%,0) -> 0 | P19: 200 | Q19: 0 | R19: 0 | S19: 0 | T19: =M19+Q19+R19+S19 -> 56757 | U19: 0 | V19: 0 | W19: 0 | X19: =IF($I19*0.12>1800,1800,$I19*0.12) -> 1800 | Y19: =IF(M19<=21000,M19*3.25%,0) -> 0 | Z19: =I19*4.81% -> 1442.9997 | AA19: =N19+O19+P19+V19+W19+U19+X19+Y19+Z19 -> 5242.9997 | AB19: =M19-AA19+Z19+X19 -> 54757
A20: AGS26041 | B20: Sudhagani Sai Charan | C20: 46113 | D20: 35000 | E20: 31 | F20: =E20-G20 -> 30 | G20: 1 | I20: =(+D20*49.99999%)/E20*F20 -> 16935.48 | J20: =(I20*50%) -> 8467.7402 | K20: =(1600/E20)*F20 -> 1548.3871 | L20: =(M20-I20-J20-K20) -> 4362.8278 | M20: =(D20-X20)/E20*F20-Z20 -> 31314.436 | N20: =IF($I20*0.12>1800,1800,$I20*0.12) -> 1800 | O20: =IF(M20<=21000,M20*0.75%,0) -> 0 | P20: 200 | Q20: 0 | R20: 0 | S20: 0 | T20: =M20+Q20+R20+S20 -> 31314.436 | U20: 0 | V20: 0 | W20: 0 | X20: =IF($I20*0.12>1800,1800,$I20*0.12) -> 1800 | Y20: =IF(M20<=21000,M20*3.25%,0) -> 0 | Z20: =I20*4.81% -> 814.59661 | AA20: =N20+O20+P20+V20+W20+U20+X20+Y20+Z20 -> 4614.5966 | AB20: =M20-AA20+Z20+X20 -> 29314.436
A21: AGS26043 | B21: Chebrolu Yashaswini | C21: 46113 | D21: 30000 | E21: 31 | F21: =E21-G21 -> 31 | G21: 0 | I21: =(+D21*49.99999%)/E21*F21 -> 14999.997 | J21: =(I21*50%) -> 7499.9985 | K21: =(1600/E21)*F21 -> 1600 | L21: =(M21-I21-J21-K21) -> 3378.505 | M21: =(D21-X21)/E21*F21-Z21 -> 27478.501 | N21: =IF($I21*0.12>1800,1800,$I21*0.12) -> 1799.9996 | O21: =IF(M21<=21000,M21*0.75%,0) -> 0 | P21: 200 | Q21: 0 | R21: 0 | S21: 0 | T21: =M21+Q21+R21+S21 -> 27478.501 | U21: 0 | V21: 0 | W21: 0 | X21: =IF($I21*0.12>1800,1800,$I21*0.12) -> 1799.9996 | Y21: =IF(M21<=21000,M21*3.25%,0) -> 0 | Z21: =I21*4.81% -> 721.49986 | AA21: =N21+O21+P21+V21+W21+U21+X21+Y21+Z21 -> 4521.4991 | AB21: =M21-AA21+Z21+X21 -> 25478.501
A22: AGS26045 | B22: Chebrolu Monika | C22: 46113 | D22: 50000 | E22: 31 | F22: =E22-G22 -> 31 | G22: 0 | I22: =(+D22*49.99999%)/E22*F22 -> 24999.995 | J22: =(I22*50%) -> 12499.997 | K22: =(1600/E22)*F22 -> 1600 | L22: =(M22-I22-J22-K22) -> 7897.5077 | M22: =(D22-X22)/E22*F22-Z22 -> 46997.5 | N22: =IF($I22*0.12>1800,1800,$I22*0.12) -> 1800 | O22: =IF(M22<=21000,M22*0.75%,0) -> 0 | P22: 200 | Q22: 0 | R22: 0 | S22: 0 | T22: =M22+Q22+R22+S22 -> 46997.5 | U22: 0 | V22: 0 | W22: 0 | X22: =IF($I22*0.12>1800,1800,$I22*0.12) -> 1800 | Y22: =IF(M22<=21000,M22*3.25%,0) -> 0 | Z22: =I22*4.81% -> 1202.4998 | AA22: =N22+O22+P22+V22+W22+U22+X22+Y22+Z22 -> 5002.4998 | AB22: =M22-AA22+Z22+X22 -> 44997.5
A23: AGS26047 | B23: Upadhyayula Naga Lakshmi Deepthi | C23: 46114 | D23: 23000 | E23: 31 | F23: =E23-G23 -> 30 | G23: 1 | I23: =(+D23*49.99999%)/E23*F23 -> 11129.03 | J23: =(I23*50%) -> 5564.515 | K23: =(1600/E23)*F23 -> 1548.3871 | L23: =(M23-I23-J23-K23) -> 2188.4225 | M23: =(D23-X23)/E23*F23-Z23 -> 20430.355 | N23: =IF($I23*0.12>1800,1800,$I23*0.12) -> 1335.4836 | O23: 0 | P23: 200 | Q23: 0 | R23: 0 | S23: 0 | T23: =M23+Q23+R23+S23 -> 20430.355 | U23: 0 | V23: 0 | W23: 0 | X23: =IF($I23*0.12>1800,1800,$I23*0.12) -> 1335.4836 | Y23: 0 | Z23: =I23*4.81% -> 535.30634 | AA23: =N23+O23+P23+V23+W23+U23+X23+Y23+Z23 -> 3406.2736 | AB23: =M23-AA23+Z23+X23 -> 18894.871
A24: AGS26048 | B24: Rapolu Rekha | C24: 46113 | D24: 15000 | E24: 31 | F24: =E24-G24 -> 31 | G24: 0 | I24: =(+D24*49.99999%)/E24*F24 -> 7499.9985 | J24: =(I24*50%) -> 3749.9992 | K24: =(1600/E24)*F24 -> 1600 | L24: =(M24-I24-J24-K24) -> 889.2525 | M24: =(D24-X24)/E24*F24-Z24 -> 13739.25 | N24: =IF($I24*0.12>1800,1800,$I24*0.12) -> 899.99982 | O24: 0 | P24: 150 | Q24: 0 | R24: 0 | S24: 0 | T24: =M24+Q24+R24+S24 -> 13739.25 | U24: 0 | V24: 0 | W24: 0 | X24: =IF($I24*0.12>1800,1800,$I24*0.12) -> 899.99982 | Y24: 0 | Z24: =I24*4.81% -> 360.74993 | AA24: =N24+O24+P24+V24+W24+U24+X24+Y24+Z24 -> 2310.7496 | AB24: =M24-AA24+Z24+X24 -> 12689.25
A25: AGS26049 | B25: Ragiru Nikhitha | C25: 46113 | D25: 15000 | E25: 31 | F25: =E25-G25 -> 31 | G25: 0 | I25: =(+D25*49.99999%)/E25*F25 -> 7499.9985 | J25: =(I25*50%) -> 3749.9992 | K25: =(1600/E25)*F25 -> 1600 | L25: =(M25-I25-J25-K25) -> 889.2525 | M25: =(D25-X25)/E25*F25-Z25 -> 13739.25 | N25: =IF($I25*0.12>1800,1800,$I25*0.12) -> 899.99982 | O25: 0 | P25: 150 | Q25: 0 | R25: 0 | S25: 0 | T25: =M25+Q25+R25+S25 -> 13739.25 | U25: 0 | V25: 0 | W25: 0 | X25: =IF($I25*0.12>1800,1800,$I25*0.12) -> 899.99982 | Y25: 0 | Z25: =I25*4.81% -> 360.74993 | AA25: =N25+O25+P25+V25+W25+U25+X25+Y25+Z25 -> 2310.7496 | AB25: =M25-AA25+Z25+X25 -> 12689.25
A26: AGS26051 | B26: Mundlamuri Mrudula | C26: 46113 | D26: 15000 | E26: 31 | F26: =E26-G26 -> 31 | G26: 0 | I26: =(+D26*49.99999%)/E26*F26 -> 7499.9985 | J26: =(I26*50%) -> 3749.9992 | K26: =(1600/E26)*F26 -> 1600 | L26: =(M26-I26-J26-K26) -> 889.2525 | M26: =(D26-X26)/E26*F26-Z26 -> 13739.25 | N26: =IF($I26*0.12>1800,1800,$I26*0.12) -> 899.99982 | O26: 0 | P26: 150 | Q26: 0 | R26: 0 | S26: 0 | T26: =M26+Q26+R26+S26 -> 13739.25 | U26: 0 | V26: 0 | W26: 0 | X26: =IF($I26*0.12>1800,1800,$I26*0.12) -> 899.99982 | Y26: 0 | Z26: =I26*4.81% -> 360.74993 | AA26: =N26+O26+P26+V26+W26+U26+X26+Y26+Z26 -> 2310.7496 | AB26: =M26-AA26+Z26+X26 -> 12689.25
A27: AGS26055 | B27: Cholleti Sai Kumar | C27: 46113 | D27: 15000 | E27: 31 | F27: =E27-G27 -> 14 | G27: 17 | I27: =(+D27*49.99999%)/E27*F27 -> 3387.0961 | J27: =(I27*50%) -> 1693.548 | K27: =(1600/E27)*F27 -> 722.58065 | L27: =(M27-I27-J27-K27) -> 624.49068 | M27: =(D27-X27)/E27*F27-Z27 -> 6427.7155 | N27: =IF($I27*0.12>1800,1800,$I27*0.12) -> 406.45153 | O27: 0 | P27: 150 | Q27: 0 | R27: 0 | S27: 0 | T27: =M27+Q27+R27+S27 -> 6427.7155 | U27: 0 | V27: 0 | W27: 0 | X27: =IF($I27*0.12>1800,1800,$I27*0.12) -> 406.45153 | Y27: 0 | Z27: =I27*4.81% -> 162.91932 | AA27: =N27+O27+P27+V27+W27+U27+X27+Y27+Z27 -> 1125.8224 | AB27: =M27-AA27+Z27+X27 -> 5871.2639
A28: AGS26053 | B28: Palavelli Praveen Reddy | C28: 46113 | D28: 15000 | E28: 31 | F28: =E28-G28 -> 31 | G28: 0 | I28: =(+D28*49.99999%)/E28*F28 -> 7499.9985 | J28: =(I28*50%) -> 3749.9992 | K28: =(1600/E28)*F28 -> 1600 | L28: =(M28-I28-J28-K28) -> 889.2525 | M28: =(D28-X28)/E28*F28-Z28 -> 13739.25 | N28: =IF($I28*0.12>1800,1800,$I28*0.12) -> 899.99982 | O28: 0 | P28: 150 | Q28: 0 | R28: 0 | S28: 0 | T28: =M28+Q28+R28+S28 -> 13739.25 | U28: 0 | V28: 0 | W28: 0 | X28: =IF($I28*0.12>1800,1800,$I28*0.12) -> 899.99982 | Y28: 0 | Z28: =I28*4.81% -> 360.74993 | AA28: =N28+O28+P28+V28+W28+U28+X28+Y28+Z28 -> 2310.7496 | AB28: =M28-AA28+Z28+X28 -> 12689.25
A29: AGS26054 | B29: Yaramothu Himaja | C29: 46113 | D29: 15000 | E29: 31 | F29: =E29-G29 -> 31 | G29: 0 | I29: =(+D29*49.99999%)/E29*F29 -> 7499.9985 | J29: =(I29*50%) -> 3749.9992 | K29: =(1600/E29)*F29 -> 1600 | L29: =(M29-I29-J29-K29) -> 889.2525 | M29: =(D29-X29)/E29*F29-Z29 -> 13739.25 | N29: =IF($I29*0.12>1800,1800,$I29*0.12) -> 899.99982 | O29: 0 | P29: 150 | Q29: 0 | R29: 0 | S29: 0 | T29: =M29+Q29+R29+S29 -> 13739.25 | U29: 0 | V29: 0 | W29: 0 | X29: =IF($I29*0.12>1800,1800,$I29*0.12) -> 899.99982 | Y29: 0 | Z29: =I29*4.81% -> 360.74993 | AA29: =N29+O29+P29+V29+W29+U29+X29+Y29+Z29 -> 2310.7496 | AB29: =M29-AA29+Z29+X29 -> 12689.25
A30: AGS26031 | B30: Y Raghavendar | C30: 46113 | D30: 45000 | E30: 31 | F30: =E30-G30 -> 31 | G30: 0 | I30: =(+D30*49.99999%)/E30*F30 -> 22499.995 | J30: =(I30*50%) -> 11249.998 | K30: =(1600/E30)*F30 -> 1600 | L30: =(M30-I30-J30-K30) -> 6767.757 | M30: =(D30-X30)/E30*F30-Z30 -> 42117.75 | N30: =IF($I30*0.12>1800,1800,$I30*0.12) -> 1800 | O30: 0 | P30: 200 | Q30: 0 | R30: 0 | S30: 0 | T30: =M30+Q30+R30+S30 -> 42117.75 | U30: 0 | V30: 0 | W30: 0 | X30: =IF($I30*0.12>1800,1800,$I30*0.12) -> 1800 | Y30: 0 | Z30: =I30*4.81% -> 1082.2498 | AA30: =N30+O30+P30+V30+W30+U30+X30+Y30+Z30 -> 4882.2498 | AB30: =M30-AA30+Z30+X30 -> 40117.75
A31: AGS26056 | B31: Bommala Naveen Kumar | C31: 46113 | D31: 45000 | E31: 31 | F31: =E31-G31 -> 31 | G31: 0 | I31: =(+D31*49.99999%)/E31*F31 -> 22499.995 | J31: =(I31*50%) -> 11249.998 | K31: =(1600/E31)*F31 -> 1600 | L31: =(M31-I31-J31-K31) -> 6767.757 | M31: =(D31-X31)/E31*F31-Z31 -> 42117.75 | N31: =IF($I31*0.12>1800,1800,$I31*0.12) -> 1800 | O31: 0 | P31: 200 | Q31: 0 | R31: 0 | S31: 0 | T31: =M31+Q31+R31+S31 -> 42117.75 | U31: 0 | V31: 0 | W31: 0 | X31: =IF($I31*0.12>1800,1800,$I31*0.12) -> 1800 | Y31: 0 | Z31: =I31*4.81% -> 1082.2498 | AA31: =N31+O31+P31+V31+W31+U31+X31+Y31+Z31 -> 4882.2498 | AB31: =M31-AA31+Z31+X31 -> 40117.75
A32: AGS26057 | B32: Odeti Srinivas | C32: 46113 | D32: 30000 | E32: 31 | F32: =E32-G32 -> 31 | G32: 0 | I32: =(+D32*49.99999%)/E32*F32 -> 14999.997 | J32: =(I32*50%) -> 7499.9985 | K32: =(1600/E32)*F32 -> 1600 | L32: =(M32-I32-J32-K32) -> 3378.505 | M32: =(D32-X32)/E32*F32-Z32 -> 27478.501 | N32: =IF($I32*0.12>1800,1800,$I32*0.12) -> 1799.9996 | O32: 0 | P32: 200 | Q32: 0 | R32: 0 | S32: 0 | T32: =M32+Q32+R32+S32 -> 27478.501 | U32: 0 | V32: 0 | W32: 0 | X32: =IF($I32*0.12>1800,1800,$I32*0.12) -> 1799.9996 | Y32: 0 | Z32: =I32*4.81% -> 721.49986 | AA32: =N32+O32+P32+V32+W32+U32+X32+Y32+Z32 -> 4521.4991 | AB32: =M32-AA32+Z32+X32 -> 25478.501
A33: AGS26058 | B33: Matha Sai Prasad | C33: 46113 | D33: 15000 | E33: 31 | F33: =E33-G33 -> 30 | G33: 1 | I33: =(+D33*49.99999%)/E33*F33 -> 7258.0631 | J33: =(I33*50%) -> 3629.0315 | K33: =(1600/E33)*F33 -> 1548.3871 | L33: =(M33-I33-J33-K33) -> 888.66267 | M33: =(D33-X33)/E33*F33-Z33 -> 13324.144 | N33: =IF($I33*0.12>1800,1800,$I33*0.12) -> 870.96757 | O33: 0 | P33: 150 | Q33: 0 | R33: 0 | S33: 0 | T33: =M33+Q33+R33+S33 -> 13324.144 | U33: 0 | V33: 0 | W33: 0 | X33: =IF($I33*0.12>1800,1800,$I33*0.12) -> 870.96757 | Y33: 0 | Z33: =I33*4.81% -> 349.11283 | AA33: =N33+O33+P33+V33+W33+U33+X33+Y33+Z33 -> 2241.048 | AB33: =M33-AA33+Z33+X33 -> 12303.177
A34: AGS26059 | B34: Chamakuri Raghuram | C34: 46113 | D34: 15000 | E34: 31 | F34: =E34-G34 -> 31 | G34: 0 | I34: =(+D34*49.99999%)/E34*F34 -> 7499.9985 | J34: =(I34*50%) -> 3749.9992 | K34: =(1600/E34)*F34 -> 1600 | L34: =(M34-I34-J34-K34) -> 889.2525 | M34: =(D34-X34)/E34*F34-Z34 -> 13739.25 | N34: =IF($I34*0.12>1800,1800,$I34*0.12) -> 899.99982 | O34: 0 | P34: 150 | Q34: 0 | R34: 0 | S34: 0 | T34: =M34+Q34+R34+S34 -> 13739.25 | U34: 0 | V34: 0 | W34: 0 | X34: =IF($I34*0.12>1800,1800,$I34*0.12) -> 899.99982 | Y34: 0 | Z34: =I34*4.81% -> 360.74993 | AA34: =N34+O34+P34+V34+W34+U34+X34+Y34+Z34 -> 2310.7496 | AB34: =M34-AA34+Z34+X34 -> 12689.25
A35: AGS26025 | B35: Tumula Dinesh Kumar | C35: 46113 | D35: 23000 | E35: 31 | F35: =E35-G35 -> 31 | G35: 0 | I35: =(+D35*49.99999%)/E35*F35 -> 11499.998 | J35: =(I35*50%) -> 5749.9988 | K35: =(1600/E35)*F35 -> 1600 | L35: =(M35-I35-J35-K35) -> 2216.8538 | M35: =(D35-X35)/E35*F35-Z35 -> 21066.85 | N35: =IF($I35*0.12>1800,1800,$I35*0.12) -> 1379.9997 | O35: =IF(M35<=21000,M35*0.75%,0) -> 0 | P35: 200 | Q35: 0 | R35: 0 | S35: 0 | T35: =M35+Q35+R35+S35 -> 21066.85 | U35: 0 | V35: 0 | W35: 0 | X35: =IF($I35*0.12>1800,1800,$I35*0.12) -> 1379.9997 | Y35: =IF(M35<=21000,M35*3.25%,0) -> 0 | Z35: =I35*4.81% -> 553.14989 | AA35: =N35+O35+P35+V35+W35+U35+X35+Y35+Z35 -> 3513.1493 | AB35: =M35-AA35+Z35+X35 -> 19486.851
A36: AGS26060 | B36: Thallada Venkatasagar | C36: 46114 | D36: 24000 | E36: 31 | F36: =E36-G36 -> 31 | G36: 0 | I36: =(+D36*49.99999%)/E36*F36 -> 11999.998 | J36: =(I36*50%) -> 5999.9988 | K36: =(1600/E36)*F36 -> 1600 | L36: =(M36-I36-J36-K36) -> 2382.804 | M36: =(D36-X36)/E36*F36-Z36 -> 21982.8 | N36: =IF($I36*0.12>1800,1800,$I36*0.12) -> 1439.9997 | O36: =IF(M36<=21000,M36*0.75%,0) -> 0 | P36: 200 | Q36: 0 | R36: 0 | S36: 0 | T36: =M36+Q36+R36+S36 -> 21982.8 | U36: 0 | V36: 0 | W36: 0 | X36: =IF($I36*0.12>1800,1800,$I36*0.12) -> 1439.9997 | Y36: =IF(M36<=21000,M36*3.25%,0) -> 0 | Z36: =I36*4.81% -> 577.19988 | AA36: =N36+O36+P36+V36+W36+U36+X36+Y36+Z36 -> 3657.1993 | AB36: =M36-AA36+Z36+X36 -> 20342.801
A37: AGS26044 | B37: Naveen Pulikonda | C37: 46113 | D37: 35000 | E37: 31 | F37: =E37-G37 -> 28.5 | G37: 2.5 | I37: =(+D37*49.99999%)/E37*F37 -> 16088.706 | J37: =(I37*50%) -> 8044.3532 | K37: =(1600/E37)*F37 -> 1470.9677 | L37: =(M37-I37-J37-K37) -> 4144.6864 | M37: =(D37-X37)/E37*F37-Z37 -> 29748.714 | N37: =IF($I37*0.12>1800,1800,$I37*0.12) -> 1800 | O37: =IF(M37<=21000,M37*0.75%,0) -> 0 | P37: 200 | Q37: 0 | R37: 0 | S37: 0 | T37: =M37+Q37+R37+S37 -> 29748.714 | U37: 0 | V37: 0 | W37: 0 | X37: =IF($I37*0.12>1800,1800,$I37*0.12) -> 1800 | Y37: =IF(M37<=21000,M37*3.25%,0) -> 0 | Z37: =I37*4.81% -> 773.86678 | AA37: =N37+O37+P37+V37+W37+U37+X37+Y37+Z37 -> 4573.8668 | AB37: =M37-AA37+Z37+X37 -> 27748.714
A38: AGS26073 | B38: KONDAPALLY AKHIL | C38: 46113 | D38: 100000 | E38: 31 | F38: =E38-G38 -> 31 | G38: 0 | I38: =(+D38*49.99999%)/E38*F38 -> 49999.99 | J38: =(I38*50%) -> 24999.995 | K38: =(1600/E38)*F38 -> 1600 | L38: =(M38-I38-J38-K38) -> 19195.015 | M38: =(D38-X38)/E38*F38-Z38 -> 95795 | N38: =IF($I38*0.12>1800,1800,$I38*0.12) -> 1800 | O38: =IF(M38<=21000,M38*0.75%,0) -> 0 | P38: 200 | Q38: 0 | R38: 0 | S38: 0 | T38: =M38+Q38+R38+S38 -> 95795 | U38: 0 | V38: 0 | W38: 0 | X38: =IF($I38*0.12>1800,1800,$I38*0.12) -> 1800 | Y38: =IF(M38<=21000,M38*3.25%,0) -> 0 | Z38: =I38*4.81% -> 2404.9995 | AA38: =N38+O38+P38+V38+W38+U38+X38+Y38+Z38 -> 6204.9995 | AB38: =M38-AA38+Z38+X38 -> 93795
A39: AGS26074 | B39: Manikonda Nagasurya Koundinya | C39: 46113 | D39: 33333 | E39: 31 | F39: =E39-G39 -> 31 | G39: 0 | I39: =(+D39*49.99999%)/E39*F39 -> 16666.497 | J39: =(I39*50%) -> 8333.2483 | K39: =(1600/E39)*F39 -> 1600 | L39: =(M39-I39-J39-K39) -> 4131.5965 | M39: =(D39-X39)/E39*F39-Z39 -> 30731.342 | N39: =IF($I39*0.12>1800,1800,$I39*0.12) -> 1800 | O39: =IF(M39<=21000,M39*0.75%,0) -> 0 | P39: 200 | Q39: 0 | R39: 0 | S39: 0 | T39: =M39+Q39+R39+S39 -> 30731.342 | U39: 0 | V39: 0 | W39: 0 | X39: =IF($I39*0.12>1800,1800,$I39*0.12) -> 1800 | Y39: =IF(M39<=21000,M39*3.25%,0) -> 0 | Z39: =I39*4.81% -> 801.65849 | AA39: =N39+O39+P39+V39+W39+U39+X39+Y39+Z39 -> 4601.6585 | AB39: =M39-AA39+Z39+X39 -> 28731.342
A40: AGS26061 | B40: Indla Kiran Kumar | C40: 46146 | D40: 35000 | E40: 31 | F40: 28 | G40: 0 | I40: =(+D40*49.99999%)/E40*F40 -> 15806.448 | J40: =(I40*50%) -> 7903.2242 | K40: =(1600/E40)*F40 -> 1445.1613 | L40: =(M40-I40-J40-K40) -> 4071.9726 | M40: =(D40-X40)/E40*F40-Z40 -> 29226.807 | N40: =IF($I40*0.12>1800,1800,$I40*0.12) -> 1800 | O40: =IF(M40<=21000,M40*0.75%,0) -> 0 | P40: 200 | Q40: 0 | R40: 0 | S40: 0 | T40: =M40+Q40+R40+S40 -> 29226.807 | U40: 0 | V40: 0 | W40: 0 | X40: =IF($I40*0.12>1800,1800,$I40*0.12) -> 1800 | Y40: =IF(M40<=21000,M40*3.25%,0) -> 0 | Z40: =I40*4.81% -> 760.29017 | AA40: =N40+O40+P40+V40+W40+U40+X40+Y40+Z40 -> 4560.2902 | AB40: =M40-AA40+Z40+X40 -> 27226.807
...

Sheet Salaries_30052026
A1: Employee ID | B1: Employee Name | C1: DOJ | D1: Net Salary Payable | E1: Bank Account Number | F1: IFSC code | G1: Bank Name | H1: Remarks
A2: AGS26006 | B2: Abhijeet Vijaysingh Pardeshi | C2: =VLOOKUP(A2,Employees!A1:C3,3,0) -> 46062 | D2: =VLOOKUP(A2,Employees!A1:AC3,29,0) -> 65329.466 | E2: 41280100007853 | F2: BARB0WALUJX | G2: BANK OF BARODA
A3: AGS26038 | B3: Ainala Saiesha | C3: =VLOOKUP(A3,Employees!A2:C4,3,0) -> 46086 | D3: =VLOOKUP(A3,Employees!A2:AC4,29,0) -> 90627.258 | E3: 99980130961795 | F3: FDRL0001555 | G3: Federal Bank
A4: AGS26004 | B4: Ande Sharath Chandra | C4: =VLOOKUP(Salaries_30052026!A4,Consultant!A1:C6,3,0) -> 46055 | D4: =VLOOKUP(A4,Consultant!A1:H6,8,0) -> 79800 | E4: 50100677371816 | F4: HDFC0001042 | G4: HDFC Bank
A5: AGS26005 | B5: Tanakala Janardhan | C5: =VLOOKUP(Salaries_30052026!A5,Consultant!A2:C7,3,0) -> 46055 | D5: =VLOOKUP(A5,Consultant!A2:H7,8,0) -> 69800 | E5: 99980130961985 | F5: FDRL0001555 | G5: Federal Bank
A6: AGS26020 | B6: Gurindapalli Krishna Chaitanya | C6: =VLOOKUP(Salaries_30052026!A6,Consultant!A3:C8,3,0) -> 46066 | D6: =VLOOKUP(A6,Consultant!A3:H8,8,0) -> 57864.516 | E6: 020201545829 | F6: ICIC0000202 | G6: ICICI Bank
A7: AGS26024 | B7: Priya Darshini Pola | C7: =VLOOKUP(Salaries_30052026!A7,Consultant!A4:C9,3,0) -> 46072 | D7: =VLOOKUP(A7,Consultant!A4:H9,8,0) -> 79800 | E7: 99980130963916 | F7: FDRL0001555 | G7: Federal Bank
A8: AGS26039 | B8: Esther Deva Priya | C8: =VLOOKUP(Salaries_30052026!A8,Consultant!A5:C10,3,0) -> 46092 | D8: =VLOOKUP(A8,Consultant!A5:H10,8,0) -> 19154.839 | E8: 99980130950434 | F8: FDRL0001555 | G8: Federal Bank
A9: AGS26011 | B9: Siddula Hemasai | C9: =VLOOKUP(A9,'Tech Employees'!A1:C51,3,0) -> 46083 | D9: =VLOOKUP(A9,'Tech Employees'!A1:AB51,28,0) -> 40117.75 | E9: 3327101004003 | F9: CNRB0003327 | G9: Canara Bank
A10: AGS26018 | B10: Settybathini Sathish | C10: =VLOOKUP(A10,'Tech Employees'!A2:C52,3,0) -> 46083 | D10: =VLOOKUP(A10,'Tech Employees'!A2:AB52,28,0) -> 37400.476 | E10: 50100595290241 | F10: HDFC0000075 | G10: HDFC Bank
A11: AGS26010 | B11: Vemula Varshith | C11: =VLOOKUP(A11,'Tech Employees'!A3:C53,3,0) -> 46083 | D11: =VLOOKUP(A11,'Tech Employees'!A3:AB53,28,0) -> 54757 | E11: 99980130961993 | F11: FDRL0001555 | G11: Federal Bank
A12: AGS26019 | B12: Nelapatla Srinivas | C12: =VLOOKUP(A12,'Tech Employees'!A4:C54,3,0) -> 46083 | D12: =VLOOKUP(A12,'Tech Employees'!A4:AB54,28,0) -> 19486.851 | E12: 99980130961951 | F12: FDRL0001555 | G12: Federal Bank
A13: AGS26014 | B13: Vulli Pavan | C13: =VLOOKUP(A13,'Tech Employees'!A5:C55,3,0) -> 46083 | D13: =VLOOKUP(A13,'Tech Employees'!A5:AB55,28,0) -> 44997.5 | E13: 77770116800885 | F13: FDRL0007777 | G13: Federal Bank
A14: AGS26017 | B14: Vavilla Saikumar | C14: =VLOOKUP(A14,'Tech Employees'!A6:C56,3,0) -> 46083 | D14: =VLOOKUP(A14,'Tech Employees'!A6:AB56,28,0) -> 40117.75 | E14: 99980130963940 | F14: FDRL0001555 | G14: Federal Bank
A15: AGS26016 | B15: Manisha Ashroba Virkar | C15: =VLOOKUP(A15,'Tech Employees'!A7:C57,3,0) -> 46083 | D15: =VLOOKUP(A15,'Tech Employees'!A7:AB57,28,0) -> 40117.75 | E15: 62297418711 | F15: SBIN0003801 | G15: State Bank of India
A16: AGS26015 | B16: Karne Narsimha Reddy | C16: =VLOOKUP(A16,'Tech Employees'!A8:C58,3,0) -> 46083 | D16: =VLOOKUP(A16,'Tech Employees'!A8:AB58,28,0) -> 40117.75 | E16: 99980130961886 | F16: FDRL0001555 | G16: Federal Bank
A17: AGS26013 | B17: Kalepu Vijay Kumar | C17: =VLOOKUP(A17,'Tech Employees'!A9:C59,3,0) -> 46083 | D17: =VLOOKUP(A17,'Tech Employees'!A9:AB59,28,0) -> 40117.75 | E17: 15550100112421 | F17: FDRL0001555 | G17: Federal Bank
A18: AGS26021 | B18: Kontham Sushma | C18: =VLOOKUP(A18,'Tech Employees'!A10:C60,3,0) -> 46083 | D18: =VLOOKUP(A18,'Tech Employees'!A10:AB60,28,0) -> 44997.5 | E18: 99980130961894 | F18: FDRL0001555 | G18: Federal Bank
A19: AGS26023 | B19: Bobbarala Varshini | C19: =VLOOKUP(A19,'Tech Employees'!A11:C61,3,0) -> 46083 | D19: =VLOOKUP(A19,'Tech Employees'!A11:AB61,28,0) -> 52926.129 | E19: 99980130961878 | F19: FDRL0001555 | G19: Federal Bank
A20: AGS26026 | B20: Surampudi Roop Sai | C20: =VLOOKUP(A20,'Tech Employees'!A12:C62,3,0) -> 46083 | D20: =VLOOKUP(A20,'Tech Employees'!A12:AB62,28,0) -> 54757 | E20: 615728726 | F20: IDIB000P121 | G20: Indian Bank
... A28: AGS26043 | B28: Chebrolu Yashaswini | C28: =VLOOKUP(A28,'Tech Employees'!A20:C70,3,0) -> 46113 | D28: =VLOOKUP(A28,'Tech Employees'!A20:AB70,28,0) -> 25478.501 | E28: 40590710609 | F28: SBIN0011984 | G28: State Bank of India
A29: AGS26045 | B29: Chebrolu Monika | C29: =VLOOKUP(A29,'Tech Employees'!A21:C71,3,0) -> 46113 | D29: =VLOOKUP(A29,'Tech Employees'!A21:AB71,28,0) -> 44997.5 | E29: 000801663119 | F29: ICIC0000008 | G29: ICICI Bank
A30: AGS26047 | B30: Upadhyayula Naga Lakshmi Deepthi | C30: =VLOOKUP(A30,'Tech Employees'!A22:C72,3,0) -> 46114 | D30: =VLOOKUP(A30,'Tech Employees'!A22:AB72,28,0) -> 18894.871 | E30: 55560103431927 | F30: FDRL0005556 | G30: Federal Bank
A31: AGS26048 | B31: Rapolu Rekha | C31: =VLOOKUP(A31,'Tech Employees'!A23:C73,3,0) -> 46113 | D31: =VLOOKUP(A31,'Tech Employees'!A23:AB73,28,0) -> 12689.25 | E31: 15550100112355 | F31: FDRL0001555 | G31: Federal Bank
A32: AGS26049 | B32: Ragiru Nikhitha | C32: =VLOOKUP(A32,'Tech Employees'!A24:C74,3,0) -> 46113 | D32: =VLOOKUP(A32,'Tech Employees'!A24:AB74,28,0) -> 12689.25 | E32: 15550100112280 | F32: FDRL0001555 | G32: Federal Bank
A33: AGS26051 | B33: Mundlamuri Mrudula | C33: =VLOOKUP(A33,'Tech Employees'!A25:C75,3,0) -> 46113 | D33: =VLOOKUP(A33,'Tech Employees'!A25:AB75,28,0) -> 12689.25 | E33: 15550100112272 | F33: FDRL0001555 | G33: Federal Bank
A34: AGS26053 | B34: Palavelli Praveen Reddy | C34: =VLOOKUP(A34,'Tech Employees'!A27:C77,3,0) -> 46113 | D34: =VLOOKUP(A34,'Tech Employees'!A27:AB77,28,0) -> 12689.25 | E34: 15550100112306 | F34: FDRL0001555 | G34: Federal Bank
A35: AGS26054 | B35: Yaramothu Himaja | C35: =VLOOKUP(A35,'Tech Employees'!A28:C78,3,0) -> 46113 | D35: =VLOOKUP(A35,'Tech Employees'!A28:AB78,28,0) -> 12689.25 | E35: 15550100112298 | F35: FDRL0001555 | G35: Federal Bank
A36: AGS26031 | B36: Y Raghavendar | C36: =VLOOKUP(A36,'Tech Employees'!A29:C79,3,0) -> 46113 | D36: =VLOOKUP(A36,'Tech Employees'!A29:AB79,28,0) -> 40117.75 | E36: 99980130961787 | F36: FDRL0001555 | G36: Federal Bank
A37: AGS26056 | B37: Bommala Naveen Kumar | C37: =VLOOKUP(A37,'Tech Employees'!A30:C80,3,0) -> 46113 | D37: =VLOOKUP(A37,'Tech Employees'!A30:AB80,28,0) -> 40117.75 | E37: 37097117593 | F37: SBIN0008833 | G37: State Bank of India
A38: AGS26057 | B38: Odeti Srinivas | C38: =VLOOKUP(A38,'Tech Employees'!A31:C81,3,0) -> 46113 | D38: =VLOOKUP(A38,'Tech Employees'!A31:AB81,28,0) -> 25478.501 | E38: 99980130961779 | F38: FDRL0001555 | G38: Federal Bank
A39: AGS26058 | B39: Matha Sai Prasad | C39: =VLOOKUP(A39,'Tech Employees'!A32:C82,3,0) -> 46113 | D39: =VLOOKUP(A39,'Tech Employees'!A32:AB82,28,0) -> 12303.177 | E39: 23520100016377 | F39: FDRL0002352 | G39: Federal Bank
A40: AGS26059 | B40: Chamakuri Raghuram | C40: =VLOOKUP(A40,'Tech Employees'!A33:C83,3,0) -> 46113 | D40: =VLOOKUP(A40,'Tech Employees'!A33:AB83,28,0) -> 12689.25 | E40: 15550100112322 | F40: FDRL0001555 | G40: Federal Bank
A41: AGS26025 | B41: Tumula Dinesh Kumar | C41: =VLOOKUP(A41,'Tech Employees'!A34:C84,3,0) -> 46113 | D41: =VLOOKUP(A41,'Tech Employees'!A34:AB84,28,0) -> 19486.851 | E41: 44610100006654 | F41: BARB0SIDDIP | G41: Bank of Baroda
A42: AGS26060 | B42: Thallada Venkatasagar | C42: =VLOOKUP(A42,'Tech Employees'!A35:C85,3,0) -> 46114 | D42: =VLOOKUP(A42,'Tech Employees'!A35:AB85,28,0) -> 20342.801 | E42: 15550100112363 | F42: FDRL0001555 | G42: Federal Bank
A43: AGS26044 | B43: Naveen Pulikonda | C43: =VLOOKUP(A43,'Tech Employees'!A36:C86,3,0) -> 46113 | D43: =VLOOKUP(A43,'Tech Employees'!A36:AB86,28,0) -> 27748.714 | E43: 15550100112330 | F43: FDRL0001555 | G43: Federal Bank
A44: AGS26073 | B44: KONDAPALLY AKHIL | C44: =VLOOKUP(A44,'Tech Employees'!A37:C87,3,0) -> 46113 | D44: =VLOOKUP(A44,'Tech Employees'!A37:AB87,28,0) -> 93795 | E44: 38613963272 | F44: SBIN0010328 | G44: State Bank of India
A45: AGS26074 | B45: Manikonda Nagasurya Koundinya | C45: =VLOOKUP(A45,'Tech Employees'!A38:C88,3,0) -> 46113 | D45: =VLOOKUP(A45,'Tech Employees'!A38:AB88,28,0) -> 28731.342 | E45: 180701000002091 | F45: IOBA0001807 | G45: Indian Overseas Bank
... A57: AGS26076 | B57: Shaik Arif | C57: =VLOOKUP(A57,'Tech Employees'!A50:C100,3,0) -> 46148 | D57: =VLOOKUP(A57,'Tech Employees'!A50:AB100,28,0) -> 10274.352 | E57: 55560103492226 | F57: FDRL0005556 | G57: Federal Bank
A58: AGS26055 | B58: Cholleti Sai Kumar | C58: =VLOOKUP(A58,'Tech Employees'!A26:C76,3,0) -> 46113 | D58: HOLD | E58: HOLD | F58: HOLD | G58: HOLD | H58: 5871
...

Sheet Trainers
A1: S.No | B1: Name | C1: No of Hours | D1: Cost per Hour | E1: Total Cost | F1: Bank Account Number | G1: IFSC code | H1: Account holder Name | I1: Bank Name
A2: 1 | B2: Sridhar | E2: 230000 | F2: 32862142889 | G2: SBIN0011121 | H2: ERGAMREDDY SARADHA | I2: SBI
A3: 2 | B3: Gayathri K | E3: 81290 | F3: 38764884239 | G3: SBIN0009047 | H3: Puttathayamma | I3: SBI
A4: 3 | B4: Sreekanth (Arjun) | C4: 17 | D4: 1200 | E4: =C4*D4 -> 20400 | F4: 004001579702 | G4: ICIC0001806 | H4: Sreekanth Koraboina | I4: ICICI Bank
A5: 4 | B5: Ravi | C5: 16.5 | D5: 1200 | E5: =C5*D5 -> 19800 | F5: 653101004326 | G5: ICIC0000053 | H5: G Ravi Teja | I5: ICICI Bank
A6: 5 | B6: Venkatesh Salla | C6: 17.5 | D6: 1000 | E6: =C6*D6 -> 17500 | F6: 922020060410761 | G6: UTIB0003985 | H6: KAKARLA PRASAD BABU | I6: Axis Bank
A7: 6 | B7: Madhuri | C7: 22.5 | D7: 1000 | E7: =C7*D7 -> 22500 | F7: 814649188 | G7: IDIB000C026 | H7: K GOPINADH | I7: INDIAN BANK
A8: 7 | B8: Chetna | C8: 2 | D8: 1000 | E8: =C8*D8 -> 2000 | F8: 50100115451901 | G8: HDFC0000485 | H8: HDFC0000485 | I8: HDFC
A9: 8 | B9: Akshay | C9: 19 | D9: 800 | E9: =C9*D9 -> 15200 | F9: 45080524946 | G9: SBIN0020030 | H9: Shweta Akshay Painjane | I9: SBI
C11: Total | E11: =SUM(E2:E10) -> 408690

Sheet Rental Payment
A1: Account holder Name | B1: Actual Cost | C1: GST | D1: Total Cost | E1: Bank Account Number | F1: IFSC code | G1: Bank Name | H1: Account Type
A2: ODCET CONSULTANCY SERVICES PVT LTD GST Number : 36AADCO5390F1ZD | B2: 160000 | C2: =B2*0.18 -> 28800 | D2: =B2+C2 -> 188800 | E2: 50200062999445 | F2: HDFC0000364 | G2: HDFC | H2: CURRENT

Sheet LOP
A1: Employee ID | B1: Employee Name | C1: LOP day's
A2: AGS26018 | B2: Settybathini Sathish | C2: 2
A3: AGS26023 | B3: Bobbarala Varshini | C3: 1
A4: AGS26032 | B4: Vempadapu Uday Sai Tarun | C4: 1
A5: AGS26034 | B5: Sripada Shivakumar | C5: 2
A6: AGS26038 | B6: Ainala Saiesha | C6: 1
A7: AGS26041 | B7: Sudhagani Sai Charan | C7: 1
A8: AGS26044 | B8: Naveen Pulikonda | C8: 4.5
A9: AGS26047 | B9: Upadhyayula Naga Lakshmi Deepthi | C9: 1
A10: AGS26055 | B10: Cholleti Sai Kumar | C10: 17
A11: AGS26058 | B11: Matha Sai Prasad | C11: 1
A12: AGS26062 | B12: K Tharun Kumar Reddy | C12: 3
A13: AGS26073 | B13: Boya Indrasena Naidu | C13: 3

Sheet Salaries_30042026
A1: Employee ID | B1: Employee Name | C1: DOJ | D1: Net Salary Payable | E1: Bank Account Number | F1: IFSC code | G1: Bank Name | H1: Remarks
A2: AGS26004 | B2: Ande Sharath Chandra | C2: 46054 | D2: =VLOOKUP(A2,Consultant!A2:H6,8,0) -> 79800 | E2: 50100677371816 | F2: HDFC0001042 | G2: HDFC Bank
A3: AGS26005 | B3: Tanakala Janardhan | C3: 46054 | D3: =VLOOKUP(A3,Consultant!A3:H7,8,0) -> 69800 | E3: 99980130961985 | F3: FDRL0001555 | G3: Federal Bank
A4: AGS26006 | B4: Abhijeet Vijaysingh Pardeshi | C4: 46062 | D4: =VLOOKUP(A4,Employees!2:3,29,0) -> 65329.466 | E4: 41280100007853 | F4: BARB0WALUJX | G4: BANK OF BARODA
A5: AGS26010 | B5: Vemula Varshith | C5: 46083 | D5: =VLOOKUP(A5,'Tech Employees'!A4:AB39,28,0) -> 54757 | E5: 99980130961993 | F5: FDRL0001555 | G5: Federal Bank
A6: AGS26011 | B6: Siddula Hemasai | C6: 46083 | D6: =VLOOKUP(A6,'Tech Employees'!A2:AB37,28,0) -> 40117.75 | E6: 3327101004003 | F6: CNRB0003327 | G6: Canara Bank
A7: AGS26013 | B7: Kalepu Vijay | C7: 46083 | D7: =VLOOKUP(A7,'Tech Employees'!A10:AB45,28,0) -> 40117.75 | E7: 159502740717 | F7: INDB0000329 | G7: INDUSIND BANK
A8: AGS26014 | B8: Vulli Pavan | C8: 46083 | D8: =VLOOKUP(A8,'Tech Employees'!A6:AB41,28,0) -> 44997.5 | E8: 77770116800885 | F8: FDRL0007777 | G8: Federal Bank
A9: AGS26015 | B9: Karne Narsimha Reddy | C9: 46083 | D9: =VLOOKUP(A9,'Tech Employees'!A9:AB44,28,0) -> 40117.75 | E9: 99980130961886 | F9: FDRL0001555 | G9: Federal Bank
A10: AGS26016 | B10: Manisha Ashroba Virkar | C10: 46083 | D10: =VLOOKUP(A10,'Tech Employees'!A8:AB43,28,0) -> 40117.75 | E10: 62297418711 | F10: SBIN0003801 | G10: State Bank of India
A11: AGS26017 | B11: Vavilla Saikumar | C11: 46083 | D11: =VLOOKUP(A11,'Tech Employees'!A7:AB42,28,0) -> 40117.75 | E11: 99980130963940 | F11: FDRL0001555 | G11: Federal Bank
A12: AGS26018 | B12: Settybathini Sathish | C12: 46083 | D12: =VLOOKUP(A12,'Tech Employees'!A3:AB38,28,0) -> 37400.476 | E12: 50100595290241 | F12: HDFC0000075 | G12: HDFC Bank
A13: AGS26019 | B13: Nelapatla Srinivas | C13: 46083 | D13: =VLOOKUP(A13,'Tech Employees'!A5:AB40,28,0) -> 19486.851 | E13: 99980130961951 | F13: FDRL0001555 | G13: Federal Bank
A14: AGS26020 | B14: Gurindapalli Krishna Chaitanya | C14: 46066 | D14: =VLOOKUP(A14,Consultant!A4:H8,8,0) -> 57864.516 | E14: 020201545829 | F14: ICIC0000202 | G14: ICICI Bank
A15: AGS26021 | B15: Kontham Sushma | C15: 46083 | D15: =VLOOKUP(A15,'Tech Employees'!A11:AB46,28,0) -> 44997.5 | E15: 99980130961894 | F15: FDRL0001555 | G15: Federal Bank
A16: AGS26023 | B16: Bobbarala Varshini | C16: 46083 | D16: =VLOOKUP(A16,'Tech Employees'!A12:AB48,28,0) -> 52926.129 | E16: 99980130961878 | F16: FDRL0001555 | G16: Federal Bank
A17: AGS26024 | B17: Priya Darshini Pola | C17: 46072 | D17: =VLOOKUP(A17,Consultant!A5:H9,8,0) -> 79800 | E17: 99980130963916 | F17: FDRL0001555 | G17: Federal Bank
A18: AGS26025 | B18: Tumula Dinesh Kumar | C18: 46113 | D18: =VLOOKUP(A18,'Tech Employees'!A35:AB72,28,0) -> 19486.851 | E18: 44610100006654 | F18: BARB0SIDDIP | G18: Bank of Baroda
A19: AGS26026 | B19: Surampudi Roop Sai | C19: 46083 | D19: =VLOOKUP(A19,'Tech Employees'!A13:AB49,28,0) -> 54757 | E19: 615728726 | F19: IDIB000P121 | G19: Indian Bank
A20: AGS26028 | B20: Mohammed Abdul Moid | C20: 46083 | D20: =VLOOKUP(A20,'Tech Employees'!A14:AB50,28,0) -> 12639.25 | E20: 99980130963882 | F20: FDRL0001555 | G20: Federal Bank
A21: AGS26029 | B21: Mula Sai Preetham Goud | C21: 46083 | D21: =VLOOKUP(A21,'Tech Employees'!A15:AB51,28,0) -> 30358.25 | E21: 99980130961902 | F21: FDRL0001555 | G21: Federal Bank
A22: AGS26030 | B22: Sruthin Kumar Basa | C22: 46083 | D22: =VLOOKUP(A22,'Tech Employees'!A16:AB52,28,0) -> 30358.25 | E22: 99980130961761 | F22: FDRL0001555 | G22: Federal Bank
A23: AGS26031 | B23: Y Raghavendar | C23: 46113 | D23: =VLOOKUP(A23,'Tech Employees'!A30:AB67,28,0) -> 40117.75 | E23: 99980130961787 | F23: FDRL0001555 | G23: Federal Bank
A24: AGS26032 | B24: Vempadapu Uday Sai Tarun | C24: 46083 | D24: =VLOOKUP(A24,'Tech Employees'!A17:AB53,28,0) -> 18077.657 | E24: 37182972098 | F24: SBIN0008054 | G24: State Bank of India
A25: AGS26034 | B25: Sripada Shivakumar | C25: 46083 | D25: =VLOOKUP(A25,'Tech Employees'!A18:AB55,28,0) -> 51095.258 | E25: 41536691505 | F25: SBIN0008807 | G25: State Bank of India
A26: AGS26035 | B26: Varakantham Surender Reddy | C26: 46083 | D26: =VLOOKUP(A26,'Tech Employees'!A19:AB56,28,0) -> 54757 | E26: 50100141200194 | F26: HDFC0004480 | G26: HDFC Bank
A27: AGS26038 | B27: Ainala Saiesha | C27: 46086 | D27: =VLOOKUP(A27,Employees!3:4,29,0) -> 90627.258 | E27: 99980130961795 | F27: FDRL0001555 | G27: Federal Bank
A28: AGS26039 | B28: Esther Deva Priya | C28: 46092 | D28: =VLOOKUP(A28,Consultant!A6:H10,8,0) -> 19154.839 | E28: 99980130950434 | F28: FDRL0001555 | G28: Federal Bank
A29: AGS26041 | B29: Sudhagani Sai Charan | C29: 46113 | D29: =VLOOKUP(A29,'Tech Employees'!A20:AB57,28,0) -> 29314.436 | E29: 15550100112314 | F29: FDRL0001555 | G29: Federal Bank
A30: AGS26043 | B30: Chebrolu Yashaswini | C30: 46113 | D30: =VLOOKUP(A30,'Tech Employees'!A21:AB58,28,0) -> 25478.501 | E30: 40590710609 | F30: SBIN0011984 | G30: State Bank of India
A31: AGS26044 | B31: Naveen Pulikonda | C31: 46113 | D31: =VLOOKUP(A31,'Tech Employees'!A37:AB74,28,0) -> 27748.714 | E31: 15550100112330 | F31: FDRL0001555 | G31: Federal Bank
A32: AGS26045 | B32: Chebrolu Monika | C32: 46113 | D32: =VLOOKUP(A32,'Tech Employees'!A22:AB59,28,0) -> 44997.5 | E32: 801663119 | F32: ICIC0000008 | G32: ICICI Bank
A33: AGS26047 | B33: Upadhyayula Naga Lakshmi Deepthi | C33: 46113 | D33: =VLOOKUP(A33,'Tech Employees'!A23:AB60,28,0) -> 18894.871 | E33: 55560103431927 | F33: FDRL0005556 | G33: Federal bank
A34: AGS26048 | B34: Rapolu Rekha | C34: 46113 | D34: =VLOOKUP(A34,'Tech Employees'!A24:AB61,28,0) -> 12689.25 | E34: 15550100112355 | F34: FDRL0001555 | G34: Federal Bank
A35: AGS26049 | B35: Ragiru Nikhitha | C35: 46113 | D35: =VLOOKUP(A35,'Tech Employees'!A25:AB62,28,0) -> 12689.25 | E35: 15550100112280 | F35: FDRL0001555 | G35: Federal Bank
A36: AGS26051 | B36: Mundlamuri Mrudula | C36: 46113 | D36: =VLOOKUP(A36,'Tech Employees'!A26:AB63,28,0) -> 12689.25 | E36: 386701504229 | F36: ICIC0003867 | G36: ICICI Bank
A37: AGS26053 | B37: Palavelli Praveen Reddy | C37: 46113 | D37: =VLOOKUP(A37,'Tech Employees'!A28:AB65,28,0) -> 12689.25 | E37: 15550100112306 | F37: FDRL0001555 | G37: Federal Bank
A38: AGS26054 | B38: Yaramothu Himaja | C38: 46113 | D38: =VLOOKUP(A38,'Tech Employees'!A29:AB66,28,0) -> 12689.25 | E38: 15550100112298 | F38: FDRL0001555 | G38: Federal Bank
A39: AGS26055 | B39: Cholleti Sai Kumar | C39: 46113 | D39: =VLOOKUP(A39,'Tech Employees'!A27:AB64,28,0) -> 5871.2639 | E39: 44652833670 | F39: SBIN0021487 | G39: State Bank of India
A40: AGS26056 | B40: Bommala Naveen Kumar | C40: 46113 | D40: =VLOOKUP(A40,'Tech Employees'!A31:AB68,28,0) -> 40117.75 | E40: 37097117593 | F40: SBIN0008833 | G40: State Bank of India
...

Sheet Payments_30042026
A1: S.No | B1: Name | C1: No of Hours | D1: Cost per Hour | E1: Total Cost | F1: Bank Account Number | G1: IFSC code | H1: Account holder Name | I1: Bank Name
A2: 1 | B2: Sridhar | E2: 230000 | F2: 32862142889 | G2: SBIN0011121 | H2: ERGAMREDDY SARADHA | I2: SBI
A3: 2 | B3: Sreekanth (Arjun) | C3: 22 | D3: 1200 | E3: =C3*D3 -> 26400 | F3: 004001579702 | G3: ICIC0001806 | H3: Sreekanth Koraboina | I3: ICICI Bank
A4: 3 | B4: Ravi | C4: 22 | D4: 1200 | E4: =C4*D4 -> 26400 | F4: 653101004326 | G4: ICIC0000053 | H4: G Ravi Teja | I4: ICICI Bank
A5: 4 | B5: Venkatesh Salla | C5: 30 | D5: 1000 | E5: =C5*D5 -> 30000 | F5: 922020060410761 | G5: UTIB0003985 | H5: KAKARLA PRASAD BABU | I5: Axis Bank
A6: 5 | B6: Madhuri | C6: 30 | D6: 1000 | E6: =C6*D6 -> 30000 | F6: 814649188 | G6: IDIB000C026 | H6: K GOPINADH | I6: INDIAN BANK
A7: 6 | B7: Chetna | C7: 13.5 | D7: 1000 | E7: =C7*D7 -> 13500 | F7: 50100115451901 | G7: HDFC0000485 | H7: HDFC0000485 | I7: HDFC
A8: 7 | B8: Akshay | C8: 19 | D8: 800 | E8: =C8*D8 -> 15200 | F8: 45080524946 | G8: SBIN0020030 | H8: Shweta Akshay Painjane | I8: SBI
A9: 8 | B9: ODCET | E9: 160000 | F9: 50200062999445 | G9: HDFC0000364 | H9: ODCET CONSULTANCY SERVICES PVT LTD | I9: HDFC
A10: 9 | B10: ZOHO Corporation Private Limited | E10: 22583.06 | F10: 50200026430541 | G10: HDFC0001225 | H10: ZOHO Corporation Private Limited | I10: HDFC
B12: Total | E12: =SUM(E2:E10) -> 554083.06

Sheet Payment
A1: Employee ID | B1: Employee Name | C1: DOJ | D1: Net Salary Payable | E1: Bank Account Number | F1: IFSC code | G1: Bank Name | H1: Remarks
A2: AGS26022 | B2: Akkma Sai Teja | C2: 46083 | D2: =VLOOKUP(A2,'Tech Employees'!A12:AB47,28,0) -> #N/A | E2: 50100565431077 | F2: HDFC0005175 | G2: HDFC Bank | H2: Hold
A3: AGS26004 | B3: Ande Sharath Chandra | C3: 46054 | D3: =VLOOKUP(A3,Consultant!A2:H6,8,0) -> 79800 | E3: 50100677371816 | F3: HDFC0001042 | G3: HDFC Bank
A4: AGS26005 | B4: Tanakala Janardhan | C4: 46054 | D4: =VLOOKUP(A4,Consultant!A3:H7,8,0) -> 69800 | E4: 154710100018477 | F4: UBIN0815471 | G4: Union Bank
A5: AGS26006 | B5: Abhijeet Vijaysingh Pardeshi | C5: 46062 | D5: =VLOOKUP(A5,Employees!2:3,29,0) -> 65329.466 | E5: 41280100007853 | F5: BARB0WALUJX | G5: BANK OF BARODA
A6: AGS26010 | B6: Vemula Varshith | C6: 46083 | D6: =VLOOKUP(A6,'Tech Employees'!A4:AB39,28,0) -> 54757 | E6: 62428832885 | F6: SBIN0020959 | G6: State Bank of India
A7: AGS26011 | B7: Siddula Hemasai | C7: 46083 | D7: =VLOOKUP(A7,'Tech Employees'!A2:AB37,28,0) -> 40117.75 | E7: 3327101004003 | F7: CNRB0003327 | G7: Canara Bank
A8: AGS26013 | B8: Kalepu Vijay | C8: 46083 | D8: =VLOOKUP(A8,'Tech Employees'!A10:AB45,28,0) -> 40117.75 | E8: 159502740717 | F8: INDB0000329 | G8: INDUSIND BANK
A9: AGS26014 | B9: Vulli Pavan | C9: 46083 | D9: =VLOOKUP(A9,'Tech Employees'!A6:AB41,28,0) -> 44997.5 | E9: 77770116800885 | F9: FDRL0007777 | G9: Federal Bank
A10: AGS26015 | B10: Karne Narsimha Reddy | C10: 46083 | D10: =VLOOKUP(A10,'Tech Employees'!A9:AB44,28,0) -> 40117.75 | E10: 1.446178e+15 | F10: KVBL0001446 | G10: Karur Vysya Bank
A11: AGS26016 | B11: Manisha Ashroba Virkar | C11: 46083 | D11: =VLOOKUP(A11,'Tech Employees'!A8:AB43,28,0) -> 40117.75 | E11: 62297418711 | F11: SBIN0003801 | G11: State Bank of India
A12: AGS26017 | B12: Vavilla Saikumar | C12: 46083 | D12: =VLOOKUP(A12,'Tech Employees'!A7:AB42,28,0) -> 40117.75 | E12: 41085488775 | F12: SBIN0016293 | G12: State Bank of India
A13: AGS26018 | B13: Settybathini Sathish | C13: 46083 | D13: =VLOOKUP(A13,'Tech Employees'!A3:AB38,28,0) -> 37400.476 | E13: 50100595290241 | F13: HDFC0000075 | G13: HDFC Bank
A14: AGS26019 | B14: Nelapatla Srinivas | C14: 46083 | D14: =VLOOKUP(A14,'Tech Employees'!A5:AB40,28,0) -> 19486.851 | E14: 62442668281 | F14: SBIN0020176 | G14: State Bank of India
A15: AGS26020 | B15: Gurindapalli Krishna Chaitanya | C15: 46066 | D15: =VLOOKUP(A15,Consultant!A4:H8,8,0) -> 57864.516 | E15: 020201545829 | F15: ICIC0000202 | G15: ICICI Bank
A16: AGS26021 | B16: Kontham Sushma | C16: 46083 | D16: =VLOOKUP(A16,'Tech Employees'!A11:AB46,28,0) -> 44997.5 | E16: 39569845546 | F16: SBIN0008024 | G16: State Bank of India
A17: AGS26023 | B17: Bobbarala Varshini | C17: 46083 | D17: =VLOOKUP(A17,'Tech Employees'!A12:AB48,28,0) -> 52926.129 | E17: 41202390653 | F17: SBIN0000910 | G17: State Bank of India
A18: AGS26024 | B18: Priya Darshini Pola | C18: 46072 | D18: =VLOOKUP(A18,Consultant!A5:H9,8,0) -> 79800 | E18: 770301501355 | F18: ICIC0007703 | G18: ICICI Bank
A19: AGS26025 | B19: Tumula Dinesh Kumar | C19: 46113 | D19: =VLOOKUP(A19,'Tech Employees'!A35:AB72,28,0) -> 19486.851 | E19: 44610100006654 | F19: BARB0SIDDIP | G19: Bank of Baroda
A20: AGS26026 | B20: Surampudi Roop Sai | C20: 46083 | D20: =VLOOKUP(A20,'Tech Employees'!A13:AB49,28,0) -> 54757 | E20: 615728726 | F20: IDIB000P121 | G20: Indian Bank
A21: AGS26028 | B21: Mohammed Abdul Moid | C21: 46083 | D21: =VLOOKUP(A21,'Tech Employees'!A14:AB50,28,0) -> 12639.25 | E21: 9147600708 | F21: KKBK0007474 | G21: Kotak
A22: AGS26029 | B22: Mula Sai Preetham Goud | C22: 46083 | D22: =VLOOKUP(A22,'Tech Employees'!A15:AB51,28,0) -> 30358.25 | E22: 7445588605 | F22: KKBK0007462 | G22: Kotak
A23: AGS26030 | B23: Sruthin Kumar Basa | C23: 46083 | D23: =VLOOKUP(A23,'Tech Employees'!A16:AB52,28,0) -> 30358.25 | E23: 4495101004331 | F23: CNRB0004495 | G23: Canara Bank
A24: AGS26031 | B24: Y Raghavendar | C24: 46113 | D24: =VLOOKUP(A24,'Tech Employees'!A30:AB67,28,0) -> 40117.75 | E24: 20086309269 | F24: SBIN0013071 | G24: State Bank of India
A25: AGS26032 | B25: Vempadapu Uday Sai Tarun | C25: 46083 | D25: =VLOOKUP(A25,'Tech Employees'!A17:AB53,28,0) -> 18077.657 | E25: 37182972098 | F25: SBIN0008054 | G25: State Bank of India
A26: AGS26033 | B26: Kethavath Sai Raj | C26: 46083 | D26: =VLOOKUP(A26,'Tech Employees'!A18:AB54,28,0) -> #N/A | E26: 39971511897 | F26: SBIN0021227 | G26: State Bank of India
A27: AGS26034 | B27: Sripada Shivakumar | C27: 46083 | D27: =VLOOKUP(A27,'Tech Employees'!A18:AB55,28,0) -> 51095.258 | E27: 41536691505 | F27: SBIN0008807 | G27: State Bank of India
A28: AGS26035 | B28: Varakantham Surender Reddy | C28: 46083 | D28: =VLOOKUP(A28,'Tech Employees'!A19:AB56,28,0) -> 54757 | E28: 50100141200194 | F28: HDFC0004480 | G28: HDFC Bank
A29: AGS26038 | B29: Ainala Saiesha | C29: 46086 | D29: =VLOOKUP(A29,Employees!3:4,29,0) -> 90627.258 | E29: 50100868298601 | F29: HDFC0003665 | G29: HDFC Bank
A30: AGS26039 | B30: Esther Deva Priya | C30: 46092 | D30: =VLOOKUP(A30,Consultant!A6:H10,8,0) -> 19154.839 | E30: 50100743220366 | F30: HDFC0000545 | G30: HDFC Bank
A31: AGS26041 | B31: Sudhagani Sai Charan | C31: 46113 | D31: =VLOOKUP(A31,'Tech Employees'!A20:AB57,28,0) -> 29314.436 | E31: 920010070801185 | F31: UTIB0000008 | G31: Axis Bank
A32: AGS26043 | B32: Chebrolu Yashaswini | C32: 46113 | D32: =VLOOKUP(A32,'Tech Employees'!A21:AB58,28,0) -> 25478.501 | E32: 40590710609 | F32: SBIN0011984 | G32: SBI
A33: AGS26044 | B33: Naveen Pulikonda | C33: 46113 | D33: =VLOOKUP(A33,'Tech Employees'!A37:AB74,28,0) -> 27748.714 | E33: 111101513423 | F33: ICIC0001111 | G33: ICICI Bank
A34: AGS26045 | B34: Chebrolu Monika | C34: 46113 | D34: =VLOOKUP(A34,'Tech Employees'!A22:AB59,28,0) -> 44997.5 | E34: 801663119 | F34: ICIC0000008 | G34: ICICI Bank
A35: AGS26047 | B35: Upadhyayula Naga Lakshmi Deepthi | C35: 46113 | D35: =VLOOKUP(A35,'Tech Employees'!A23:AB60,28,0) -> 18894.871 | E35: 55560103431927 | F35: FDRL0005556 | G35: Federal bank
A36: AGS26048 | B36: Rapolu Rekha | C36: 46113 | D36: =VLOOKUP(A36,'Tech Employees'!A24:AB61,28,0) -> 12689.25 | E36: 55560103536675 | F36: FDRL0005556 | G36: Federal bank
A37: AGS26049 | B37: Ragiru Nikhitha | C37: 46113 | D37: =VLOOKUP(A37,'Tech Employees'!A25:AB62,28,0) -> 12689.25 | E37: 110240929810 | F37: CNRB0007792 | G37: Canara Bank
A38: AGS26051 | B38: Mundlamuri Mrudula | C38: 46113 | D38: =VLOOKUP(A38,'Tech Employees'!A26:AB63,28,0) -> 12689.25 | E38: 386701504229 | F38: ICIC0003867 | G38: ICICI Bank
A39: AGS26053 | B39: Palavelli Praveen Reddy | C39: 46113 | D39: =VLOOKUP(A39,'Tech Employees'!A28:AB65,28,0) -> 12689.25 | E39: 520101254028703 | F39: UBIN0826383 | G39: Union Bank of India
A40: AGS26054 | B40: Yaramothu Himaja | C40: 46113 | D40: =VLOOKUP(A40,'Tech Employees'!A29:AB66,28,0) -> 12689.25 | E40: 263812010000686 | F40: UBIN0826383 | G40: Union Bank Of India
...
