Workbook

Sheet Employees
A1: Employee ID | B1: Employee Name | C1: DOJ | D1: CTC | E1: Calendar Days | F1: Paid Days | G1: LOP day's | H1: Basic | I1: HRA | J1: Special Allowance | K1: Other Allowance | L1: Gross Income | M1: Employee PF (12%) | N1: Employee ESI (0.75%) | O1: Professional Tax | P1: Arrears | Q1: Reimbursements | R1: Bonus/Incentive | S1: Gross Earnings | T1: TDS | U1: LOP Deduction | V1: Other Deductions | W1: Employer PF (12%) | X1: Employer ESI (3.25%) | Y1: Gratuity (4.81%) | Z1: Total Deductions | AA1: Correction | AB1: Net Salary Payable
A2: AGS26038 | B2: Ainala Saiesha | C2: 46086 | D2: 100000 | E2: 31 | F2: =E2-G2 -> 31 | G2: 0 | H2: =(+D2*49.99999%)/E2*F2 -> 49999.99 | I2: =(H2*50%) -> 24999.995 | J2: =(1600/E2)*F2 -> 1600 | K2: =(L2-H2-I2-J2) -> 19195.015 | L2: =(D2-W2)/E2*F2-Y2 -> 95795 | M2: =IF($H2*0.12>1800,1800,$H2*0.12) -> 1800 | N2: =IF(L2<=21000,L2*0.75%,0) -> 0 | O2: 200 | P2: 0 | R2: 0 | S2: =L2+P2+Q2+R2 -> 95795 | T2: 0 | U2: =ROUND((L2/E2)*G2,0) -> 0 | V2: 180 | W2: =IF($H2*0.12>1800,1800,$H2*0.12) -> 1800 | X2: =IF(L2<=21000,L2*3.25%,0) -> 0 | Y2: 2405 | Z2: =M2+N2+O2+V2+T2+W2+X2+Y2 -> 6385 | AB2: =L2-Z2+AA2+M2+Y2 -> 93615
C6: Total | D6: =SUM(D2:D5) -> 100000 | H6: =SUM(H2:H5) -> 49999.99 | I6: =SUM(I2:I5) -> 24999.995 | J6: =SUM(J2:J5) -> 1600 | K6: =SUM(K2:K5) -> 19195.015 | L6: =SUM(L2:L5) -> 95795 | M6: =SUM(M2:M5) -> 1800 | N6: =SUM(N2:N5) -> 0 | O6: =SUM(O2:O5) -> 200 | ... Z6: =SUM(Z2:Z5) -> 6385 | AB6: =SUM(AB2:AB5) -> 93615

Sheet Consultant
A1: Employee ID | B1: Employee Name | C1: DOJ | D1: CTC | E1: Actuals | F1: TDS | G1: PT | H1: Payable | I1: LOP
A2: AGS26004 | B2: Ande Sharath Chandra | C2: 46055 | D2: 80000 | E2: 80000 | F2: 0 | G2: 200 | H2: =E2-G2 -> 79800
A3: AGS26005 | B3: Tanakala Janardhan | C3: 46055 | D3: 70000 | E3: 70000 | F3: 0 | G3: 200 | H3: =E3-G3 -> 69800
A4: AGS26024 | B4: Priya Darshini Pola | C4: 46072 | D4: 80000 | E4: 80000 | F4: 0 | G4: 200 | H4: =E4-G4 -> 79800
A5: AGS26039 | B5: Esther Deva Priya | C5: 46092 | D5: 20000 | E5: 20000 | F5: 0 | G5: 200 | H5: =E5-G5 -> 19800
A6: AGS26091 | B6: Tepala Rajukumar | C6: 46174 | D6: 10200 | E6: 10200 | F6: 0 | G6: 200 | H6: =E6-G6 -> 10000
A7: AGS26088 | B7: Budhi Vamshi | C7: 46174 | D7: 125000 | E7: 125000 | F7: 0 | G7: 200 | H7: =E7-G7 -> 124800
G8: Total | H8: =SUM(H3:H7) -> 304200

Sheet Tech Team
A1: Employee ID | B1: Employee Name | C1: DOJ | D1: CTC | E1: Calendar Days | F1: Paid Days | G1: LOP day's | H1: Basic | I1: HRA | J1: Special Allowance | K1: Other Allowance | L1: Gross Income | M1: Employee PF (12%) | N1: Employee ESI (0.75%) | O1: Professional Tax | P1: Arrears | Q1: Reimbursements | R1: Bonus/ Incentive | S1: Gross Earnings | T1: TDS | U1: LOP Deduction | V1: Other Deductions | W1: Employer PF (12%) | X1: Employer ESI (3.25%) | Y1: Gratuity (4.81%) | Z1: Total Deductions | AA1: Net Salary Payable
A2: AGS26011 | B2: Siddula Hemasai | C2: 46083 | D2: 45000 | E2: 31 | F2: =E2-G2 -> 31 | G2: 0 | H2: =(+D2*49.99999%)/E2*F2 -> 22499.995 | I2: =(H2*50%) -> 11249.998 | J2: =(1600/E2)*F2 -> 1600 | K2: =(L2-H2-I2-J2) -> 6767.757 | L2: =(D2-W2)/E2*F2-Y2 -> 42117.75 | M2: =IF($H2*0.12>1800,1800,$H2*0.12) -> 1800 | N2: =IF(L2<=21000,L2*0.75%,0) -> 0 | O2: 200 | P2: 0 | Q2: 0 | R2: 0 | S2: =L2+P2+Q2+R2 -> 42117.75 | T2: 0 | U2: =ROUND((L2/E2)*G2,0) -> 0 | V2: 0 | W2: =IF($H2*0.12>1800,1800,$H2*0.12) -> 1800 | X2: =IF(L2<=21000,L2*3.25%,0) -> 0 | Y2: =H2*4.81% -> 1082.2498 | Z2: =M2+N2+O2+V2+T2+W2+X2+Y2 -> 4882.2498 | AA2: =L2-Z2+Y2+W2+X2 -> 40117.75
A3: AGS26018 | B3: Settybathini Sathish | C3: 46083 | D3: 45000 | E3: 31 | F3: =E3-G3 -> 31 | G3: 0 | H3: =(+D3*49.99999%)/E3*F3 -> 22499.995 | I3: =(H3*50%) -> 11249.998 | J3: =(1600/E3)*F3 -> 1600 | K3: =(L3-H3-I3-J3) -> 6767.757 | L3: =(D3-W3)/E3*F3-Y3 -> 42117.75 | M3: =IF($H3*0.12>1800,1800,$H3*0.12) -> 1800 | N3: =IF(L3<=21000,L3*0.75%,0) -> 0 | O3: 200 | P3: 0 | Q3: 0 | R3: 0 | S3: =L3+P3+Q3+R3 -> 42117.75 | T3: 0 | U3: 0 | V3: 0 | W3: =IF($H3*0.12>1800,1800,$H3*0.12) -> 1800 | X3: =IF(L3<=21000,L3*3.25%,0) -> 0 | Y3: =H3*4.81% -> 1082.2498 | Z3: =M3+N3+O3+U3+V3+T3+W3+X3+Y3 -> 4882.2498 | AA3: =L3-Z3+Y3+W3 -> 40117.75
A4: AGS26010 | B4: Vemula Varshith | C4: 46083 | D4: 60000 | E4: 31 | F4: =E4-G4 -> 31 | G4: 0 | H4: =(+D4*49.99999%)/E4*F4 -> 29999.994 | I4: =(H4*50%) -> 14999.997 | J4: =(1600/E4)*F4 -> 1600 | K4: =(L4-H4-I4-J4) -> 10157.009 | L4: =(D4-W4)/E4*F4-Y4 -> 56757 | M4: =IF($H4*0.12>1800,1800,$H4*0.12) -> 1800 | N4: =IF(L4<=21000,L4*0.75%,0) -> 0 | O4: 200 | P4: 0 | Q4: 0 | R4: 0 | S4: =L4+P4+Q4+R4 -> 56757 | T4: 0 | U4: =ROUND((L4/E4)*G4,0) -> 0 | V4: 0 | W4: =IF($H4*0.12>1800,1800,$H4*0.12) -> 1800 | X4: =IF(L4<=21000,L4*3.25%,0) -> 0 | Y4: =H4*4.81% -> 1442.9997 | Z4: =M4+N4+O4+U4+V4+T4+W4+X4+Y4 -> 5242.9997 | AA4: =L4-Z4+Y4+W4 -> 54757
A5: AGS26019 | B5: Nelapatla Srinivas | C5: 46083 | D5: 23000 | E5: 31 | F5: =E5-G5 -> 31 | G5: 0 | H5: =(+D5*49.99999%)/E5*F5 -> 11499.998 | I5: =(H5*50%) -> 5749.9988 | J5: =(1600/E5)*F5 -> 1600 | K5: =(L5-H5-I5-J5) -> 2216.8538 | L5: =(D5-W5)/E5*F5-Y5 -> 21066.85 | M5: =IF($H5*0.12>1800,1800,$H5*0.12) -> 1379.9997 | N5: =IF(L5<=21000,L5*0.75%,0) -> 0 | O5: 200 | P5: 0 | Q5: 0 | R5: 0 | S5: =L5+P5+Q5+R5 -> 21066.85 | T5: 0 | U5: =ROUND((L5/E5)*G5,0) -> 0 | V5: 0 | W5: =IF($H5*0.12>1800,1800,$H5*0.12) -> 1379.9997 | X5: =IF(L5<=21000,L5*3.25%,0) -> 0 | Y5: =H5*4.81% -> 553.14989 | Z5: =M5+N5+O5+U5+V5+T5+W5+X5+Y5 -> 3513.1493 | AA5: =L5-Z5+Y5+W5 -> 19486.851
A6: AGS26014 | B6: Vulli Pavan | C6: 46083 | D6: 50000 | E6: 31 | F6: =E6-G6 -> 31 | G6: 0 | H6: =(+D6*49.99999%)/E6*F6 -> 24999.995 | I6: =(H6*50%) -> 12499.997 | J6: =(1600/E6)*F6 -> 1600 | K6: =(L6-H6-I6-J6) -> 7897.5077 | L6: =(D6-W6)/E6*F6-Y6 -> 46997.5 | M6: =IF($H6*0.12>1800,1800,$H6*0.12) -> 1800 | N6: =IF(L6<=21000,L6*0.75%,0) -> 0 | O6: 200 | P6: 0 | Q6: 0 | R6: 0 | S6: =L6+P6+Q6+R6 -> 46997.5 | T6: 0 | U6: =ROUND((L6/E6)*G6,0) -> 0 | V6: 0 | W6: =IF($H6*0.12>1800,1800,$H6*0.12) -> 1800 | X6: =IF(L6<=21000,L6*3.25%,0) -> 0 | Y6: =H6*4.81% -> 1202.4998 | Z6: =M6+N6+O6+U6+V6+T6+W6+X6+Y6 -> 5002.4998 | AA6: =L6-Z6+Y6+W6 -> 44997.5
A7: AGS26017 | B7: Vavilla Saikumar | C7: 46083 | D7: 45000 | E7: 31 | F7: =E7-G7 -> 31 | G7: 0 | H7: =(+D7*49.99999%)/E7*F7 -> 22499.995 | I7: =(H7*50%) -> 11249.998 | J7: =(1600/E7)*F7 -> 1600 | K7: =(L7-H7-I7-J7) -> 6767.757 | L7: =(D7-W7)/E7*F7-Y7 -> 42117.75 | M7: =IF($H7*0.12>1800,1800,$H7*0.12) -> 1800 | N7: =IF(L7<=21000,L7*0.75%,0) -> 0 | O7: 200 | P7: 0 | Q7: 0 | R7: 0 | S7: =L7+P7+Q7+R7 -> 42117.75 | T7: 0 | U7: =ROUND((L7/E7)*G7,0) -> 0 | V7: 0 | W7: =IF($H7*0.12>1800,1800,$H7*0.12) -> 1800 | X7: =IF(L7<=21000,L7*3.25%,0) -> 0 | Y7: =H7*4.81% -> 1082.2498 | Z7: =M7+N7+O7+U7+V7+T7+W7+X7+Y7 -> 4882.2498 | AA7: =L7-Z7+Y7+W7 -> 40117.75
A8: AGS26016 | B8: Manisha Ashroba Virkar | C8: 46083 | D8: 45000 | E8: 31 | F8: =E8-G8 -> 31 | G8: 0 | H8: =(+D8*49.99999%)/E8*F8 -> 22499.995 | I8: =(H8*50%) -> 11249.998 | J8: =(1600/E8)*F8 -> 1600 | K8: =(L8-H8-I8-J8) -> 6767.757 | L8: =(D8-W8)/E8*F8-Y8 -> 42117.75 | M8: =IF($H8*0.12>1800,1800,$H8*0.12) -> 1800 | N8: =IF(L8<=21000,L8*0.75%,0) -> 0 | O8: 200 | P8: 0 | Q8: 0 | R8: 0 | S8: =L8+P8+Q8+R8 -> 42117.75 | T8: 0 | U8: =ROUND((L8/E8)*G8,0) -> 0 | V8: 0 | W8: =IF($H8*0.12>1800,1800,$H8*0.12) -> 1800 | X8: =IF(L8<=21000,L8*3.25%,0) -> 0 | Y8: =H8*4.81% -> 1082.2498 | Z8: =M8+N8+O8+U8+V8+T8+W8+X8+Y8 -> 4882.2498 | AA8: =L8-Z8+Y8+W8 -> 40117.75
A9: AGS26015 | B9: Karne Narsimha Reddy | C9: 46083 | D9: 45000 | E9: 31 | F9: =E9-G9 -> 31 | G9: 0 | H9: =(+D9*49.99999%)/E9*F9 -> 22499.995 | I9: =(H9*50%) -> 11249.998 | J9: =(1600/E9)*F9 -> 1600 | K9: =(L9-H9-I9-J9) -> 6767.757 | L9: =(D9-W9)/E9*F9-Y9 -> 42117.75 | M9: =IF($H9*0.12>1800,1800,$H9*0.12) -> 1800 | N9: =IF(L9<=21000,L9*0.75%,0) -> 0 | O9: 200 | P9: 0 | Q9: 0 | R9: 0 | S9: =L9+P9+Q9+R9 -> 42117.75 | T9: 0 | U9: =ROUND((L9/E9)*G9,0) -> 0 | V9: 0 | W9: =IF($H9*0.12>1800,1800,$H9*0.12) -> 1800 | X9: =IF(L9<=21000,L9*3.25%,0) -> 0 | Y9: =H9*4.81% -> 1082.2498 | Z9: =M9+N9+O9+V9+T9+W9+X9+Y9 -> 4882.2498 | AA9: =L9-Z9+Y9+W9 -> 40117.75
A10: AGS26013 | B10: Kalepu Vijay | C10: 46083 | D10: 45000 | E10: 31 | F10: =E10-G10 -> 31 | G10: 0 | H10: =(+D10*49.99999%)/E10*F10 -> 22499.995 | I10: =(H10*50%) -> 11249.998 | J10: =(1600/E10)*F10 -> 1600 | K10: =(L10-H10-I10-J10) -> 6767.757 | L10: =(D10-W10)/E10*F10-Y10 -> 42117.75 | M10: =IF($H10*0.12>1800,1800,$H10*0.12) -> 1800 | N10: =IF(L10<=21000,L10*0.75%,0) -> 0 | O10: 200 | P10: 0 | Q10: 0 | R10: 0 | S10: =L10+P10+Q10+R10 -> 42117.75 | T10: 0 | U10: =ROUND((L10/E10)*G10,0) -> 0 | V10: 0 | W10: =IF($H10*0.12>1800,1800,$H10*0.12) -> 1800 | X10: =IF(L10<=21000,L10*3.25%,0) -> 0 | Y10: =H10*4.81% -> 1082.2498 | Z10: =M10+N10+O10+U10+V10+T10+W10+X10+Y10 -> 4882.2498 | AA10: =L10-Z10+Y10+W10 -> 40117.75
A11: AGS26021 | B11: Kontham Sushma | C11: 46083 | D11: 50000 | E11: 31 | F11: =E11-G11 -> 31 | G11: 0 | H11: =(+D11*49.99999%)/E11*F11 -> 24999.995 | I11: =(H11*50%) -> 12499.997 | J11: =(1600/E11)*F11 -> 1600 | K11: =(L11-H11-I11-J11) -> 7897.5077 | L11: =(D11-W11)/E11*F11-Y11 -> 46997.5 | M11: =IF($H11*0.12>1800,1800,$H11*0.12) -> 1800 | N11: =IF(L11<=21000,L11*0.75%,0) -> 0 | O11: 200 | P11: 0 | Q11: 0 | R11: 0 | S11: =L11+P11+Q11+R11 -> 46997.5 | T11: 0 | U11: =ROUND((L11/E11)*G11,0) -> 0 | V11: 0 | W11: =IF($H11*0.12>1800,1800,$H11*0.12) -> 1800 | X11: =IF(L11<=21000,L11*3.25%,0) -> 0 | Y11: =H11*4.81% -> 1202.4998 | Z11: =M11+N11+O11+U11+V11+T11+W11+X11+Y11 -> 5002.4998 | AA11: =L11-Z11+Y11+W11 -> 44997.5
A12: AGS26023 | B12: Bobbarala Varshini | C12: 46083 | D12: 60000 | E12: 31 | F12: =E12-G12 -> 31 | G12: 0 | H12: =(+D12*49.99999%)/E12*F12 -> 29999.994 | I12: =(H12*50%) -> 14999.997 | J12: =(1600/E12)*F12 -> 1600 | K12: =(L12-H12-I12-J12) -> 10157.009 | L12: =(D12-W12)/E12*F12-Y12 -> 56757 | M12: =IF($H12*0.12>1800,1800,$H12*0.12) -> 1800 | N12: =IF(L12<=21000,L12*0.75%,0) -> 0 | O12: 200 | P12: 0 | Q12: 0 | R12: 0 | S12: =L12+P12+Q12+R12 -> 56757 | T12: 0 | U12: 0 | V12: 0 | W12: =IF($H12*0.12>1800,1800,$H12*0.12) -> 1800 | X12: =IF(L12<=21000,L12*3.25%,0) -> 0 | Y12: =H12*4.81% -> 1442.9997 | Z12: =M12+N12+O12+U12+V12+T12+W12+X12+Y12 -> 5242.9997 | AA12: =L12-Z12+Y12+W12 -> 54757
A13: AGS26026 | B13: Surampudi Roop Sai | C13: 46083 | D13: 60000 | E13: 31 | F13: =E13-G13 -> 31 | G13: 0 | H13: =(+D13*49.99999%)/E13*F13 -> 29999.994 | I13: =(H13*50%) -> 14999.997 | J13: =(1600/E13)*F13 -> 1600 | K13: =(L13-H13-I13-J13) -> 10157.009 | L13: =(D13-W13)/E13*F13-Y13 -> 56757 | M13: =IF($H13*0.12>1800,1800,$H13*0.12) -> 1800 | N13: =IF(L13<=21000,L13*0.75%,0) -> 0 | O13: 200 | P13: 0 | Q13: 0 | R13: 0 | S13: =L13+P13+Q13+R13 -> 56757 | T13: 0 | U13: =ROUND((L13/E13)*G13,0) -> 0 | V13: 0 | W13: =IF($H13*0.12>1800,1800,$H13*0.12) -> 1800 | X13: =IF(L13<=21000,L13*3.25%,0) -> 0 | Y13: =H13*4.81% -> 1442.9997 | Z13: =M13+N13+O13+U13+V13+T13+W13+X13+Y13 -> 5242.9997 | AA13: =L13-Z13+Y13+W13 -> 54757
A14: AGS26028 | B14: Mohammed Abdul Moid | C14: 46083 | D14: 15000 | E14: 31 | F14: =E14-G14 -> 31 | G14: 0 | H14: =(+D14*49.99999%)/E14*F14 -> 7499.9985 | I14: =(H14*50%) -> 3749.9992 | J14: =(1600/E14)*F14 -> 1600 | K14: =(L14-H14-I14-J14) -> 889.2525 | L14: =(D14-W14)/E14*F14-Y14 -> 13739.25 | M14: =IF($H14*0.12>1800,1800,$H14*0.12) -> 899.99982 | N14: 0 | O14: 200 | P14: 0 | Q14: 0 | R14: 0 | S14: =L14+P14+Q14+R14 -> 13739.25 | T14: 0 | U14: =ROUND((L14/E14)*G14,0) -> 0 | V14: 0 | W14: =IF($H14*0.12>1800,1800,$H14*0.12) -> 899.99982 | X14: 0 | Y14: =H14*4.81% -> 360.74993 | Z14: =M14+N14+O14+U14+V14+T14+W14+X14+Y14 -> 2360.7496 | AA14: =L14-Z14+Y14+W14 -> 12639.25
A15: AGS26029 | B15: Mula Sai Preetham Goud | C15: 46083 | D15: 35000 | E15: 31 | F15: =E15-G15 -> 31 | G15: 0 | H15: =(+D15*49.99999%)/E15*F15 -> 17499.996 | I15: =(H15*50%) -> 8749.9982 | J15: =(1600/E15)*F15 -> 1600 | K15: =(L15-H15-I15-J15) -> 4508.2554 | L15: =(D15-W15)/E15*F15-Y15 -> 32358.25 | M15: =IF($H15*0.12>1800,1800,$H15*0.12) -> 1800 | N15: =IF(L15<=21000,L15*0.75%,0) -> 0 | O15: 200 | P15: 0 | Q15: 0 | R15: 0 | S15: =L15+P15+Q15+R15 -> 32358.25 | T15: 0 | U15: =ROUND((L15/E15)*G15,0) -> 0 | V15: 0 | W15: =IF($H15*0.12>1800,1800,$H15*0.12) -> 1800 | X15: =IF(L15<=21000,L15*3.25%,0) -> 0 | Y15: =H15*4.81% -> 841.74983 | Z15: =M15+N15+O15+U15+V15+T15+W15+X15+Y15 -> 4641.7498 | AA15: =L15-Z15+Y15+W15 -> 30358.25
A16: AGS26030 | B16: Sruthin Kumar Basa | C16: 46083 | D16: 35000 | E16: 31 | F16: =E16-G16 -> 31 | G16: 0 | H16: =(+D16*49.99999%)/E16*F16 -> 17499.996 | I16: =(H16*50%) -> 8749.9982 | J16: =(1600/E16)*F16 -> 1600 | K16: =(L16-H16-I16-J16) -> 4508.2554 | L16: =(D16-W16)/E16*F16-Y16 -> 32358.25 | M16: =IF($H16*0.12>1800,1800,$H16*0.12) -> 1800 | N16: =IF(L16<=21000,L16*0.75%,0) -> 0 | O16: 200 | P16: 0 | Q16: 0 | R16: 0 | S16: =L16+P16+Q16+R16 -> 32358.25 | T16: 0 | U16: =ROUND((L16/E16)*G16,0) -> 0 | V16: 0 | W16: =IF($H16*0.12>1800,1800,$H16*0.12) -> 1800 | X16: =IF(L16<=21000,L16*3.25%,0) -> 0 | Y16: =H16*4.81% -> 841.74983 | Z16: =M16+N16+O16+U16+V16+T16+W16+X16+Y16 -> 4641.7498 | AA16: =L16-Z16+Y16+W16 -> 30358.25
A17: AGS26032 | B17: Vempadapu Uday Sai Tarun | C17: 46083 | D17: 23000 | E17: 31 | F17: =E17-G17 -> 31 | G17: 0 | H17: =(+D17*49.99999%)/E17*F17 -> 11499.998 | I17: =(H17*50%) -> 5749.9988 | J17: =(1600/E17)*F17 -> 1600 | K17: =(L17-H17-I17-J17) -> 2216.8538 | L17: =(D17-W17)/E17*F17-Y17 -> 21066.85 | M17: =IF($H17*0.12>1800,1800,$H17*0.12) -> 1379.9997 | N17: =IF(L17<=21000,L17*0.75%,0) -> 0 | O17: 200 | P17: 0 | Q17: 0 | R17: 0 | S17: =L17+P17+Q17+R17 -> 21066.85 | T17: 0 | U17: 0 | V17: 0 | W17: =IF($H17*0.12>1800,1800,$H17*0.12) -> 1379.9997 | X17: =IF(L17<=21000,L17*3.25%,0) -> 0 | Y17: =H17*4.81% -> 553.14989 | Z17: =M17+N17+O17+U17+V17+T17+W17+X17+Y17 -> 3513.1493 | AA17: =L17-Z17+Y17+W17 -> 19486.851
A18: AGS26034 | B18: Sripada Shivakumar | C18: 46083 | D18: 60000 | E18: 31 | F18: =E18-G18 -> 30 | G18: 1 | H18: =(+D18*49.99999%)/E18*F18 -> 29032.252 | I18: =(H18*50%) -> 14516.126 | J18: =(1600/E18)*F18 -> 1548.3871 | K18: =(L18-H18-I18-J18) -> 9829.3638 | L18: =(D18-W18)/E18*F18-Y18 -> 54926.129 | M18: =IF($H18*0.12>1800,1800,$H18*0.12) -> 1800 | N18: =IF(L18<=21000,L18*0.75%,0) -> 0 | O18: 200 | P18: 0 | Q18: 0 | R18: 0 | S18: =L18+P18+Q18+R18 -> 54926.129 | T18: 0 | U18: 0 | V18: 0 | W18: =IF($H18*0.12>1800,1800,$H18*0.12) -> 1800 | X18: =IF(L18<=21000,L18*3.25%,0) -> 0 | Y18: =H18*4.81% -> 1396.4513 | Z18: =M18+N18+O18+U18+V18+T18+W18+X18+Y18 -> 5196.4513 | AA18: =L18-Z18+Y18+W18 -> 52926.129
A19: AGS26035 | B19: Varakantham Surender Reddy | C19: 46083 | D19: 60000 | E19: 31 | F19: =E19-G19 -> 31 | G19: 0 | H19: =(+D19*49.99999%)/E19*F19 -> 29999.994 | I19: =(H19*50%) -> 14999.997 | J19: =(1600/E19)*F19 -> 1600 | K19: =(L19-H19-I19-J19) -> 10157.009 | L19: =(D19-W19)/E19*F19-Y19 -> 56757 | M19: =IF($H19*0.12>1800,1800,$H19*0.12) -> 1800 | N19: =IF(L19<=21000,L19*0.75%,0) -> 0 | O19: 200 | P19: 0 | Q19: 0 | R19: 0 | S19: =L19+P19+Q19+R19 -> 56757 | T19: 0 | U19: 0 | V19: 0 | W19: =IF($H19*0.12>1800,1800,$H19*0.12) -> 1800 | X19: =IF(L19<=21000,L19*3.25%,0) -> 0 | Y19: =H19*4.81% -> 1442.9997 | Z19: =M19+N19+O19+U19+V19+T19+W19+X19+Y19 -> 5242.9997 | AA19: =L19-Z19+Y19+W19 -> 54757
A20: AGS26041 | B20: Sudhagani Sai Charan | C20: 46113 | D20: 35000 | E20: 31 | F20: =E20-G20 -> 31 | G20: 0 | H20: =(+D20*49.99999%)/E20*F20 -> 17499.996 | I20: =(H20*50%) -> 8749.9982 | J20: =(1600/E20)*F20 -> 1600 | K20: =(L20-H20-I20-J20) -> 4508.2554 | L20: =(D20-W20)/E20*F20-Y20 -> 32358.25 | M20: =IF($H20*0.12>1800,1800,$H20*0.12) -> 1800 | N20: =IF(L20<=21000,L20*0.75%,0) -> 0 | O20: 200 | P20: 0 | Q20: 0 | R20: 0 | S20: =L20+P20+Q20+R20 -> 32358.25 | T20: 0 | U20: 0 | V20: 0 | W20: =IF($H20*0.12>1800,1800,$H20*0.12) -> 1800 | X20: =IF(L20<=21000,L20*3.25%,0) -> 0 | Y20: =H20*4.81% -> 841.74983 | Z20: =M20+N20+O20+U20+V20+T20+W20+X20+Y20 -> 4641.7498 | AA20: =L20-Z20+Y20+W20 -> 30358.25
A21: AGS26043 | B21: Chebrolu Yashaswini | C21: 46113 | D21: 30000 | E21: 31 | F21: =E21-G21 -> 31 | G21: 0 | H21: =(+D21*49.99999%)/E21*F21 -> 14999.997 | I21: =(H21*50%) -> 7499.9985 | J21: =(1600/E21)*F21 -> 1600 | K21: =(L21-H21-I21-J21) -> 3378.505 | L21: =(D21-W21)/E21*F21-Y21 -> 27478.501 | M21: =IF($H21*0.12>1800,1800,$H21*0.12) -> 1799.9996 | N21: =IF(L21<=21000,L21*0.75%,0) -> 0 | O21: 200 | P21: 0 | Q21: 0 | R21: 0 | S21: =L21+P21+Q21+R21 -> 27478.501 | T21: 0 | U21: 0 | V21: 0 | W21: =IF($H21*0.12>1800,1800,$H21*0.12) -> 1799.9996 | X21: =IF(L21<=21000,L21*3.25%,0) -> 0 | Y21: =H21*4.81% -> 721.49986 | Z21: =M21+N21+O21+U21+V21+T21+W21+X21+Y21 -> 4521.4991 | AA21: =L21-Z21+Y21+W21 -> 25478.501
A22: AGS26045 | B22: Chebrolu Monika | C22: 46113 | D22: 50000 | E22: 31 | F22: =E22-G22 -> 31 | G22: 0 | H22: =(+D22*49.99999%)/E22*F22 -> 24999.995 | I22: =(H22*50%) -> 12499.997 | J22: =(1600/E22)*F22 -> 1600 | K22: =(L22-H22-I22-J22) -> 7897.5077 | L22: =(D22-W22)/E22*F22-Y22 -> 46997.5 | M22: =IF($H22*0.12>1800,1800,$H22*0.12) -> 1800 | N22: =IF(L22<=21000,L22*0.75%,0) -> 0 | O22: 200 | P22: 0 | Q22: 0 | R22: 0 | S22: =L22+P22+Q22+R22 -> 46997.5 | T22: 0 | U22: 0 | V22: 0 | W22: =IF($H22*0.12>1800,1800,$H22*0.12) -> 1800 | X22: =IF(L22<=21000,L22*3.25%,0) -> 0 | Y22: =H22*4.81% -> 1202.4998 | Z22: =M22+N22+O22+U22+V22+T22+W22+X22+Y22 -> 5002.4998 | AA22: =L22-Z22+Y22+W22 -> 44997.5
A23: AGS26047 | B23: Upadhyayula Naga Lakshmi Deepthi | C23: 46114 | D23: 23000 | E23: 31 | F23: =E23-G23 -> 31 | G23: 0 | H23: =(+D23*49.99999%)/E23*F23 -> 11499.998 | I23: =(H23*50%) -> 5749.9988 | J23: =(1600/E23)*F23 -> 1600 | K23: =(L23-H23-I23-J23) -> 2216.8538 | L23: =(D23-W23)/E23*F23-Y23 -> 21066.85 | M23: =IF($H23*0.12>1800,1800,$H23*0.12) -> 1379.9997 | N23: 0 | O23: 200 | P23: 0 | Q23: 0 | R23: 0 | S23: =L23+P23+Q23+R23 -> 21066.85 | T23: 0 | U23: 0 | V23: 0 | W23: =IF($H23*0.12>1800,1800,$H23*0.12) -> 1379.9997 | X23: 0 | Y23: =H23*4.81% -> 553.14989 | Z23: =M23+N23+O23+U23+V23+T23+W23+X23+Y23 -> 3513.1493 | AA23: =L23-Z23+Y23+W23 -> 19486.851
A24: AGS26048 | B24: Rapolu Rekha | C24: 46113 | D24: 15000 | E24: 31 | F24: =E24-G24 -> 31 | G24: 0 | H24: =(+D24*49.99999%)/E24*F24 -> 7499.9985 | I24: =(H24*50%) -> 3749.9992 | J24: =(1600/E24)*F24 -> 1600 | K24: =(L24-H24-I24-J24) -> 889.2525 | L24: =(D24-W24)/E24*F24-Y24 -> 13739.25 | M24: =IF($H24*0.12>1800,1800,$H24*0.12) -> 899.99982 | N24: 0 | O24: 150 | P24: 0 | Q24: 0 | R24: 0 | S24: =L24+P24+Q24+R24 -> 13739.25 | T24: 0 | U24: 0 | V24: 0 | W24: =IF($H24*0.12>1800,1800,$H24*0.12) -> 899.99982 | X24: 0 | Y24: =H24*4.81% -> 360.74993 | Z24: =M24+N24+O24+U24+V24+T24+W24+X24+Y24 -> 2310.7496 | AA24: =L24-Z24+Y24+W24 -> 12689.25
A25: AGS26049 | B25: Ragiru Nikhitha | C25: 46113 | D25: 15000 | E25: 31 | F25: =E25-G25 -> 31 | G25: 0 | H25: =(+D25*49.99999%)/E25*F25 -> 7499.9985 | I25: =(H25*50%) -> 3749.9992 | J25: =(1600/E25)*F25 -> 1600 | K25: =(L25-H25-I25-J25) -> 889.2525 | L25: =(D25-W25)/E25*F25-Y25 -> 13739.25 | M25: =IF($H25*0.12>1800,1800,$H25*0.12) -> 899.99982 | N25: 0 | O25: 150 | P25: 0 | Q25: 0 | R25: 0 | S25: =L25+P25+Q25+R25 -> 13739.25 | T25: 0 | U25: 0 | V25: 0 | W25: =IF($H25*0.12>1800,1800,$H25*0.12) -> 899.99982 | X25: 0 | Y25: =H25*4.81% -> 360.74993 | Z25: =M25+N25+O25+U25+V25+T25+W25+X25+Y25 -> 2310.7496 | AA25: =L25-Z25+Y25+W25 -> 12689.25
A26: AGS26051 | B26: Mundlamuri Mrudula | C26: 46113 | D26: 15000 | E26: 31 | F26: =E26-G26 -> 31 | G26: 0 | H26: =(+D26*49.99999%)/E26*F26 -> 7499.9985 | I26: =(H26*50%) -> 3749.9992 | J26: =(1600/E26)*F26 -> 1600 | K26: =(L26-H26-I26-J26) -> 889.2525 | L26: =(D26-W26)/E26*F26-Y26 -> 13739.25 | M26: =IF($H26*0.12>1800,1800,$H26*0.12) -> 899.99982 | N26: 0 | O26: 150 | P26: 0 | Q26: 0 | R26: 0 | S26: =L26+P26+Q26+R26 -> 13739.25 | T26: 0 | U26: 0 | V26: 0 | W26: =IF($H26*0.12>1800,1800,$H26*0.12) -> 899.99982 | X26: 0 | Y26: =H26*4.81% -> 360.74993 | Z26: =M26+N26+O26+U26+V26+T26+W26+X26+Y26 -> 2310.7496 | AA26: =L26-Z26+Y26+W26 -> 12689.25
A27: AGS26053 | B27: Palavelli Praveen Reddy | C27: 46113 | D27: 15000 | E27: 31 | F27: =E27-G27 -> 31 | G27: 0 | H27: =(+D27*49.99999%)/E27*F27 -> 7499.9985 | I27: =(H27*50%) -> 3749.9992 | J27: =(1600/E27)*F27 -> 1600 | K27: =(L27-H27-I27-J27) -> 889.2525 | L27: =(D27-W27)/E27*F27-Y27 -> 13739.25 | M27: =IF($H27*0.12>1800,1800,$H27*0.12) -> 899.99982 | N27: 0 | O27: 150 | P27: 0 | Q27: 0 | R27: 0 | S27: =L27+P27+Q27+R27 -> 13739.25 | T27: 0 | U27: 0 | V27: 0 | W27: =IF($H27*0.12>1800,1800,$H27*0.12) -> 899.99982 | X27: 0 | Y27: =H27*4.81% -> 360.74993 | Z27: =M27+N27+O27+U27+V27+T27+W27+X27+Y27 -> 2310.7496 | AA27: =L27-Z27+Y27+W27 -> 12689.25
A28: AGS26054 | B28: Yaramothu Himaja | C28: 46113 | D28: 15000 | E28: 31 | F28: =E28-G28 -> 31 | G28: 0 | H28: =(+D28*49.99999%)/E28*F28 -> 7499.9985 | I28: =(H28*50%) -> 3749.9992 | J28: =(1600/E28)*F28 -> 1600 | K28: =(L28-H28-I28-J28) -> 889.2525 | L28: =(D28-W28)/E28*F28-Y28 -> 13739.25 | M28: =IF($H28*0.12>1800,1800,$H28*0.12) -> 899.99982 | N28: 0 | O28: 150 | P28: 0 | Q28: 0 | R28: 0 | S28: =L28+P28+Q28+R28 -> 13739.25 | T28: 0 | U28: 0 | V28: 0 | W28: =IF($H28*0.12>1800,1800,$H28*0.12) -> 899.99982 | X28: 0 | Y28: =H28*4.81% -> 360.74993 | Z28: =M28+N28+O28+U28+V28+T28+W28+X28+Y28 -> 2310.7496 | AA28: =L28-Z28+Y28+W28 -> 12689.25
A29: AGS26031 | B29: Y Raghavendar | C29: 46113 | D29: 45000 | E29: 31 | F29: =E29-G29 -> 31 | G29: 0 | H29: =(+D29*49.99999%)/E29*F29 -> 22499.995 | I29: =(H29*50%) -> 11249.998 | J29: =(1600/E29)*F29 -> 1600 | K29: =(L29-H29-I29-J29) -> 6767.757 | L29: =(D29-W29)/E29*F29-Y29 -> 42117.75 | M29: =IF($H29*0.12>1800,1800,$H29*0.12) -> 1800 | N29: 0 | O29: 200 | P29: 0 | Q29: 0 | R29: 0 | S29: =L29+P29+Q29+R29 -> 42117.75 | T29: 0 | U29: 0 | V29: 0 | W29: =IF($H29*0.12>1800,1800,$H29*0.12) -> 1800 | X29: 0 | Y29: =H29*4.81% -> 1082.2498 | Z29: =M29+N29+O29+U29+V29+T29+W29+X29+Y29 -> 4882.2498 | AA29: =L29-Z29+Y29+W29 -> 40117.75
A30: AGS26056 | B30: Bommala Naveen Kumar | C30: 46113 | D30: 45000 | E30: 31 | F30: =E30-G30 -> 31 | G30: 0 | H30: =(+D30*49.99999%)/E30*F30 -> 22499.995 | I30: =(H30*50%) -> 11249.998 | J30: =(1600/E30)*F30 -> 1600 | K30: =(L30-H30-I30-J30) -> 6767.757 | L30: =(D30-W30)/E30*F30-Y30 -> 42117.75 | M30: =IF($H30*0.12>1800,1800,$H30*0.12) -> 1800 | N30: 0 | O30: 200 | P30: 0 | Q30: 0 | R30: 0 | S30: =L30+P30+Q30+R30 -> 42117.75 | T30: 0 | U30: 0 | V30: 0 | W30: =IF($H30*0.12>1800,1800,$H30*0.12) -> 1800 | X30: 0 | Y30: =H30*4.81% -> 1082.2498 | Z30: =M30+N30+O30+U30+V30+T30+W30+X30+Y30 -> 4882.2498 | AA30: =L30-Z30+Y30+W30 -> 40117.75
A31: AGS26057 | B31: Odeti Srinivas | C31: 46113 | D31: 30000 | E31: 31 | F31: =E31-G31 -> 31 | G31: 0 | H31: =(+D31*49.99999%)/E31*F31 -> 14999.997 | I31: =(H31*50%) -> 7499.9985 | J31: =(1600/E31)*F31 -> 1600 | K31: =(L31-H31-I31-J31) -> 3378.505 | L31: =(D31-W31)/E31*F31-Y31 -> 27478.501 | M31: =IF($H31*0.12>1800,1800,$H31*0.12) -> 1799.9996 | N31: 0 | O31: 200 | P31: 0 | Q31: 0 | R31: 0 | S31: =L31+P31+Q31+R31 -> 27478.501 | T31: 0 | U31: 0 | V31: 0 | W31: =IF($H31*0.12>1800,1800,$H31*0.12) -> 1799.9996 | X31: 0 | Y31: =H31*4.81% -> 721.49986 | Z31: =M31+N31+O31+U31+V31+T31+W31+X31+Y31 -> 4521.4991 | AA31: =L31-Z31+Y31+W31 -> 25478.501
A32: AGS26058 | B32: Matha Sai Prasad | C32: 46113 | D32: 15000 | E32: 31 | F32: =E32-G32 -> 31 | G32: 0 | H32: =(+D32*49.99999%)/E32*F32 -> 7499.9985 | I32: =(H32*50%) -> 3749.9992 | J32: =(1600/E32)*F32 -> 1600 | K32: =(L32-H32-I32-J32) -> 889.2525 | L32: =(D32-W32)/E32*F32-Y32 -> 13739.25 | M32: =IF($H32*0.12>1800,1800,$H32*0.12) -> 899.99982 | N32: 0 | O32: 150 | P32: 0 | Q32: 0 | R32: 0 | S32: =L32+P32+Q32+R32 -> 13739.25 | T32: 0 | U32: 0 | V32: 0 | W32: =IF($H32*0.12>1800,1800,$H32*0.12) -> 899.99982 | X32: 0 | Y32: =H32*4.81% -> 360.74993 | Z32: =M32+N32+O32+U32+V32+T32+W32+X32+Y32 -> 2310.7496 | AA32: =L32-Z32+Y32+W32 -> 12689.25
A33: AGS26059 | B33: Chamakuri Raghuram | C33: 46113 | D33: 15000 | E33: 31 | F33: =E33-G33 -> 31 | G33: 0 | H33: =(+D33*49.99999%)/E33*F33 -> 7499.9985 | I33: =(H33*50%) -> 3749.9992 | J33: =(1600/E33)*F33 -> 1600 | K33: =(L33-H33-I33-J33) -> 889.2525 | L33: =(D33-W33)/E33*F33-Y33 -> 13739.25 | M33: =IF($H33*0.12>1800,1800,$H33*0.12) -> 899.99982 | N33: 0 | O33: 150 | P33: 0 | Q33: 0 | R33: 0 | S33: =L33+P33+Q33+R33 -> 13739.25 | T33: 0 | U33: 0 | V33: 0 | W33: =IF($H33*0.12>1800,1800,$H33*0.12) -> 899.99982 | X33: 0 | Y33: =H33*4.81% -> 360.74993 | Z33: =M33+N33+O33+U33+V33+T33+W33+X33+Y33 -> 2310.7496 | AA33: =L33-Z33+Y33+W33 -> 12689.25
A34: AGS26025 | B34: Tumula Dinesh Kumar | C34: 46113 | D34: 23000 | E34: 31 | F34: =E34-G34 -> 31 | G34: 0 | H34: =(+D34*49.99999%)/E34*F34 -> 11499.998 | I34: =(H34*50%) -> 5749.9988 | J34: =(1600/E34)*F34 -> 1600 | K34: =(L34-H34-I34-J34) -> 2216.8538 | L34: =(D34-W34)/E34*F34-Y34 -> 21066.85 | M34: =IF($H34*0.12>1800,1800,$H34*0.12) -> 1379.9997 | N34: =IF(L34<=21000,L34*0.75%,0) -> 0 | O34: 200 | P34: 0 | Q34: 0 | R34: 0 | S34: =L34+P34+Q34+R34 -> 21066.85 | T34: 0 | U34: 0 | V34: 0 | W34: =IF($H34*0.12>1800,1800,$H34*0.12) -> 1379.9997 | X34: =IF(L34<=21000,L34*3.25%,0) -> 0 | Y34: =H34*4.81% -> 553.14989 | Z34: =M34+N34+O34+U34+V34+T34+W34+X34+Y34 -> 3513.1493 | AA34: =L34-Z34+Y34+W34 -> 19486.851
A35: AGS26060 | B35: Thallada Venkatasagar | C35: 46114 | D35: 24000 | E35: 31 | F35: =E35-G35 -> 31 | G35: 0 | H35: =(+D35*49.99999%)/E35*F35 -> 11999.998 | I35: =(H35*50%) -> 5999.9988 | J35: =(1600/E35)*F35 -> 1600 | K35: =(L35-H35-I35-J35) -> 2382.804 | L35: =(D35-W35)/E35*F35-Y35 -> 21982.8 | M35: =IF($H35*0.12>1800,1800,$H35*0.12) -> 1439.9997 | N35: =IF(L35<=21000,L35*0.75%,0) -> 0 | O35: 200 | P35: 0 | Q35: 0 | R35: 0 | S35: =L35+P35+Q35+R35 -> 21982.8 | T35: 0 | U35: 0 | V35: 0 | W35: =IF($H35*0.12>1800,1800,$H35*0.12) -> 1439.9997 | X35: =IF(L35<=21000,L35*3.25%,0) -> 0 | Y35: =H35*4.81% -> 577.19988 | Z35: =M35+N35+O35+U35+V35+T35+W35+X35+Y35 -> 3657.1993 | AA35: =L35-Z35+Y35+W35 -> 20342.801
A36: AGS26044 | B36: Naveen Pulikonda | C36: 46113 | D36: 35000 | E36: 31 | F36: =E36-G36 -> 31 | G36: 0 | H36: =(+D36*49.99999%)/E36*F36 -> 17499.996 | I36: =(H36*50%) -> 8749.9982 | J36: =(1600/E36)*F36 -> 1600 | K36: =(L36-H36-I36-J36) -> 4508.2554 | L36: =(D36-W36)/E36*F36-Y36 -> 32358.25 | M36: =IF($H36*0.12>1800,1800,$H36*0.12) -> 1800 | N36: =IF(L36<=21000,L36*0.75%,0) -> 0 | O36: 200 | P36: 0 | Q36: 0 | R36: 0 | S36: =L36+P36+Q36+R36 -> 32358.25 | T36: 0 | U36: 0 | V36: 0 | W36: =IF($H36*0.12>1800,1800,$H36*0.12) -> 1800 | X36: =IF(L36<=21000,L36*3.25%,0) -> 0 | Y36: =H36*4.81% -> 841.74983 | Z36: =M36+N36+O36+U36+V36+T36+W36+X36+Y36 -> 4641.7498 | AA36: =L36-Z36+Y36+W36 -> 30358.25
A37: AGS26075 | B37: KONDAPALLY AKHIL | C37: 46113 | D37: 100000 | E37: 31 | F37: =E37-G37 -> 31 | G37: 0 | H37: =(+D37*49.99999%)/E37*F37 -> 49999.99 | I37: =(H37*50%) -> 24999.995 | J37: =(1600/E37)*F37 -> 1600 | K37: =(L37-H37-I37-J37) -> 19195.015 | L37: =(D37-W37)/E37*F37-Y37 -> 95795 | M37: =IF($H37*0.12>1800,1800,$H37*0.12) -> 1800 | N37: =IF(L37<=21000,L37*0.75%,0) -> 0 | O37: 200 | P37: 0 | Q37: 0 | R37: 0 | S37: =L37+P37+Q37+R37 -> 95795 | T37: 0 | U37: 0 | V37: 0 | W37: =IF($H37*0.12>1800,1800,$H37*0.12) -> 1800 | X37: =IF(L37<=21000,L37*3.25%,0) -> 0 | Y37: =H37*4.81% -> 2404.9995 | Z37: =M37+N37+O37+U37+V37+T37+W37+X37+Y37 -> 6204.9995 | AA37: =L37-Z37+Y37+W37 -> 93795
A38: AGS26074 | B38: Manikonda Nagasurya Koundinya | C38: 46113 | D38: 33333 | E38: 31 | F38: =E38-G38 -> 31 | G38: 0 | H38: =(+D38*49.99999%)/E38*F38 -> 16666.497 | I38: =(H38*50%) -> 8333.2483 | J38: =(1600/E38)*F38 -> 1600 | K38: =(L38-H38-I38-J38) -> 4131.5965 | L38: =(D38-W38)/E38*F38-Y38 -> 30731.342 | M38: =IF($H38*0.12>1800,1800,$H38*0.12) -> 1800 | N38: =IF(L38<=21000,L38*0.75%,0) -> 0 | O38: 200 | P38: 0 | Q38: 0 | R38: 0 | S38: =L38+P38+Q38+R38 -> 30731.342 | T38: 0 | U38: 0 | V38: 0 | W38: =IF($H38*0.12>1800,1800,$H38*0.12) -> 1800 | X38: =IF(L38<=21000,L38*3.25%,0) -> 0 | Y38: =H38*4.81% -> 801.65849 | Z38: =M38+N38+O38+U38+V38+T38+W38+X38+Y38 -> 4601.6585 | AA38: =L38-Z38+Y38+W38 -> 28731.342
A39: AGS26061 | B39: Indla Kiran Kumar | C39: 46146 | D39: 35000 | E39: 31 | F39: =E39-G39 -> 31 | G39: 0 | H39: =(+D39*49.99999%)/E39*F39 -> 17499.996 | I39: =(H39*50%) -> 8749.9982 | J39: =(1600/E39)*F39 -> 1600 | K39: =(L39-H39-I39-J39) -> 4508.2554 | L39: =(D39-W39)/E39*F39-Y39 -> 32358.25 | M39: =IF($H39*0.12>1800,1800,$H39*0.12) -> 1800 | N39: =IF(L39<=21000,L39*0.75%,0) -> 0 | O39: 200 | P39: 0 | Q39: 0 | R39: 0 | S39: =L39+P39+Q39+R39 -> 32358.25 | T39: 0 | U39: 0 | V39: 0 | W39: =IF($H39*0.12>1800,1800,$H39*0.12) -> 1800 | X39: =IF(L39<=21000,L39*3.25%,0) -> 0 | Y39: =H39*4.81% -> 841.74983 | Z39: =M39+N39+O39+U39+V39+T39+W39+X39+Y39 -> 4641.7498 | AA39: =L39-Z39+Y39+W39 -> 30358.25
A40: AGS26062 | B40: K Tharun Kumar Reddy | C40: 46146 | D40: 15000 | E40: 31 | F40: =E40-G40 -> 31 | G40: 0 | H40: =(+D40*49.99999%)/E40*F40 -> 7499.9985 | I40: =(H40*50%) -> 3749.9992 | J40: =(1600/E40)*F40 -> 1600 | K40: =(L40-H40-I40-J40) -> 889.2525 | L40: =(D40-W40)/E40*F40-Y40 -> 13739.25 | M40: =IF($H40*0.12>1800,1800,$H40*0.12) -> 899.99982 | N40: 0 | O40: 150 | P40: 0 | Q40: 0 | R40: 0 | S40: =L40+P40+Q40+R40 -> 13739.25 | T40: 0 | U40: 0 | V40: 0 | W40: =IF($H40*0.12>1800,1800,$H40*0.12) -> 899.99982 | X40: 0 | Y40: =H40*4.81% -> 360.74993 | Z40: =M40+N40+O40+U40+V40+T40+W40+X40+Y40 -> 2310.7496 | AA40: =L40-Z40+Y40+W40+X40 -> 12689.25
...

Sheet HIT
A1: Employee ID | B1: Employee Name | C1: DOJ | D1: CTC | E1: Calendar Days | F1: Paid Days | G1: LOP day's | H1: Basic | I1: HRA | J1: Special Allowance | K1: Other Allowance | L1: Gross Income | M1: Employee PF (12%) | N1: Employee ESI (0.75%) | O1: Professional Tax | P1: Arrears | Q1: Reimbursements | R1: Bonus/ Incentive | S1: Gross Earnings | T1: TDS | U1: LOP Deduction | V1: Other Deductions | W1: Employer PF (12%) | X1: Employer ESI (3.25%) | Y1: Gratuity (4.81%) | Z1: Total Deductions | AA1: Net Salary Payable
A2: AGS26077 | B2: Batta Jyotsna | C2: 46174 | D2: 18444 | E2: 31 | F2: =E2-G2 -> 31 | G2: 0 | H2: =(+D2*49.99999%)/E2*F2 -> 9221.9982 | I2: =(H2*50%) -> 4610.9991 | J2: =(1600/E2)*F2 -> 1600 | K2: =(L2-H2-I2-J2) -> 2567.4247 | L2: =(D2-W2)/E2*F2-Y2 -> 18000.422 | M2: 0 | N2: 0 | O2: 200 | P2: 0 | Q2: 0 | R2: 500 | S2: =L2+P2+Q2+R2 -> 18500.422 | T2: 0 | U2: =ROUND((L2/E2)*G2,0) -> 0 | V2: 0 | W2: 0 | X2: 0 | Y2: =H2*4.81% -> 443.57811 | Z2: =M2+N2+O2+U2+V2+T2+W2+X2+Y2 -> 643.57811 | AA2: =L2-Z2+Y2+W2+X2+P2+Q2+R2 -> 18300.422
A3: AGS26078 | B3: Kankanala Sravani | C3: 46174 | D3: 15370 | E3: 31 | F3: =E3-G3 -> 31 | G3: 0 | H3: =(+D3*49.99999%)/E3*F3 -> 7684.9985 | I3: =(H3*50%) -> 3842.4992 | J3: =(1600/E3)*F3 -> 1600 | K3: =(L3-H3-I3-J3) -> 1872.8539 | L3: =(D3-W3)/E3*F3-Y3 -> 15000.352 | M3: 0 | N3: 0 | O3: 200 | P3: 0 | Q3: 0 | R3: 0 | S3: =L3+P3+Q3+R3 -> 15000.352 | T3: 0 | U3: =ROUND((L3/E3)*G3,0) -> 0 | V3: 0 | W3: 0 | X3: 0 | Y3: =H3*4.81% -> 369.64843 | Z3: =M3+N3+O3+U3+V3+T3+W3+X3+Y3 -> 569.64843 | AA3: =L3-Z3+Y3+W3+X3+P3+Q3+R3 -> 14800.352
A4: AGS26079 | B4: Vadicharla Sandeep Kumar | C4: 46174 | D4: 18444 | E4: 31 | F4: =E4-G4 -> 31 | G4: 0 | H4: =(+D4*49.99999%)/E4*F4 -> 9221.9982 | I4: =(H4*50%) -> 4610.9991 | J4: =(1600/E4)*F4 -> 1600 | K4: =(L4-H4-I4-J4) -> 2567.4247 | L4: =(D4-W4)/E4*F4-Y4 -> 18000.422 | M4: 0 | N4: 0 | O4: 200 | P4: 0 | Q4: 0 | R4: 0 | S4: =L4+P4+Q4+R4 -> 18000.422 | T4: 0 | U4: =ROUND((L4/E4)*G4,0) -> 0 | V4: 0 | W4: 0 | X4: 0 | Y4: =H4*4.81% -> 443.57811 | Z4: =M4+N4+O4+U4+V4+T4+W4+X4+Y4 -> 643.57811 | AA4: =L4-Z4+Y4+W4+X4+P4+Q4+R4 -> 17800.422
A5: AGS26080 | B5: Thota Varsha | C5: 46174 | D5: 15370 | E5: 31 | F5: =E5-G5 -> 31 | G5: 0 | H5: =(+D5*49.99999%)/E5*F5 -> 7684.9985 | I5: =(H5*50%) -> 3842.4992 | J5: =(1600/E5)*F5 -> 1600 | K5: =(L5-H5-I5-J5) -> 1872.8539 | L5: =(D5-W5)/E5*F5-Y5 -> 15000.352 | M5: 0 | N5: 0 | O5: 200 | P5: 0 | Q5: 0 | R5: 0 | S5: =L5+P5+Q5+R5 -> 15000.352 | T5: 0 | U5: =ROUND((L5/E5)*G5,0) -> 0 | V5: 0 | W5: 0 | X5: 0 | Y5: =H5*4.81% -> 369.64843 | Z5: =M5+N5+O5+U5+V5+T5+W5+X5+Y5 -> 569.64843 | AA5: =L5-Z5+Y5+W5+X5+P5+Q5+R5 -> 14800.352
A6: AGS26081 | B6: Shaik Faiza | C6: 46174 | D6: 13320 | E6: 31 | F6: =E6-G6 -> 31 | G6: 0 | H6: =(+D6*49.99999%)/E6*F6 -> 6659.9987 | I6: =(H6*50%) -> 3329.9993 | J6: =(1600/E6)*F6 -> 1600 | K6: =(L6-H6-I6-J6) -> 1409.6561 | L6: =(D6-W6)/E6*F6-Y6 -> 12999.654 | M6: 0 | N6: 0 | O6: 150 | P6: 0 | Q6: 0 | R6: 0 | S6: =L6+P6+Q6+R6 -> 12999.654 | T6: 0 | U6: =ROUND((L6/E6)*G6,0) -> 0 | V6: 0 | W6: 0 | X6: 0 | Y6: =H6*4.81% -> 320.34594 | Z6: =M6+N6+O6+U6+V6+T6+W6+X6+Y6 -> 470.34594 | AA6: =L6-Z6+Y6+W6+X6+P6+Q6+R6 -> 12849.654
A7: AGS26082 | B7: Shaik Shaheen | C7: 46174 | D7: 12296 | E7: 31 | F7: =E7-G7 -> 31 | G7: 0 | H7: =(+D7*49.99999%)/E7*F7 -> 6147.9988 | I7: =(H7*50%) -> 3073.9994 | J7: =(1600/E7)*F7 -> 1600 | K7: =(L7-H7-I7-J7) -> 1178.2831 | L7: =(D7-W7)/E7*F7-Y7 -> 12000.281 | M7: 0 | N7: 0 | O7: 150 | P7: 0 | Q7: 0 | R7: 0 | S7: =L7+P7+Q7+R7 -> 12000.281 | T7: 0 | U7: =ROUND((L7/E7)*G7,0) -> 0 | V7: 0 | W7: 0 | X7: 0 | Y7: =H7*4.81% -> 295.71874 | Z7: =M7+N7+O7+U7+V7+T7+W7+X7+Y7 -> 445.71874 | AA7: =L7-Z7+Y7+W7+X7+P7+Q7+R7 -> 11850.281
A8: AGS26083 | B8: Guduru Subhanbee | C8: 46174 | D8: 13320 | E8: 31 | F8: =E8-G8 -> 31 | G8: 0 | H8: =(+D8*49.99999%)/E8*F8 -> 6659.9987 | I8: =(H8*50%) -> 3329.9993 | J8: =(1600/E8)*F8 -> 1600 | K8: =(L8-H8-I8-J8) -> 1409.6561 | L8: =(D8-W8)/E8*F8-Y8 -> 12999.654 | M8: 0 | N8: 0 | O8: 150 | P8: 0 | Q8: 0 | R8: 0 | S8: =L8+P8+Q8+R8 -> 12999.654 | T8: 0 | U8: =ROUND((L8/E8)*G8,0) -> 0 | V8: 0 | W8: 0 | X8: 0 | Y8: =H8*4.81% -> 320.34594 | Z8: =M8+N8+O8+U8+V8+T8+W8+X8+Y8 -> 470.34594 | AA8: =L8-Z8+Y8+W8+X8+P8+Q8+R8 -> 12849.654
A9: AGS26084 | B9: Yapakayala Sampath | C9: 46174 | D9: 28690 | E9: 31 | F9: =E9-G9 -> 31 | G9: 0 | H9: =(+D9*49.99999%)/E9*F9 -> 14344.997 | I9: =(H9*50%) -> 7172.4986 | J9: =(1600/E9)*F9 -> 1600 | K9: =(L9-H9-I9-J9) -> 4882.5099 | L9: =(D9-W9)/E9*F9-Y9 -> 28000.006 | M9: 0 | N9: 0 | O9: 200 | P9: 0 | Q9: 0 | R9: 0 | S9: =L9+P9+Q9+R9 -> 28000.006 | T9: 0 | U9: =ROUND((L9/E9)*G9,0) -> 0 | V9: 0 | W9: 0 | X9: 0 | Y9: =H9*4.81% -> 689.99436 | Z9: =M9+N9+O9+U9+V9+T9+W9+X9+Y9 -> 889.99436 | AA9: =L9-Z9+Y9+W9+X9+P9+Q9+R9 -> 27800.006
A10: AGS26085 | B10: Shaik Akram | C10: 46174 | D10: 25616 | E10: 31 | F10: =E10-G10 -> 31 | G10: 0 | H10: =(+D10*49.99999%)/E10*F10 -> 12807.997 | I10: =(H10*50%) -> 6403.9987 | J10: =(1600/E10)*F10 -> 1600 | K10: =(L10-H10-I10-J10) -> 4187.9392 | L10: =(D10-W10)/E10*F10-Y10 -> 24999.935 | M10: 0 | N10: 0 | O10: 200 | P10: 0 | Q10: 0 | R10: 0 | S10: =L10+P10+Q10+R10 -> 24999.935 | T10: 0 | U10: =ROUND((L10/E10)*G10,0) -> 0 | V10: 0 | W10: 0 | X10: 0 | Y10: =H10*4.81% -> 616.06468 | Z10: =M10+N10+O10+U10+V10+T10+W10+X10+Y10 -> 816.06468 | AA10: =L10-Z10+Y10+W10+X10+P10+Q10+R10 -> 24799.935
A11: AGS26086 | B11: Mesu Lion Kumar | C11: 46174 | D11: 23567 | E11: 31 | F11: =E11-G11 -> 31 | G11: 0 | H11: =(+D11*49.99999%)/E11*F11 -> 11783.498 | I11: =(H11*50%) -> 5891.7488 | J11: =(1600/E11)*F11 -> 1600 | K11: =(L11-H11-I11-J11) -> 3724.9673 | L11: =(D11-W11)/E11*F11-Y11 -> 23000.214 | M11: 0 | N11: 0 | O11: 200 | P11: 0 | Q11: 0 | R11: 0 | S11: =L11+P11+Q11+R11 -> 23000.214 | T11: 0 | U11: =ROUND((L11/E11)*G11,0) -> 0 | V11: 0 | W11: 0 | X11: 0 | Y11: =H11*4.81% -> 566.78624 | Z11: =M11+N11+O11+U11+V11+T11+W11+X11+Y11 -> 766.78624 | AA11: =L11-Z11+Y11+W11+X11+P11+Q11+R11 -> 22800.214
A12: AGS26087 | B12: Bashaboina Srilatha | C12: 46174 | D12: 46109 | E12: 31 | F12: =E12-G12 -> 31 | G12: 0 | H12: =(+D12*49.99999%)/E12*F12 -> 23054.495 | I12: =(H12*50%) -> 11527.248 | J12: =(1600/E12)*F12 -> 1600 | K12: =(L12-H12-I12-J12) -> 8818.3357 | L12: =(D12-W12)/E12*F12-Y12 -> 45000.079 | M12: 0 | N12: 0 | O12: 200 | P12: 0 | Q12: 0 | R12: 0 | S12: =L12+P12+Q12+R12 -> 45000.079 | T12: 0 | U12: =ROUND((L12/E12)*G12,0) -> 0 | V12: 0 | W12: 0 | X12: 0 | Y12: =H12*4.81% -> 1108.9212 | Z12: =M12+N12+O12+U12+V12+T12+W12+X12+Y12 -> 1308.9212 | AA12: =L12-Z12+Y12+W12+X12+P12+Q12+R12 -> 44800.079
A13: AGS26089 | B13: Pothuraju Haritha | C13: 46174 | D13: 10246 | E13: 31 | F13: =E13-G13 -> 31 | G13: 0 | H13: =(+D13*49.99999%)/E13*F13 -> 5122.999 | I13: =(H13*50%) -> 2561.4995 | J13: =(1600/E13)*F13 -> 1600 | K13: =(L13-H13-I13-J13) -> 715.08529 | L13: =(D13-W13)/E13*F13-Y13 -> 9999.5837 | M13: 0 | N13: 0 | O13: 150 | P13: 0 | Q13: 0 | R13: 0 | S13: =L13+P13+Q13+R13 -> 9999.5837 | T13: 0 | U13: =ROUND((L13/E13)*G13,0) -> 0 | V13: 0 | W13: 0 | X13: 0 | Y13: =H13*4.81% -> 246.41625 | Z13: =M13+N13+O13+U13+V13+T13+W13+X13+Y13 -> 396.41625 | AA13: =L13-Z13+Y13+W13+X13+P13+Q13+R13 -> 9849.5837
A14: AGS26090 | B14: Tirupathi Anusha | C14: 46174 | D14: 12296 | E14: 31 | F14: =E14-G14 -> 31 | G14: 0 | H14: =(+D14*49.99999%)/E14*F14 -> 6147.9988 | I14: =(H14*50%) -> 3073.9994 | J14: =(1600/E14)*F14 -> 1600 | K14: =(L14-H14-I14-J14) -> 1178.2831 | L14: =(D14-W14)/E14*F14-Y14 -> 12000.281 | M14: 0 | N14: 0 | O14: 150 | P14: 0 | Q14: 0 | R14: 0 | S14: =L14+P14+Q14+R14 -> 12000.281 | T14: 0 | U14: =ROUND((L14/E14)*G14,0) -> 0 | V14: 0 | W14: 0 | X14: 0 | Y14: =H14*4.81% -> 295.71874 | Z14: =M14+N14+O14+U14+V14+T14+W14+X14+Y14 -> 445.71874 | AA14: =L14-Z14+Y14+W14+X14+P14+Q14+R14 -> 11850.281

Sheet LOP
A1: Employee ID | B1: Employee Name | C1: LOP day's
A2: AGS26034 | B2: Sripada Shivakumar | C2: 1

Sheet Trainers
A1: S.No | B1: Name | C1: Hours/Days | D1: Unit | E1: Cost per Hour/Day | F1: Total Cost | G1: Bank Account Number | H1: IFSC code | I1: Account holder Name | J1: Bank Name
A2: 1 | B2: Venkatesh Salla | C2: 29 | D2: Hours | E2: 1000 | F2: =C2*E2 -> 29000 | G2: 922020060410761 | H2: UTIB0003985 | I2: KAKARLA PRASAD BABU | J2: Axis Bank
A3: 2 | B3: Dharna | C3: 15 | D3: Hours | E3: 1000 | F3: =C3*E3 -> 15000 | G3: 621837012 | H3: IDIB000H561 | I3: dharna ahuja | J3: indian bank
A4: 3 | B4: Simeon | C4: 14 | D4: Hours | E4: 1800 | F4: =C4*E4 -> 25200 | G4: 62332625265 | H4: SBIN0020884 | I4: SIMEON ABRAHAM iniganti | J4: SBI
A5: 4 | B5: Akshay | C5: 11 | D5: Hours | E5: 800 | F5: =C5*E5 -> 8800 | G5: 45080524946 | H5: SBIN0020030 | I5: Shweta Akshay Painjane | J5: SBI
A6: 5 | B6: Madhuri | C6: 16.5 | D6: Hours | E6: 1000 | F6: =C6*E6 -> 16500 | G6: 814649188 | H6: IDIB000C026 | I6: K GOPINADH | J6: INDIAN BANK
C9: Total | E9: =SUM(F2:F8) -> 94500

Sheet Salaries
A1: Employee ID | B1: Employee Name | C1: DOJ | D1: Net Salary Payable | E1: Bank Account Number | F1: IFSC code | G1: Bank Name | H1: Remarks
A2: AGS26038 | B2: Ainala Saiesha | C2: 46086 | D2: =VLOOKUP(A2,Employees!A2:AB3,28,0) -> 93615 | E2: 99980130961795 | F2: FDRL0001555 | G2: Federal Bank
A3: AGS26004 | B3: Ande Sharath Chandra | C3: 46055 | D3: =VLOOKUP(A3,Consultant!A1:H5,8,0) -> 79800 | E3: 50100677371816 | F3: HDFC0001042 | G3: HDFC Bank
A4: AGS26005 | B4: Tanakala Janardhan | C4: 46055 | D4: =VLOOKUP(A4,Consultant!A2:H7,8,0) -> 69800 | E4: 99980130961985 | F4: FDRL0001555 | G4: Federal Bank
A5: AGS26024 | B5: Priya Darshini Pola | C5: 46072 | D5: =VLOOKUP(A5,Consultant!A4:H9,8,0) -> 79800 | E5: 99980130963916 | F5: FDRL0001555 | G5: Federal Bank
A6: AGS26039 | B6: Esther Deva Priya | C6: 46092 | D6: =VLOOKUP(A6,Consultant!A4:H10,8,0) -> 19800 | E6: 99980130950434 | F6: FDRL0001555 | G6: Federal Bank
A7: AGS26091 | B7: Tepala Rajukumar | C7: 46174 | D7: =VLOOKUP(A7,Consultant!A5:H11,8,0) -> 10000 | E7: 99980128938326 | F7: FDRL0001555 | G7: Federal Bank
A8: AGS26088 | B8: Budhi Vamshi | C8: 46174 | D8: =VLOOKUP(A8,Consultant!A3:H7,8,0) -> 124800 | E8: 20261344343 | F8: SBIN0063220 | G8: SBI
A9: AGS26011 | B9: Siddula Hemasai | C9: 46083 | D9: =VLOOKUP(A9,'Tech Team'!A1:AA50,27,0) -> 40117.75 | E9: 3327101004003 | F9: CNRB0003327 | G9: Canara Bank
A10: AGS26018 | B10: Settybathini Sathish | C10: 46083 | D10: =VLOOKUP(A10,'Tech Team'!A2:AA51,27,0) -> 40117.75 | E10: 50100595290241 | F10: HDFC0000075 | G10: HDFC Bank
A11: AGS26010 | B11: Vemula Varshith | C11: 46083 | D11: =VLOOKUP(A11,'Tech Team'!A3:AA52,27,0) -> 54757 | E11: 99980130961993 | F11: FDRL0001555 | G11: Federal Bank
A12: AGS26019 | B12: Nelapatla Srinivas | C12: 46083 | D12: =VLOOKUP(A12,'Tech Team'!A4:AA53,27,0) -> 19486.851 | E12: 99980130961951 | F12: FDRL0001555 | G12: Federal Bank
A13: AGS26014 | B13: Vulli Pavan | C13: 46083 | D13: =VLOOKUP(A13,'Tech Team'!A5:AA54,27,0) -> 44997.5 | E13: 77770116800885 | F13: FDRL0007777 | G13: Federal Bank
A14: AGS26017 | B14: Vavilla Saikumar | C14: 46083 | D14: =VLOOKUP(A14,'Tech Team'!A6:AA55,27,0) -> 40117.75 | E14: 99980130963940 | F14: FDRL0001555 | G14: Federal Bank
A15: AGS26016 | B15: Manisha Ashroba Virkar | C15: 46083 | D15: =VLOOKUP(A15,'Tech Team'!A7:AA56,27,0) -> 40117.75 | E15: 62297418711 | F15: SBIN0003801 | G15: State Bank of India
A16: AGS26015 | B16: Karne Narsimha Reddy | C16: 46083 | D16: =VLOOKUP(A16,'Tech Team'!A8:AA57,27,0) -> 40117.75 | E16: 99980130961886 | F16: FDRL0001555 | G16: Federal Bank
A17: AGS26013 | B17: Kalepu Vijay Kumar | C17: 46083 | D17: =VLOOKUP(A17,'Tech Team'!A9:AA58,27,0) -> 40117.75 | E17: 15550100112421 | F17: FDRL0001555 | G17: Federal Bank
A18: AGS26021 | B18: Kontham Sushma | C18: 46083 | D18: =VLOOKUP(A18,'Tech Team'!A10:AA59,27,0) -> 44997.5 | E18: 99980130961894 | F18: FDRL0001555 | G18: Federal Bank
A19: AGS26023 | B19: Bobbarala Varshini | C19: 46083 | D19: =VLOOKUP(A19,'Tech Team'!A11:AA60,27,0) -> 54757 | E19: 99980130961878 | F19: FDRL0001555 | G19: Federal Bank
A20: AGS26026 | B20: Surampudi Roop Sai | C20: 46083 | D20: =VLOOKUP(A20,'Tech Team'!A12:AA61,27,0) -> 54757 | E20: 615728726 | F20: IDIB000P121 | G20: Indian Bank
... A28: AGS26043 | B28: Chebrolu Yashaswini | C28: 46113 | D28: =VLOOKUP(A28,'Tech Team'!A20:AA69,27,0) -> 25478.501 | E28: 40590710609 | F28: SBIN0011984 | G28: State Bank of India
A29: AGS26045 | B29: Chebrolu Monika | C29: 46113 | D29: =VLOOKUP(A29,'Tech Team'!A21:AA70,27,0) -> 44997.5 | E29: 000801663119 | F29: ICIC0000008 | G29: ICICI Bank
A30: AGS26047 | B30: Upadhyayula Naga Lakshmi Deepthi | C30: 46114 | D30: =VLOOKUP(A30,'Tech Team'!A22:AA71,27,0) -> 19486.851 | E30: 55560103431927 | F30: FDRL0005556 | G30: Federal Bank
A31: AGS26048 | B31: Rapolu Rekha | C31: 46113 | D31: =VLOOKUP(A31,'Tech Team'!A23:AA72,27,0) -> 12689.25 | E31: 15550100112355 | F31: FDRL0001555 | G31: Federal Bank
A32: AGS26049 | B32: Ragiru Nikhitha | C32: 46113 | D32: =VLOOKUP(A32,'Tech Team'!A24:AA73,27,0) -> 12689.25 | E32: 15550100112280 | F32: FDRL0001555 | G32: Federal Bank
A33: AGS26051 | B33: Mundlamuri Mrudula | C33: 46113 | D33: =VLOOKUP(A33,'Tech Team'!A25:AA74,27,0) -> 12689.25 | E33: 15550100112272 | F33: FDRL0001555 | G33: Federal Bank
A34: AGS26053 | B34: Palavelli Praveen Reddy | C34: 46113 | D34: =VLOOKUP(A34,'Tech Team'!A26:AA75,27,0) -> 12689.25 | E34: 15550100112306 | F34: FDRL0001555 | G34: Federal Bank
A35: AGS26054 | B35: Yaramothu Himaja | C35: 46113 | D35: =VLOOKUP(A35,'Tech Team'!A27:AA76,27,0) -> 12689.25 | E35: 15550100112298 | F35: FDRL0001555 | G35: Federal Bank
A36: AGS26031 | B36: Y Raghavendar | C36: 46113 | D36: =VLOOKUP(A36,'Tech Team'!A28:AA77,27,0) -> 40117.75 | E36: 99980130961787 | F36: FDRL0001555 | G36: Federal Bank
A37: AGS26056 | B37: Bommala Naveen Kumar | C37: 46113 | D37: =VLOOKUP(A37,'Tech Team'!A29:AA78,27,0) -> 40117.75 | E37: 37097117593 | F37: SBIN0008833 | G37: State Bank of India
A38: AGS26057 | B38: Odeti Srinivas | C38: 46113 | D38: =VLOOKUP(A38,'Tech Team'!A30:AA79,27,0) -> 25478.501 | E38: 99980130961779 | F38: FDRL0001555 | G38: Federal Bank
A39: AGS26058 | B39: Matha Sai Prasad | C39: 46113 | D39: =VLOOKUP(A39,'Tech Team'!A31:AA80,27,0) -> 12689.25 | E39: 23520100016377 | F39: FDRL0002352 | G39: Federal Bank
A40: AGS26059 | B40: Chamakuri Raghuram | C40: 46113 | D40: =VLOOKUP(A40,'Tech Team'!A32:AA81,27,0) -> 12689.25 | E40: 15550100112322 | F40: FDRL0001555 | G40: Federal Bank
A41: AGS26025 | B41: Tumula Dinesh Kumar | C41: 46113 | D41: =VLOOKUP(A41,'Tech Team'!A33:AA82,27,0) -> 19486.851 | E41: 44610100006654 | F41: BARB0SIDDIP | G41: Bank of Baroda
... A51: AGS26067 | B51: Md Imran Khan | C51: 46146 | D51: =VLOOKUP(A51,'Tech Team'!A43:AA92,27,0) -> 12689.25 | E51: 40592463089 | F51: SBIN0020248 | G51: State Bank of India
A52: AGS26068 | B52: Narmeta Srujanreddy | C52: 46146 | D52: =VLOOKUP(A52,'Tech Team'!A44:AA93,27,0) -> 12689.25 | E52: 1814100100000327 | F52: PUNB0181410 | G52: Punjab National Bank
A53: AGS26069 | B53: Neetapalli Sreekanth Reddy | C53: 46146 | D53: =VLOOKUP(A53,'Tech Team'!A45:AA94,27,0) -> 40117.75 | E53: 55560103591175 | F53: FDRL0005556 | G53: Federal Bank
A54: AGS26070 | B54: Melath Ashwin | C54: 46146 | D54: =VLOOKUP(A54,'Tech Team'!A46:AA95,27,0) -> 30358.25 | E54: 99980130963841 | F54: FDRL0001555 | G54: Federal Bank
A55: AGS26072 | B55: Mohd Sameer | C55: 46146 | D55: =VLOOKUP(A55,'Tech Team'!A47:AA96,27,0) -> 12689.25 | E55: 15550100112397 | F55: FDRL0001555 | G55: Federal Bank
A56: AGS26073 | B56: Boya Indrasena Naidu | C56: 46146 | D56: =VLOOKUP(A56,'Tech Team'!A48:AA97,27,0) -> 12689.25 | E56: 225210100082348 | F56: UBIN0822523 | G56: Union Bank
...

Sheet Rental Payment
A1: Account holder Name | B1: Actual Cost | C1: GST | D1: Total Cost | E1: Bank Account Number | F1: IFSC code | G1: Bank Name | H1: Transfer
A2: ODCET CONSULTANCY SERVICES PVT LTD GST Number : 36AADCO5390F1ZD | B2: 160000 | C2: 0 | D2: =B2+C2 -> 160000 | E2: 50200062999445 | F2: HDFC0000364 | G2: HDFC | H2: Cash
A3: ODCET CONSULTANCY SERVICES PVT LTD GST Number : 36AADCO5390F1ZD | B3: 20000 | C3: 0 | D3: =B3+C3 -> 20000 | E3: 50200062999445 | F3: HDFC0000364 | G3: HDFC | H3: Cash
D5: =SUM(D2:D4) -> 180000

Sheet Salaries_30042026
A1: Employee ID | B1: Employee Name | C1: DOJ | D1: Net Salary Payable | E1: Bank Account Number | F1: IFSC code | G1: Bank Name | H1: Remarks
A2: AGS26004 | B2: Ande Sharath Chandra | C2: 46054 | D2: =VLOOKUP(A2,Consultant!A2:H5,8,0) -> 79800 | E2: 50100677371816 | F2: HDFC0001042 | G2: HDFC Bank
A3: AGS26005 | B3: Tanakala Janardhan | C3: 46054 | D3: =VLOOKUP(A3,Consultant!A3:H7,8,0) -> 69800 | E3: 99980130961985 | F3: FDRL0001555 | G3: Federal Bank
A4: AGS26006 | B4: Abhijeet Vijaysingh Pardeshi | C4: 46062 | D4: =VLOOKUP(A4,Employees!2:2,29,0) -> #N/A | E4: 41280100007853 | F4: BARB0WALUJX | G4: BANK OF BARODA
A5: AGS26010 | B5: Vemula Varshith | C5: 46083 | D5: =VLOOKUP(A5,'Tech Team'!A4:AA38,28,0) -> #REF! | E5: 99980130961993 | F5: FDRL0001555 | G5: Federal Bank
A6: AGS26011 | B6: Siddula Hemasai | C6: 46083 | D6: =VLOOKUP(A6,'Tech Team'!A2:AA36,28,0) -> #REF! | E6: 3327101004003 | F6: CNRB0003327 | G6: Canara Bank
A7: AGS26013 | B7: Kalepu Vijay | C7: 46083 | D7: =VLOOKUP(A7,'Tech Team'!A10:AA44,28,0) -> #REF! | E7: 159502740717 | F7: INDB0000329 | G7: INDUSIND BANK
A8: AGS26014 | B8: Vulli Pavan | C8: 46083 | D8: =VLOOKUP(A8,'Tech Team'!A6:AA40,28,0) -> #REF! | E8: 77770116800885 | F8: FDRL0007777 | G8: Federal Bank
A9: AGS26015 | B9: Karne Narsimha Reddy | C9: 46083 | D9: =VLOOKUP(A9,'Tech Team'!A9:AA43,28,0) -> #REF! | E9: 99980130961886 | F9: FDRL0001555 | G9: Federal Bank
A10: AGS26016 | B10: Manisha Ashroba Virkar | C10: 46083 | D10: =VLOOKUP(A10,'Tech Team'!A8:AA42,28,0) -> #REF! | E10: 62297418711 | F10: SBIN0003801 | G10: State Bank of India
A11: AGS26017 | B11: Vavilla Saikumar | C11: 46083 | D11: =VLOOKUP(A11,'Tech Team'!A7:AA41,28,0) -> #REF! | E11: 99980130963940 | F11: FDRL0001555 | G11: Federal Bank
A12: AGS26018 | B12: Settybathini Sathish | C12: 46083 | D12: =VLOOKUP(A12,'Tech Team'!A3:AA37,28,0) -> #REF! | E12: 50100595290241 | F12: HDFC0000075 | G12: HDFC Bank
A13: AGS26019 | B13: Nelapatla Srinivas | C13: 46083 | D13: =VLOOKUP(A13,'Tech Team'!A5:AA39,28,0) -> #REF! | E13: 99980130961951 | F13: FDRL0001555 | G13: Federal Bank
A14: AGS26020 | B14: Gurindapalli Krishna Chaitanya | C14: 46066 | D14: =VLOOKUP(A14,Consultant!A4:H8,8,0) -> #N/A | E14: 020201545829 | F14: ICIC0000202 | G14: ICICI Bank
A15: AGS26021 | B15: Kontham Sushma | C15: 46083 | D15: =VLOOKUP(A15,'Tech Team'!A11:AA45,28,0) -> #REF! | E15: 99980130961894 | F15: FDRL0001555 | G15: Federal Bank
A16: AGS26023 | B16: Bobbarala Varshini | C16: 46083 | D16: =VLOOKUP(A16,'Tech Team'!A12:AA47,28,0) -> #REF! | E16: 99980130961878 | F16: FDRL0001555 | G16: Federal Bank
A17: AGS26024 | B17: Priya Darshini Pola | C17: 46072 | D17: =VLOOKUP(A17,Consultant!A4:H9,8,0) -> 79800 | E17: 99980130963916 | F17: FDRL0001555 | G17: Federal Bank
A18: AGS26025 | B18: Tumula Dinesh Kumar | C18: 46113 | D18: =VLOOKUP(A18,'Tech Team'!A34:AA71,28,0) -> #REF! | E18: 44610100006654 | F18: BARB0SIDDIP | G18: Bank of Baroda
A19: AGS26026 | B19: Surampudi Roop Sai | C19: 46083 | D19: =VLOOKUP(A19,'Tech Team'!A13:AA48,28,0) -> #REF! | E19: 615728726 | F19: IDIB000P121 | G19: Indian Bank
A20: AGS26028 | B20: Mohammed Abdul Moid | C20: 46083 | D20: =VLOOKUP(A20,'Tech Team'!A14:AA49,28,0) -> #REF! | E20: 99980130963882 | F20: FDRL0001555 | G20: Federal Bank
A21: AGS26029 | B21: Mula Sai Preetham Goud | C21: 46083 | D21: =VLOOKUP(A21,'Tech Team'!A15:AA50,28,0) -> #REF! | E21: 99980130961902 | F21: FDRL0001555 | G21: Federal Bank
A22: AGS26030 | B22: Sruthin Kumar Basa | C22: 46083 | D22: =VLOOKUP(A22,'Tech Team'!A16:AA51,28,0) -> #REF! | E22: 99980130961761 | F22: FDRL0001555 | G22: Federal Bank
A23: AGS26031 | B23: Y Raghavendar | C23: 46113 | D23: =VLOOKUP(A23,'Tech Team'!A29:AA66,28,0) -> #REF! | E23: 99980130961787 | F23: FDRL0001555 | G23: Federal Bank
A24: AGS26032 | B24: Vempadapu Uday Sai Tarun | C24: 46083 | D24: =VLOOKUP(A24,'Tech Team'!A17:AA52,28,0) -> #REF! | E24: 37182972098 | F24: SBIN0008054 | G24: State Bank of India
A25: AGS26034 | B25: Sripada Shivakumar | C25: 46083 | D25: =VLOOKUP(A25,'Tech Team'!A18:AA54,28,0) -> #REF! | E25: 41536691505 | F25: SBIN0008807 | G25: State Bank of India
A26: AGS26035 | B26: Varakantham Surender Reddy | C26: 46083 | D26: =VLOOKUP(A26,'Tech Team'!A19:AA55,28,0) -> #REF! | E26: 50100141200194 | F26: HDFC0004480 | G26: HDFC Bank
A27: AGS26038 | B27: Ainala Saiesha | C27: 46086 | D27: =VLOOKUP(A27,Employees!2:3,29,0) -> 0 | E27: 99980130961795 | F27: FDRL0001555 | G27: Federal Bank
A28: AGS26039 | B28: Esther Deva Priya | C28: 46092 | D28: =VLOOKUP(A28,Consultant!A5:H10,8,0) -> 19800 | E28: 99980130950434 | F28: FDRL0001555 | G28: Federal Bank
A29: AGS26041 | B29: Sudhagani Sai Charan | C29: 46113 | D29: =VLOOKUP(A29,'Tech Team'!A20:AA56,28,0) -> #REF! | E29: 15550100112314 | F29: FDRL0001555 | G29: Federal Bank
A30: AGS26043 | B30: Chebrolu Yashaswini | C30: 46113 | D30: =VLOOKUP(A30,'Tech Team'!A21:AA57,28,0) -> #REF! | E30: 40590710609 | F30: SBIN0011984 | G30: State Bank of India
A31: AGS26044 | B31: Naveen Pulikonda | C31: 46113 | D31: =VLOOKUP(A31,'Tech Team'!A36:AA73,28,0) -> #REF! | E31: 15550100112330 | F31: FDRL0001555 | G31: Federal Bank
A32: AGS26045 | B32: Chebrolu Monika | C32: 46113 | D32: =VLOOKUP(A32,'Tech Team'!A22:AA58,28,0) -> #REF! | E32: 801663119 | F32: ICIC0000008 | G32: ICICI Bank
A33: AGS26047 | B33: Upadhyayula Naga Lakshmi Deepthi | C33: 46113 | D33: =VLOOKUP(A33,'Tech Team'!A23:AA59,28,0) -> #REF! | E33: 55560103431927 | F33: FDRL0005556 | G33: Federal bank
A34: AGS26048 | B34: Rapolu Rekha | C34: 46113 | D34: =VLOOKUP(A34,'Tech Team'!A24:AA60,28,0) -> #REF! | E34: 15550100112355 | F34: FDRL0001555 | G34: Federal Bank
A35: AGS26049 | B35: Ragiru Nikhitha | C35: 46113 | D35: =VLOOKUP(A35,'Tech Team'!A25:AA61,28,0) -> #REF! | E35: 15550100112280 | F35: FDRL0001555 | G35: Federal Bank
A36: AGS26051 | B36: Mundlamuri Mrudula | C36: 46113 | D36: =VLOOKUP(A36,'Tech Team'!A26:AA62,28,0) -> #REF! | E36: 386701504229 | F36: ICIC0003867 | G36: ICICI Bank
A37: AGS26053 | B37: Palavelli Praveen Reddy | C37: 46113 | D37: =VLOOKUP(A37,'Tech Team'!A27:AA64,28,0) -> #REF! | E37: 15550100112306 | F37: FDRL0001555 | G37: Federal Bank
A38: AGS26054 | B38: Yaramothu Himaja | C38: 46113 | D38: =VLOOKUP(A38,'Tech Team'!A28:AA65,28,0) -> #REF! | E38: 15550100112298 | F38: FDRL0001555 | G38: Federal Bank
A39: AGS26055 | B39: Cholleti Sai Kumar | C39: 46113 | D39: =VLOOKUP(A39,'Tech Team'!A27:AA63,28,0) -> #N/A | E39: 44652833670 | F39: SBIN0021487 | G39: State Bank of India
A40: AGS26056 | B40: Bommala Naveen Kumar | C40: 46113 | D40: =VLOOKUP(A40,'Tech Team'!A30:AA67,28,0) -> #REF! | E40: 37097117593 | F40: SBIN0008833 | G40: State Bank of India
...

Sheet Payments_30042026
A1: S.No | B1: Name | C1: No of Hours | D1: Cost per Hour | E1: Total Cost | F1: Bank Account Number | G1: IFSC code | H1: Account holder Name | I1: Bank Name
A2: 1 | B2: Sridhar | E2: 230000 | F2: 32862142889 | G2: SBIN0011121 | H2: ERGAMREDDY SARADHA | I2: SBI
A3: 2 | B3: Sreekanth (Arjun) | C3: 22 | D3: 1200 | E3: =C3*D3 -> 26400 | F3: 004001579702 | G3: ICIC0001806 | H3: Sreekanth Koraboina | I3: ICICI Bank
A4: 3 | B4: Ravi | C4: 22 | D4: 1200 | E4: =C4*D4 -> 26400 | F4: 653101004326 | G4: ICIC0000053 | H4: G Ravi Teja | I4: ICICI Bank
A5: 4 | B5: Venkatesh Salla | C5: 30 | D5: 1000 | E5: =C5*D5 -> 30000 | F5: 922020060410761 | G5: UTIB0003985 | H5: KAKARLA PRASAD BABU | I5: Axis Bank
A6: 5 | B6: Madhuri | C6: 30 | D6: 1000 | E6: =C6*D6 -> 30000 | F6: 814649188 | G6: IDIB000C026 | H6: K GOPINADH | I6: INDIAN BANK
A7: 6 | B7: Chetna | C7: 13.5 | D7: 1000 | E7: =C7*D7 -> 13500 | F7: 50100115451901 | G7: HDFC0000485 | H7: HDFC0000485 | I7: HDFC
A8: 7 | B8: Akshay | C8: 19 | D8: 800 | E8: =C8*D8 -> 15200 | F8: 45080524946 | G8: SBIN0020030 | H8: Shweta Akshay Painjane | I8: SBI
A9: 8 | B9: ODCET | E9: 160000 | F9: 50200062999445 | G9: HDFC0000364 | H9: ODCET CONSULTANCY SERVICES PVT LTD | I9: HDFC
A10: 9 | B10: ZOHO Corporation Private Limited | E10: 22583.06 | F10: 50200026430541 | G10: HDFC0001225 | H10: ZOHO Corporation Private Limited | I10: HDFC
B12: Total | E12: =SUM(E2:E10) -> 554083.06

Sheet Payment
A1: Employee ID | B1: Employee Name | C1: DOJ | D1: Net Salary Payable | E1: Bank Account Number | F1: IFSC code | G1: Bank Name | H1: Remarks
A2: AGS26022 | B2: Akkma Sai Teja | C2: 46083 | D2: =VLOOKUP(A2,'Tech Team'!A12:AA46,28,0) -> #N/A | E2: 50100565431077 | F2: HDFC0005175 | G2: HDFC Bank | H2: Hold
A3: AGS26004 | B3: Ande Sharath Chandra | C3: 46054 | D3: =VLOOKUP(A3,Consultant!A2:H5,8,0) -> 79800 | E3: 50100677371816 | F3: HDFC0001042 | G3: HDFC Bank
A4: AGS26005 | B4: Tanakala Janardhan | C4: 46054 | D4: =VLOOKUP(A4,Consultant!A3:H7,8,0) -> 69800 | E4: 154710100018477 | F4: UBIN0815471 | G4: Union Bank
A5: AGS26006 | B5: Abhijeet Vijaysingh Pardeshi | C5: 46062 | D5: =VLOOKUP(A5,Employees!2:2,29,0) -> #N/A | E5: 41280100007853 | F5: BARB0WALUJX | G5: BANK OF BARODA
A6: AGS26010 | B6: Vemula Varshith | C6: 46083 | D6: =VLOOKUP(A6,'Tech Team'!A4:AA38,28,0) -> #REF! | E6: 62428832885 | F6: SBIN0020959 | G6: State Bank of India
A7: AGS26011 | B7: Siddula Hemasai | C7: 46083 | D7: =VLOOKUP(A7,'Tech Team'!A2:AA36,28,0) -> #REF! | E7: 3327101004003 | F7: CNRB0003327 | G7: Canara Bank
A8: AGS26013 | B8: Kalepu Vijay | C8: 46083 | D8: =VLOOKUP(A8,'Tech Team'!A10:AA44,28,0) -> #REF! | E8: 159502740717 | F8: INDB0000329 | G8: INDUSIND BANK
A9: AGS26014 | B9: Vulli Pavan | C9: 46083 | D9: =VLOOKUP(A9,'Tech Team'!A6:AA40,28,0) -> #REF! | E9: 77770116800885 | F9: FDRL0007777 | G9: Federal Bank
A10: AGS26015 | B10: Karne Narsimha Reddy | C10: 46083 | D10: =VLOOKUP(A10,'Tech Team'!A9:AA43,28,0) -> #REF! | E10: 1.446178e+15 | F10: KVBL0001446 | G10: Karur Vysya Bank
A11: AGS26016 | B11: Manisha Ashroba Virkar | C11: 46083 | D11: =VLOOKUP(A11,'Tech Team'!A8:AA42,28,0) -> #REF! | E11: 62297418711 | F11: SBIN0003801 | G11: State Bank of India
A12: AGS26017 | B12: Vavilla Saikumar | C12: 46083 | D12: =VLOOKUP(A12,'Tech Team'!A7:AA41,28,0) -> #REF! | E12: 41085488775 | F12: SBIN0016293 | G12: State Bank of India
A13: AGS26018 | B13: Settybathini Sathish | C13: 46083 | D13: =VLOOKUP(A13,'Tech Team'!A3:AA37,28,0) -> #REF! | E13: 50100595290241 | F13: HDFC0000075 | G13: HDFC Bank
A14: AGS26019 | B14: Nelapatla Srinivas | C14: 46083 | D14: =VLOOKUP(A14,'Tech Team'!A5:AA39,28,0) -> #REF! | E14: 62442668281 | F14: SBIN0020176 | G14: State Bank of India
A15: AGS26020 | B15: Gurindapalli Krishna Chaitanya | C15: 46066 | D15: =VLOOKUP(A15,Consultant!A4:H8,8,0) -> #N/A | E15: 020201545829 | F15: ICIC0000202 | G15: ICICI Bank
A16: AGS26021 | B16: Kontham Sushma | C16: 46083 | D16: =VLOOKUP(A16,'Tech Team'!A11:AA45,28,0) -> #REF! | E16: 39569845546 | F16: SBIN0008024 | G16: State Bank of India
A17: AGS26023 | B17: Bobbarala Varshini | C17: 46083 | D17: =VLOOKUP(A17,'Tech Team'!A12:AA47,28,0) -> #REF! | E17: 41202390653 | F17: SBIN0000910 | G17: State Bank of India
A18: AGS26024 | B18: Priya Darshini Pola | C18: 46072 | D18: =VLOOKUP(A18,Consultant!A4:H9,8,0) -> 79800 | E18: 770301501355 | F18: ICIC0007703 | G18: ICICI Bank
A19: AGS26025 | B19: Tumula Dinesh Kumar | C19: 46113 | D19: =VLOOKUP(A19,'Tech Team'!A34:AA71,28,0) -> #REF! | E19: 44610100006654 | F19: BARB0SIDDIP | G19: Bank of Baroda
A20: AGS26026 | B20: Surampudi Roop Sai | C20: 46083 | D20: =VLOOKUP(A20,'Tech Team'!A13:AA48,28,0) -> #REF! | E20: 615728726 | F20: IDIB000P121 | G20: Indian Bank
A21: AGS26028 | B21: Mohammed Abdul Moid | C21: 46083 | D21: =VLOOKUP(A21,'Tech Team'!A14:AA49,28,0) -> #REF! | E21: 9147600708 | F21: KKBK0007474 | G21: Kotak
A22: AGS26029 | B22: Mula Sai Preetham Goud | C22: 46083 | D22: =VLOOKUP(A22,'Tech Team'!A15:AA50,28,0) -> #REF! | E22: 7445588605 | F22: KKBK0007462 | G22: Kotak
A23: AGS26030 | B23: Sruthin Kumar Basa | C23: 46083 | D23: =VLOOKUP(A23,'Tech Team'!A16:AA51,28,0) -> #REF! | E23: 4495101004331 | F23: CNRB0004495 | G23: Canara Bank
A24: AGS26031 | B24: Y Raghavendar | C24: 46113 | D24: =VLOOKUP(A24,'Tech Team'!A29:AA66,28,0) -> #REF! | E24: 20086309269 | F24: SBIN0013071 | G24: State Bank of India
A25: AGS26032 | B25: Vempadapu Uday Sai Tarun | C25: 46083 | D25: =VLOOKUP(A25,'Tech Team'!A17:AA52,28,0) -> #REF! | E25: 37182972098 | F25: SBIN0008054 | G25: State Bank of India
A26: AGS26033 | B26: Kethavath Sai Raj | C26: 46083 | D26: =VLOOKUP(A26,'Tech Team'!A18:AA53,28,0) -> #N/A | E26: 39971511897 | F26: SBIN0021227 | G26: State Bank of India
A27: AGS26034 | B27: Sripada Shivakumar | C27: 46083 | D27: =VLOOKUP(A27,'Tech Team'!A18:AA54,28,0) -> #REF! | E27: 41536691505 | F27: SBIN0008807 | G27: State Bank of India
A28: AGS26035 | B28: Varakantham Surender Reddy | C28: 46083 | D28: =VLOOKUP(A28,'Tech Team'!A19:AA55,28,0) -> #REF! | E28: 50100141200194 | F28: HDFC0004480 | G28: HDFC Bank
A29: AGS26038 | B29: Ainala Saiesha | C29: 46086 | D29: =VLOOKUP(A29,Employees!2:3,29,0) -> 0 | E29: 50100868298601 | F29: HDFC0003665 | G29: HDFC Bank
A30: AGS26039 | B30: Esther Deva Priya | C30: 46092 | D30: =VLOOKUP(A30,Consultant!A5:H10,8,0) -> 19800 | E30: 50100743220366 | F30: HDFC0000545 | G30: HDFC Bank
A31: AGS26041 | B31: Sudhagani Sai Charan | C31: 46113 | D31: =VLOOKUP(A31,'Tech Team'!A20:AA56,28,0) -> #REF! | E31: 920010070801185 | F31: UTIB0000008 | G31: Axis Bank
A32: AGS26043 | B32: Chebrolu Yashaswini | C32: 46113 | D32: =VLOOKUP(A32,'Tech Team'!A21:AA57,28,0) -> #REF! | E32: 40590710609 | F32: SBIN0011984 | G32: SBI
A33: AGS26044 | B33: Naveen Pulikonda | C33: 46113 | D33: =VLOOKUP(A33,'Tech Team'!A36:AA73,28,0) -> #REF! | E33: 111101513423 | F33: ICIC0001111 | G33: ICICI Bank
A34: AGS26045 | B34: Chebrolu Monika | C34: 46113 | D34: =VLOOKUP(A34,'Tech Team'!A22:AA58,28,0) -> #REF! | E34: 801663119 | F34: ICIC0000008 | G34: ICICI Bank
A35: AGS26047 | B35: Upadhyayula Naga Lakshmi Deepthi | C35: 46113 | D35: =VLOOKUP(A35,'Tech Team'!A23:AA59,28,0) -> #REF! | E35: 55560103431927 | F35: FDRL0005556 | G35: Federal bank
A36: AGS26048 | B36: Rapolu Rekha | C36: 46113 | D36: =VLOOKUP(A36,'Tech Team'!A24:AA60,28,0) -> #REF! | E36: 55560103536675 | F36: FDRL0005556 | G36: Federal bank
A37: AGS26049 | B37: Ragiru Nikhitha | C37: 46113 | D37: =VLOOKUP(A37,'Tech Team'!A25:AA61,28,0) -> #REF! | E37: 110240929810 | F37: CNRB0007792 | G37: Canara Bank
A38: AGS26051 | B38: Mundlamuri Mrudula | C38: 46113 | D38: =VLOOKUP(A38,'Tech Team'!A26:AA62,28,0) -> #REF! | E38: 386701504229 | F38: ICIC0003867 | G38: ICICI Bank
